Workbook

Sheet 개요
B2: Weapon
C3: 사용여부 | D3: column명 | E3: 한글 명칭 | F3: 데이터 형식 | G3: 형식 설명 | H3: 설명
C4: 모든 무기 보유 스탯 | D4: weaponId | E4: 무기ID | F4: string | G4: "Weapon_target_00001" | H4: 포탑 ID 저장
D5: weaponName | E5: 무기명칭 | F5: string | G5: "기관포" | H5: 포탑의 이름 저장
D6: weaponLandType | E6: 지형속성 | F6: string | G6: "L" | H6: 포탑의 지형속성 저장, "L", "F" 2가지 값이 들어갈 수 있다.
D7: weaponPower | E7: 위력 | F7: int | G7: 0 | H7: 포탑의 위력 수치 저장
D8: weaponRange | E8: 사정거리 | F8: float | G8: 0.0f | H8: 포탑의 사정거리 수치 저장
D9: weaponAtkcycle | E9: 공격주기 | F9: float | G9: 0.0f | H9: 포탑의 공격주기 저장
D10: weaponPaturn | E10: 공격패턴 | F10: string | G10: "단일형" | H10: 포탑의 공격형식 저장["single", "blast", "pierce", "curved", "shot", "debuff"] 6개 값중 하나가 들어가며 추후 추가될 수 있다.
D11: weaponAtkType | E11: 공격속성 | F11: string | G11: "Spread" | H11: 포탑의 공격속성 저장 "spread", "normal", "armored" 3가지 값 중 하나가 들어간다.
D12: weaponHitboxSize | E12: 탄환 크기 | F12: float | G12: 0.0f | H12: 발사할 탄환의 크기 저장
D13: weaponAmmoSpeed | E13: 탄환 속도 | F13: float | G13: 0.0f | H13: 발사할 탄환의 속도 저장
D14: weaponRotaionSpeed | E14: 회전속도 | F14: float | G14: 0.0f | H14: 포탑의 회전 속도 저장
D15: weaponWeight | E15: 무게 | F15: int | G15: 0 | H15: 장착할 포탑의 무게수치 저장
D16: weaponPrice | E16: 포탑 가격 | F16: int | G16: 0 | H16: 포탑의 가격수치 저장
D17: weaponUseammoType | E17: 소모탄환 종류 | F17: string | G17: "bullet" | H17: 공격때마다 감소하는 탄환의 종류
C18: 폭발형, 곡사형만 사용 | D18: weaponExplosionRange | E18: 폭발 범위 | F18: float | G18: 0.0f | H18: 탄환이 생성하는 폭발의 범위 수치 저장
C19: 상태이상형만 사용 | D19: weaponSp | E19: 소환 위치 | F19: string | G19: "Weapon" | H19: 상태이상형 탄환이 소환될 위치 이름을 저장
D20: weaponZoneShape | E20: 범위 형태 | F20: string | G20: "Circle" | H20: 생성될 상태이상형 탄환의 형태 이름을 저장, "Circle", "Triangle" 2가지 값중 하나가 들어간다.
D21: weaponDebuff | E21: 적용효과 | F21: string | G21: "Stun" | H21: 상태이상형 탄환의 효과 이름 저장
C22: 관통형, 상태이상형, 산탄형만 사용 | D22: weaponAmmoDuration | E22: 지속시간 | F22: float | G22: 0.0f | H22: 탄환의 지속시간 수치 저장
C23: 곡사형,산탄형만사용 | D23: weaponAmmonMuch | E23: 탄환개수 | F23: int | G23: 0 | H23: 탄환이 발사될 개수 저장

Sheet Factor
B2: ● 해당 페이지에서 모든 또는 특정 종류의 포탑의 능력치를 조절할 수 있다. ● 가격별 기준 능력치가 모든 포탑의 기준 능력치 수치를 조절하며 나머지 테이블은 특정 속성을 가진 포탑의 능력치의 배율을 조정한다. ● 배율을 조정하는 테이블의 요소는 크기가 클수록 증가수치도 증가하기 때문에 큰 수치조정은 권장하지 않는다. ● 일반적인 수치는 크기가 증가하면 강력해지지만 공격주기 수치의 경우 크기가 작을수록 포탑이 빠르게 공격을 진행한다. ● 회전속도 수치는 초당 몇도를 회전하는지에 대한 수치이다. EX) 30이면 초당 30도 회전한다. ● 탄환속도는 초당 몇 M 이동하는지에 대한 수치이다. ● 탄환 크기는 유니티에서 오브젝트 크기 수치를 나타낸다. EX) 1이면 1*1*1 크기가 된다. ●사정거리는 포탑의 적 감지범위인 원형 범위의 반지름 크기이다. ● 소수 보정치는 소수점 단위로 나올 수 있는 능력치에 대하여 0.1초당 추가적인 배율을 어느정도 제공할지에 대한 수치이다.
B3: 공격 패턴별 보정치 | K3: 공격 속성 보정치 | T3: 소모 탄환별 보정치 | AB3: id구별 | AE3: 가격별 기준 능력치 | AN3: 피해범위 보정치 | AX3: 상태이상 보정치 | BG3: 지속시간 보정치 | BQ3: 탄환 개수보정치 | BZ3: 탄환 구경 보정치 | CL3: 무기 이름별 기본 속성
B4: 종류 구분 | C4: 위력 | D4: 사정거리 | E4: 공격주기 | F4: 탄환크기 | G4: 탄환 속도 | H4: 회전속도 | I4: 무게 | K4: 종류 구분 | L4: 위력 | M4: 사정거리 | N4: 공격주기 | O4: 탄환크기 | P4: 탄환 속도 | Q4: 회전속도 | R4: 무게 | T4: 종류 구분 | U4: 위력 | V4: 사정거리 | W4: 공격주기 | X4: 탄환크기 | Y4: 탄환 속도 | Z4: 회전속도 | AA4: 무게 | AB4: 적힐 이름 | AD4: 등급 구분 | AE4: 종류 구분 | AF4: 위력 | AG4: 사정거리 | AH4: 공격주기 | AI4: 탄환크기 | AJ4: 탄환 속도 | AK4: 회전속도 | AL4: 무게 | AN4: 종류 구분 | AO4: 소수 보정치 | AP4: 위력 | AQ4: 사정거리 | AR4: 공격주기 | AS4: 탄환크기 | AT4: 탄환 속도 | AU4: 회전속도 | AV4: 무게 | AX4: 종류 구분 | AY4: 위력 | AZ4: 사정거리 | BA4: 공격주기 | BB4: 탄환크기 | BC4: 탄환 속도 | BD4: 회전속도 | BE4: 무게 | BG4: 종류 구분 | BH4: 세부 보정치 | BI4: 위력 | BJ4: 사정거리 | BK4: 공격주기 | BL4: 탄환크기 | BM4: 탄환 속도 | BN4: 회전속도 | BO4: 무게 | BQ4: 종류 구분 | BR4: 위력 | BS4: 사정거리 | BT4: 공격주기 | BU4: 탄환크기 | BV4: 탄환 속도 | BW4: 회전속도 | BX4: 무게 | BZ4: 종류 구분 | CA4: 위력 | CB4: 사정거리 | CC4: 공격주기 | CD4: 탄환크기 | CE4: 탄환 속도 | CF4: 회전속도 | CG4: 무게 | CH4: 피해 범위 | CI4: 지속시간 | CJ4: 탄환개수 | CL4: 종류 구분 | CM4: 공격패턴 | CN4: 소모탄환 종류 | CO4: 지형속성 | CP4: 공격속성 | CQ4: 폭발 범위 | CR4: 적용효과 | CS4: 지속시간 | CT4: 탄환개수 | CU4: 소환 위치 | CV4: 범위 형태
B5: single | C5: 1 | D5: 1 | E5: 1 | F5: 1 | G5: 1 | H5: 1 | I5: 1 | K5: spread | L5: 1 | M5: 1 | N5: 1 | O5: 1 | P5: 1 | Q5: 1 | R5: 1 | T5: ammo | U5: 1 | V5: 1 | W5: 1 | X5: 1 | Y5: 1 | Z5: 1 | AA5: 1 | AB5: Am | AD5: 녹슨 | AE5: 0 | AF5: 10 | AG5: 4 | AH5: 1 | AI5: 1 | AJ5: 1 | AK5: 120 | AL5: 1 | AN5: 0 | AO5: 0.01 | AP5: 1 | AQ5: 1 | AR5: 1 | AS5: 1 | AT5: 1 | AU5: 1 | AV5: 1 | AX5: null | AY5: 1 | AZ5: 1 | BA5: 1 | BB5: 1 | BC5: 1 | BD5: 1 | BE5: 1 | BG5: 0 | BH5: 1 | BI5: 1 | BJ5: 1 | BK5: 1 | BL5: 1 | BM5: 1 | BN5: 1 | BO5: 1 | BQ5: 1 | BR5: 1 | BS5: 1 | BT5: 1 | BU5: 1 | BV5: 1 | BW5: 1 | BX5: 1 | BZ5: none | CA5: 1 | CB5: 1 | CC5: 1 | CD5: 1 | CE5: 1 | CF5: 1 | CG5: 1 | CH5: 1 | CI5: 1 | CJ5: 1 | CL5: 기관포 | CM5: single | CN5: ammo | CO5: L | CP5: spread | CQ5: 0 | CR5: null | CS5: 0 | CT5: 1 | CU5: null | CV5: null
B6: blast | C6: 1 | D6: 0.9 | E6: 0.9 | F6: 0.9 | G6: 0.9 | H6: 0.9 | I6: 0.9 | K6: normal | L6: 2 | M6: 2 | N6: 2 | O6: 2 | P6: 2 | Q6: 2 | R6: 2 | T6: shell | U6: 2 | V6: 2 | W6: 2 | X6: 2 | Y6: 2 | Z6: 2 | AA6: 2 | AB6: Sh | AD6: T1 | AE6: 1000 | AF6: 20 | AG6: 4 | AH6: 1 | AI6: 2 | AJ6: 2 | AK6: 120 | AL6: 2 | AN6: 1 | AO6: 0.01 | AP6: 1 | AQ6: 1 | AR6: 1 | AS6: 1 | AT6: 1 | AU6: 1 | AV6: 1 | AX6: stun | AY6: 1 | AZ6: 1 | BA6: 1 | BB6: 1 | BC6: 1 | BD6: 1 | BE6: 1 | BG6: 1 | BH6: 1 | BI6: 1 | BJ6: 1 | BK6: 1 | BL6: 1 | BM6: 1 | BN6: 1 | BO6: 1 | BQ6: 2 | BR6: 2 | BS6: 2 | BT6: 2 | BU6: 2 | BV6: 2 | BW6: 2 | BX6: 2 | BZ6: 5.56mm | CA6: 1 | CB6: 1 | CC6: 1 | CD6: 1 | CE6: 1 | CF6: 1 | CG6: 1 | CH6: 2 | CI6: 2 | CJ6: 2 | CL6: 대공포 | CM6: single | CN6: ammo | CO6: F | CP6: spread | CQ6: 0 | CR6: null | CS6: 0 | CT6: 1 | CU6: null | CV6: null
B7: pierce | C7: 1 | D7: 0.8 | E7: 0.8 | F7: 0.8 | G7: 0.8 | H7: 0.8 | I7: 0.8 | K7: armored | L7: 3 | M7: 3 | N7: 3 | O7: 3 | P7: 3 | Q7: 3 | R7: 3 | T7: missile | U7: 3 | V7: 3 | W7: 3 | X7: 3 | Y7: 3 | Z7: 3 | AA7: 3 | AB7: Ms | AD7: T2 | AE7: 2000 | AF7: 30 | AG7: 4 | AH7: 1 | AI7: 3 | AJ7: 3 | AK7: 120 | AL7: 3 | AN7: 2 | AO7: 0.01 | AP7: 2 | AQ7: 2 | AR7: 2 | AS7: 2 | AT7: 2 | AU7: 2 | AV7: 2 | AX7: dots | AY7: 2 | AZ7: 2 | BA7: 2 | BB7: 2 | BC7: 2 | BD7: 2 | BE7: 2 | BG7: 2 | BH7: 2 | BI7: 2 | BJ7: 2 | BK7: 2 | BL7: 2 | BM7: 2 | BN7: 2 | BO7: 2 | BQ7: 3 | BR7: 3 | BS7: 3 | BT7: 3 | BU7: 3 | BV7: 3 | BW7: 3 | BX7: 3 | BZ7: 7.62mm | CA7: 1 | CB7: 1 | CC7: 1 | CD7: 1 | CE7: 1 | CF7: 1 | CG7: 1 | CH7: 3 | CI7: 3 | CJ7: 3 | CL7: 유탄 포탑 | CM7: blast | CN7: ammo | CO7: L | CP7: spread | CQ7: 1 | CR7: null | CS7: 0 | CT7: 1 | CU7: null | CV7: null
B8: curved | C8: 1 | D8: 0.7 | E8: 0.7 | F8: 0.7 | G8: 0.7 | H8: 0.7 | I8: 0.7 | AD8: T3 | AE8: 3000 | AF8: 40 | AG8: 5 | AH8: 1 | AI8: 4 | AJ8: 4 | AK8: 120 | AL8: 4 | AN8: 3 | AO8: 0.01 | AP8: 3 | AQ8: 3 | AR8: 3 | AS8: 3 | AT8: 3 | AU8: 3 | AV8: 3 | AX8: slow | AY8: 3 | AZ8: 3 | BA8: 3 | BB8: 3 | BC8: 3 | BD8: 3 | BE8: 3 | BG8: 3 | BH8: 3 | BI8: 3 | BJ8: 3 | BK8: 3 | BL8: 3 | BM8: 3 | BN8: 3 | BO8: 3 | BQ8: 4 | BR8: 4 | BS8: 4 | BT8: 4 | BU8: 4 | BV8: 4 | BW8: 4 | BX8: 4 | BZ8: 12.7mm | CA8: 1 | CB8: 1 | CC8: 1 | CD8: 1 | CE8: 1 | CF8: 1 | CG8: 1 | CH8: 4 | CI8: 4 | CJ8: 4 | CL8: 직사포 | CM8: pierce | CN8: shell | CO8: L | CP8: normal | CQ8: 0 | CR8: null | CS8: 3 | CT8: 1 | CU8: null | CV8: null
B9: shot | C9: 1 | D9: 0.6 | E9: 0.6 | F9: 0.6 | G9: 0.6 | H9: 0.6 | I9: 0.6 | AD9: T4 | AE9: 4000 | AF9: 50 | AG9: 5 | AH9: 1 | AI9: 5 | AJ9: 5 | AK9: 120 | AL9: 5 | AN9: 4 | AO9: 0.01 | AP9: 4 | AQ9: 4 | AR9: 4 | AS9: 4 | AT9: 4 | AU9: 4 | AV9: 4 | AX9: deflow | AY9: 4 | AZ9: 4 | BA9: 4 | BB9: 4 | BC9: 4 | BD9: 4 | BE9: 4 | BG9: 4 | BH9: 4 | BI9: 4 | BJ9: 4 | BK9: 4 | BL9: 4 | BM9: 4 | BN9: 4 | BO9: 4 | BQ9: 5 | BR9: 5 | BS9: 5 | BT9: 5 | BU9: 5 | BV9: 5 | BW9: 5 | BX9: 5 | BZ9: 20mm | CA9: 1 | CB9: 1 | CC9: 1 | CD9: 1 | CE9: 1 | CF9: 1 | CG9: 1 | CH9: 5 | CI9: 5 | CJ9: 5 | CL9: 바주카포 발사대 | CM9: blast | CN9: missile | CO9: L | CP9: normal | CQ9: 2 | CR9: null | CS9: 0 | CT9: 1 | CU9: null | CV9: null
B10: debuff | C10: 1 | D10: 0.5 | E10: 0.5 | F10: 0.5 | G10: 0.5 | H10: 0.5 | I10: 0.5 | K10: 지형 보정치 | AD10: T5 | AE10: 5000 | AF10: 60 | AG10: 5 | AH10: 1 | AI10: 6 | AJ10: 6 | AK10: 120 | AL10: 6 | AN10: 5 | AO10: 0.01 | AP10: 5 | AQ10: 5 | AR10: 5 | AS10: 5 | AT10: 5 | AU10: 5 | AV10: 5 | BG10: 5 | BH10: 5 | BI10: 5 | BJ10: 5 | BK10: 5 | BL10: 5 | BM10: 5 | BN10: 5 | BO10: 5 | BQ10: 6 | BR10: 6 | BS10: 6 | BT10: 6 | BU10: 6 | BV10: 6 | BW10: 6 | BX10: 6 | BZ10: 40mm | CA10: 1 | CB10: 1 | CC10: 1 | CD10: 1 | CE10: 1 | CF10: 1 | CG10: 1 | CH10: 6 | CI10: 6 | CJ10: 6 | CL10: 휴대용 대공 미사일 발사대 | CM10: blast | CN10: missile | CO10: F | CP10: armored | CQ10: 2 | CR10: null | CS10: 0 | CT10: 1 | CU10: null | CV10: null
K11: 종류 구분 | L11: 위력 | M11: 사정거리 | N11: 공격주기 | O11: 탄환크기 | P11: 탄환 속도 | Q11: 회전속도 | R11: 무게 | AD11: T6 | AE11: 6000 | AF11: 70 | AG11: 6 | AH11: 1 | AI11: 7 | AJ11: 7 | AK11: 120 | AL11: 7 | BG11: 6 | BH11: 6 | BI11: 6 | BJ11: 6 | BK11: 6 | BL11: 6 | BM11: 6 | BN11: 6 | BO11: 6 | BQ11: 7 | BR11: 7 | BS11: 7 | BT11: 7 | BU11: 7 | BV11: 7 | BW11: 7 | BX11: 7 | BZ11: 55mm | CA11: 1 | CB11: 1 | CC11: 1 | CD11: 1 | CE11: 1 | CF11: 1 | CG11: 1 | CH11: 7 | CI11: 7 | CJ11: 7 | CL11: 쌍열 기관포 | CM11: shot | CN11: ammo | CO11: L | CP11: spread | CQ11: 0 | CR11: null | CS11: 3 | CT11: 1 | CU11: null | CV11: null
K12: L | L12: 1 | M12: 1 | N12: 1 | O12: 1 | P12: 1 | Q12: 1 | R12: 1 | AD12: T7 | AE12: 7000 | AF12: 80 | AG12: 6 | AH12: 1 | AI12: 8 | AJ12: 8 | AK12: 120 | AL12: 8 | BG12: 7 | BH12: 7 | BI12: 7 | BJ12: 7 | BK12: 7 | BL12: 7 | BM12: 7 | BN12: 7 | BO12: 7 | BQ12: 8 | BR12: 8 | BS12: 8 | BT12: 8 | BU12: 8 | BV12: 8 | BW12: 8 | BX12: 8 | BZ12: 81mm | CA12: 1 | CB12: 1 | CC12: 1 | CD12: 1 | CE12: 1 | CF12: 1 | CG12: 1 | CH12: 8 | CI12: 8 | CJ12: 8 | CL12: 쌍열 대공포 | CM12: shot | CN12: ammo | CO12: F | CP12: spread | CQ12: 0 | CR12: null | CS12: 3 | CT12: 1 | CU12: null | CV12: null
K13: F | L13: 2 | M13: 2 | N13: 2 | O13: 2 | P13: 2 | Q13: 2 | R13: 2 | AD13: T8 | AE13: 8000 | AF13: 90 | AG13: 6 | AH13: 1 | AI13: 9 | AJ13: 9 | AK13: 120 | AL13: 9 | BG13: 8 | BH13: 8 | BI13: 8 | BJ13: 8 | BK13: 8 | BL13: 8 | BM13: 8 | BN13: 8 | BO13: 8 | BQ13: 9 | BR13: 9 | BS13: 9 | BT13: 9 | BU13: 9 | BV13: 9 | BW13: 9 | BX13: 9 | BZ13: 105mm | CA13: 1 | CB13: 1 | CC13: 1 | CD13: 1 | CE13: 1 | CF13: 1 | CG13: 1 | CH13: 8 | CI13: 8 | CJ13: 8 | CL13: 박격포탑 | CM13: curved | CN13: shell | CO13: L | CP13: spread | CQ13: 3 | CR13: null | CS13: 0 | CT13: 1 | CU13: null | CV13: null
AD14: T9 | AE14: 9000 | AF14: 100 | AG14: 7 | AH14: 1 | AI14: 10 | AJ14: 10 | AK14: 120 | AL14: 10 | BG14: 9 | BH14: 9 | BI14: 9 | BJ14: 9 | BK14: 9 | BL14: 9 | BM14: 9 | BN14: 9 | BO14: 9 | BQ14: 10 | BR14: 10 | BS14: 10 | BT14: 10 | BU14: 10 | BV14: 10 | BW14: 10 | BX14: 10 | BZ14: 155mm | CA14: 1 | CB14: 1 | CC14: 1 | CD14: 1 | CE14: 1 | CF14: 1 | CG14: 1 | CH14: 8 | CI14: 8 | CJ14: 8 | CL14: 함포 | CM14: pierce | CN14: shell | CO14: L | CP14: normal | CQ14: 0 | CR14: null | CS14: 3 | CT14: 1 | CU14: null | CV14: null
AD15: T10 | AE15: 10000 | AF15: 110 | AG15: 7 | AH15: 1 | AI15: 11 | AJ15: 11 | AK15: 120 | AL15: 11 | BG15: 10 | BH15: 10 | BI15: 10 | BJ15: 10 | BK15: 10 | BL15: 10 | BM15: 10 | BN15: 10 | BO15: 10 | BZ15: 240mm | CA15: 1 | CB15: 1 | CC15: 1 | CD15: 1 | CE15: 1 | CF15: 1 | CG15: 1 | CH15: 8 | CI15: 8 | CJ15: 8 | CL15: 곡사포 | CM15: curved | CN15: shell | CO15: L | CP15: normal | CQ15: 4 | CR15: null | CS15: 0 | CT15: 1 | CU15: null | CV15: null
K16: 상태이상 생성위치 보정치 | CL16: 샷건포탑 | CM16: shot | CN16: ammo | CO16: L | CP16: spread | CQ16: 0 | CR16: null | CS16: 3 | CT16: 5 | CU16: null | CV16: null
K17: 종류 구분 | L17: 위력 | M17: 사정거리 | N17: 공격주기 | O17: 탄환크기 | P17: 탄환 속도 | Q17: 회전속도 | R17: 무게 | CL17: 화염방사기 | CM17: debuff | CN17: ammo | CO17: L | CP17: spread | CQ17: 0 | CR17: dots | CS17: 5 | CT17: 1 | CU17: head | CV17: triangle
K18: head | L18: 1 | M18: 1 | N18: 1 | O18: 1 | P18: 1 | Q18: 1 | R18: 1 | CL18: 네이팜 미사일 발사대 | CM18: debuff | CN18: missile | CO18: L | CP18: armored | CQ18: 0 | CR18: dots | CS18: 5 | CT18: 1 | CU18: target | CV18: circle
K19: target | L19: 2 | M19: 2 | N19: 2 | O19: 2 | P19: 2 | Q19: 2 | R19: 2 | CL19: 벙커버스터 미사일 발사대 | CM19: debuff | CN19: missile | CO19: L | CP19: armored | CQ19: 0 | CR19: deflow | CS19: 5 | CT19: 1 | CU19: target | CV19: circle
K20: null | CL20: 액화질소 살포 미사일 발사대 | CM20: debuff | CN20: missile | CO20: L | CP20: spread | CQ20: 0 | CR20: stun | CS20: 5 | CT20: 1 | CU20: target | CV20: circle
CL21: 연막탄 발사기 | CM21: debuff | CN21: ammo | CO21: L | CP21: spread | CQ21: 0 | CR21: slow | CS21: 5 | CT21: 1 | CU21: target | CV21: circle
K22: 상태이상 형태 범위 보정치
K23: 종류 구분 | L23: 위력 | M23: 사정거리 | N23: 공격주기 | O23: 탄환크기 | P23: 탄환 속도 | Q23: 회전속도 | R23: 무게
K24: circle | L24: 1 | M24: 1 | N24: 1 | O24: 1 | P24: 1 | Q24: 1 | R24: 1
K25: triangle | L25: 2 | M25: 2 | N25: 2 | O25: 2 | P25: 2 | Q25: 2 | R25: 2
K26: null

Sheet Weapon
A1: ● 해당 페이지는 실제 사용할 데이터에 대한 내용이 적힌 테이블이다. ●3열은 데이터의 자료형이며 자료형이 한글로 되어있는 경우 인게임에서 사용하지 않는 데이터지만 테이블에서 수치조정 또는 색인을 위해 넣은 데이터이다. ●보정치의 수치를 조정해 각 포탑별로 상세 능력치를 조정할 수 있다. ● 보정값의 경우 수치 조정의도가 없는 경우 1을 유지한다. ●포탑에 따라 사용하지 않는 칼럼이 존재한다. 데이터를 입력해도 영향을 주지 않지만 통일성을 위하여 사용하지 않는데이터는 문자형의 경우 null값, 정수형/소수형의 경우 0 을 넣는다.
A2: 무기ID | B2: 무기명칭 | C2: 등급 | D2: 무기 명칭(구경 입력용) | E2: 무기 명칭(이름 입력용) | F2: 포탑 가격 | G2: 공격패턴 | H2: 소모탄환 종류 | I2: 지형속성 | J2: 공격속성 | K2: 폭발 범위 보정치 | L2: 폭발 범위 | M2: 적용효과 | N2: 지속시간 보정치 | O2: 지속시간 | P2: 탄환개수 보정치 | Q2: 탄환개수 | R2: 소환 위치 | S2: 범위 형태 | T2: 위력 보정치 | U2: 사정거리 보정치 | V2: 공격주기 보정치 | W2: 탄환크기 보정치 | X2: 탄환 속도 보정치 | Y2: 회전속도 보정치 | Z2: 무게 보정치 | AA2: 위력 | AB2: 사정거리 | AC2: 공격주기 | AD2: 탄환크기 | AE2: 탄환 속도 | AF2: 회전속도 | AG2: 무게
A3: string | B3: string | C3: 내부색인 | D3: 내부색인(없으면 none 입력) | E3: 내부색인 | F3: int | G3: string | H3: string | I3: string | J3: string | K3: 보정치 | L3: float | M3: string | N3: 보정치 | O3: float | P3: 보정치 | Q3: int | R3: string | S3: string | T3: 보정치 | U3: 보정치 | V3: 보정치 | W3: 보정치 | X3: 보정치 | Y3: 보정치 | Z3: 보정치 | AA3: int | AB3: float | AC3: float | AD3: float | AE3: float | AF3: float | AG3: int
A4: weaponId | B4: weaponName | C4: weaponTier | D4: weaponName | E4: weaponName | F4: weaponPrice | G4: weaponPaturn | H4: weaponAmmo | I4: weaponLandType | J4: weaponType | K4: weaponExplosionRange | L4: weaponExplosionRange | M4: weaponDebuff | N4: weaponAmmoDuration | O4: weaponAmmoDuration | P4: weaponAmmonMuch | Q4: weaponAmmonMuch | R4: weaponSP | S4: weaponZoneShape | T4: weaponPower | U4: weaponRange | V4: weaponAtkcycle | W4: weaponHitboxSize | X4: weaponAmmoSpeed | Y4: weaponRotaionSpeed | Z4: weaponWeight | AA4: weaponPower | AB4: weaponRange | AC4: weaponAtkcycle | AD4: weaponHitboxSize | AE4: weaponAmmoSpeed | AF4: weaponRotaionSpeed | AG4: weaponWeight
A5: ="weapon_"&G5&"_"&VLOOKUP(H5, Factor!$T$5:$AB$7, 9, 0)&"_"&IF(COUNTIFS($G$4:G4, G5, $H$4:H4, H5)+1>=100, COUNTIFS($G$4:G4, G5, $H$4:H4, H5)+1,IF(COUNTIFS($G$4:G4, G5, $H$4:H4, H5)+1>=10, "0"&COUNTIFS($G$4:G4, G5, $H$4:H4, H5)+1, "00"&COUNTIFS($G$4:G4, G5, $H$4:H4, H5)+1)) -> weapon_single_Am_001 | B5: =C5&" "&IF(D5 = "none","", D5)&E5 -> 녹슨 기관포 | C5: 녹슨 | D5: none | E5: 기관포 | F5: =VLOOKUP(C5, Factor!$AD$5:$AE$15, 2, 0) -> 0 | G5: =VLOOKUP(E5, Factor!$CL$5:$CV$50, 2, 0) -> single | H5: =VLOOKUP(E5, Factor!$CL$5:$CV$50, 3, 0) -> ammo | I5: =VLOOKUP(E5, Factor!$CL$5:$CV$50, 4, 0) -> L | J5: =VLOOKUP(E5, Factor!$CL$5:$CV$50, 5, 0) -> spread | K5: 1 | L5: =VLOOKUP(E5, Factor!$CL$5:$CV$50, 6, 0)*K5*VLOOKUP(D5, Factor!$BZ$5:$CJ$49, 9, 0) -> 0 | M5: =VLOOKUP(E5, Factor!$CL$5:$CV$50, 7, 0) -> null | N5: 1 | O5: =VLOOKUP(E5, Factor!$CL$5:$CV$50, 8, 0)*N5*VLOOKUP(D5, Factor!$BZ$5:$CJ$49, 10, 0) -> 0 | P5: 1 | Q5: =VLOOKUP(E5, Factor!$CL$5:$CV$50, 9, 0)*P5*VLOOKUP(D5, Factor!$BZ$5:$CJ$49, 11, 0) -> 1 | R5: =VLOOKUP(E5, Factor!$CL$5:$CV$50, 10, 0) -> null | S5: =VLOOKUP(E5, Factor!$CL$5:$CV$50, 11, 0) -> null | T5: 1 | U5: 1 | V5: 1 | W5: 1 | X5: 1 | Y5: 1 | Z5: 1 | AA5: {=_xlfn.LET(_xlpm.기본_색인번호, 2, _xlpm.추가_색인번호, 3, _xlpm.개별보정치, T5, _xlpm.패턴보정치, VLOOKUP($G5, Factor!$B$5:$I$51, _xlpm.기본_색인번호, 0), _xlpm.소모탄환보정치, VLOOKUP($H5, Factor!$T$5:$AA$51, _xlpm.기본_색인번호, 0), _xlpm.지형보정치, VLOOKUP($I5, Factor!$K$12:$R$13, _xlpm.기본_색인번호, 0), _xlpm.공격속성보정치, VLOOKUP($J5, Factor!$K$5:$R$7, _xlpm.기본_색인번호, 0), _xlpm.피해범위보정치, INDEX(Factor!$AN$5:$AV$51, _xlfn.XMATCH(IF(OR($G5="blast", $G5="curved", $G5= "debuff"), $L5, 0), Factor!$AN$5:$AN$51, -1), _xlpm.추가_색인번호)-IF(AND(OR($G5="blast", $G5="curved", $G5= "debuff"), MOD($L5,1)<>0),INDEX(Factor!$AN$5:$AV$51, _xlfn.XMATCH(IF(OR($G5="blast", $G5="curved", $G5= "debuff"), $L5, 0), Factor!$AN$5:$AN$51, -1), 2)*MOD($L5,1)*10,0), _xlpm.상태이상보정치, VLOOKUP(IF($G5 = "debuff", $M5, "null"), Factor!$AX$5:$BE$51, _xlpm.기본_색인번호, 0), _xlpm.지속시간보정치, INDEX(Factor!$BG$5:$BO$51, _xlfn.XMATCH(IF(OR($G5 ="debuff", $G5 = "shot", $G5 = "pierce"), $O5, 0), Factor!$BG$5:$BG$51, -1), _xlpm.추가_색인번호)-IF(AND(OR($G5 ="debuff", $G5 = "shot", $G5 = "pierce"), MOD($O5, 1)<>0), 10*MOD($O5, 1)*INDEX(Factor!$BG$5:$BO$51, _xlfn.XMATCH(IF(OR($G5 ="debuff", $G5 = "shot", $G5 = "pierce"), $O5, 0), Factor!$BG$5:$BG$51, -1), 2), 0), _xlpm.탄환개수보정치, VLOOKUP(IF(OR($G5 = "curved", $G5 = "shot"), $Q5, 1), Factor!$BQ$5:$BX$51, _xlpm.기본_색인번호, 0), _xlpm.상태이상탄환생성위치보정치, IF($G5 = "debuff", VLOOKUP($R5, Factor!$K$18:$R$19, _xlpm.기본_색인번호, 0),1), _xlpm.상태이상탄환형태보정치, IF($G5 = "debuff", VLOOKUP($S5, Factor!$K$24:$R$25, _xlpm.기본_색인번호, 0),1), _xlpm.가격보정치, INDEX(Factor!$AE$5:$AL$51, _xlfn.XMATCH($F5,Factor!$AE$5:$AE$51, -1), _xlpm.기본_색인번호), _xlpm.구경보정치, VLOOKUP($D5, Factor!$BZ$5:$CJ$56, _xlpm.기본_색인번호, 0), _xlpm.결과, _xlpm.개별보정치*_xlpm.패턴보정치*_xlpm.소모탄환보정치*_xlpm.지형보정치*_xlpm.공격속성보정치*_xlpm.피해범위보정치*_xlpm.상태이상보정치*_xlpm.지속시간보정치*_xlpm.탄환개수보정치*_xlpm.상태이상탄환생성위치보정치*_xlpm.상태이상탄환형태보정치*_xlpm.가격보정치*_xlpm.구경보정치, _xlpm.결과)} -> 10 | AB5: {=_xlfn.LET(_xlpm.기본_색인번호, 3, _xlpm.추가_색인번호, 4, _xlpm.개별보정치, U5, _xlpm.패턴보정치, VLOOKUP($G5, Factor!$B$5:$I$51, _xlpm.기본_색인번호, 0), _xlpm.소모탄환보정치, VLOOKUP($H5, Factor!$T$5:$AA$51, _xlpm.기본_색인번호, 0), _xlpm.지형보정치, VLOOKUP($I5, Factor!$K$12:$R$13, _xlpm.기본_색인번호, 0), _xlpm.공격속성보정치, VLOOKUP($J5, Factor!$K$5:$R$7, _xlpm.기본_색인번호, 0), _xlpm.피해범위보정치, INDEX(Factor!$AN$5:$AV$51, _xlfn.XMATCH(IF(OR($G5="blast", $G5="curved", $G5= "debuff"), $L5, 0), Factor!$AN$5:$AN$51, -1), _xlpm.추가_색인번호)-IF(AND(OR($G5="blast", $G5="curved", $G5= "debuff"), MOD($L5,1)<>0),INDEX(Factor!$AN$5:$AV$51, _xlfn.XMATCH(IF(OR($G5="blast", $G5="curved", $G5= "debuff"), $L5, 0), Factor!$AN$5:$AN$51, -1), 2)*MOD($L5,1)*10,0), _xlpm.상태이상보정치, VLOOKUP(IF($G5 = "debuff", $M5, "null"), Factor!$AX$5:$BE$51, _xlpm.기본_색인번호, 0), _xlpm.지속시간보정치, INDEX(Factor!$BG$5:$BO$51, _xlfn.XMATCH(IF(OR($G5 ="debuff", $G5 = "shot", $G5 = "pierce"), $O5, 0), Factor!$BG$5:$BG$51, -1), _xlpm.추가_색인번호)-IF(AND(OR($G5 ="debuff", $G5 = "shot", $G5 = "pierce"), MOD($O5, 1)<>0), 10*MOD($O5, 1)*INDEX(Factor!$BG$5:$BO$51, _xlfn.XMATCH(IF(OR($G5 ="debuff", $G5 = "shot", $G5 = "pierce"), $O5, 0), Factor!$BG$5:$BG$51, -1), 2), 0), _xlpm.탄환개수보정치, VLOOKUP(IF(OR($G5 = "curved", $G5 = "shot"), $Q5, 1), Factor!$BQ$5:$BX$51, _xlpm.기본_색인번호, 0), _xlpm.상태이상탄환생성위치보정치, IF($G5 = "debuff", VLOOKUP($R5, Factor!$K$18:$R$19, _xlpm.기본_색인번호, 0),1), _xlpm.상태이상탄환형태보정치, IF($G5 = "debuff", VLOOKUP($S5, Factor!$K$24:$R$25, _xlpm.기본_색인번호, 0),1), _xlpm.가격보정치, INDEX(Factor!$AE$5:$AL$51, _xlfn.XMATCH($F5,Factor!$AE$5:$AE$51, -1), _xlpm.기본_색인번호), _xlpm.구경보정치, VLOOKUP($D5, Factor!$BZ$5:$CJ$56, _xlpm.기본_색인번호, 0), _xlpm.결과, _xlpm.개별보정치*_xlpm.패턴보정치*_xlpm.소모탄환보정치*_xlpm.지형보정치*_xlpm.공격속성보정치*_xlpm.피해범위보정치*_xlpm.상태이상보정치*_xlpm.지속시간보정치*_xlpm.탄환개수보정치*_xlpm.상태이상탄환생성위치보정치*_xlpm.상태이상탄환형태보정치*_xlpm.가격보정치*_xlpm.구경보정치, _xlpm.결과)} -> 4 | AC5: {=_xlfn.LET(_xlpm.기본_색인번호, 4, _xlpm.추가_색인번호, 5, _xlpm.개별보정치, V5, _xlpm.패턴보정치, VLOOKUP($G5, Factor!$B$5:$I$51, _xlpm.기본_색인번호, 0), _xlpm.소모탄환보정치, VLOOKUP($H5, Factor!$T$5:$AA$51, _xlpm.기본_색인번호, 0), _xlpm.지형보정치, VLOOKUP($I5, Factor!$K$12:$R$13, _xlpm.기본_색인번호, 0), _xlpm.공격속성보정치, VLOOKUP($J5, Factor!$K$5:$R$7, _xlpm.기본_색인번호, 0), _xlpm.피해범위보정치, INDEX(Factor!$AN$5:$AV$51, _xlfn.XMATCH(IF(OR($G5="blast", $G5="curved", $G5= "debuff"), $L5, 0), Factor!$AN$5:$AN$51, -1), _xlpm.추가_색인번호)-IF(AND(OR($G5="blast", $G5="curved", $G5= "debuff"), MOD($L5,1)<>0),INDEX(Factor!$AN$5:$AV$51, _xlfn.XMATCH(IF(OR($G5="blast", $G5="curved", $G5= "debuff"), $L5, 0), Factor!$AN$5:$AN$51, -1), 2)*MOD($L5,1)*10,0), _xlpm.상태이상보정치, VLOOKUP(IF($G5 = "debuff", $M5, "null"), Factor!$AX$5:$BE$51, _xlpm.기본_색인번호, 0), _xlpm.지속시간보정치, INDEX(Factor!$BG$5:$BO$51, _xlfn.XMATCH(IF(OR($G5 ="debuff", $G5 = "shot", $G5 = "pierce"), $O5, 0), Factor!$BG$5:$BG$51, -1), _xlpm.추가_색인번호)-IF(AND(OR($G5 ="debuff", $G5 = "shot", $G5 = "pierce"), MOD($O5, 1)<>0), 10*MOD($O5, 1)*INDEX(Factor!$BG$5:$BO$51, _xlfn.XMATCH(IF(OR($G5 ="debuff", $G5 = "shot", $G5 = "pierce"), $O5, 0), Factor!$BG$5:$BG$51, -1), 2), 0), _xlpm.탄환개수보정치, VLOOKUP(IF(OR($G5 = "curved", $G5 = "shot"), $Q5, 1), Factor!$BQ$5:$BX$51, _xlpm.기본_색인번호, 0), _xlpm.상태이상탄환생성위치보정치, IF($G5 = "debuff", VLOOKUP($R5, Factor!$K$18:$R$19, _xlpm.기본_색인번호, 0),1), _xlpm.상태이상탄환형태보정치, IF($G5 = "debuff", VLOOKUP($S5, Factor!$K$24:$R$25, _xlpm.기본_색인번호, 0),1), _xlpm.가격보정치, INDEX(Factor!$AE$5:$AL$51, _xlfn.XMATCH($F5,Factor!$AE$5:$AE$51, -1), _xlpm.기본_색인번호), _xlpm.구경보정치, VLOOKUP($D5, Factor!$BZ$5:$CJ$56, _xlpm.기본_색인번호, 0), _xlpm.결과, _xlpm.개별보정치*_xlpm.패턴보정치*_xlpm.소모탄환보정치*_xlpm.지형보정치*_xlpm.공격속성보정치*_xlpm.피해범위보정치*_xlpm.상태이상보정치*_xlpm.지속시간보정치*_xlpm.탄환개수보정치*_xlpm.상태이상탄환생성위치보정치*_xlpm.상태이상탄환형태보정치*_xlpm.가격보정치*_xlpm.구경보정치, _xlpm.결과)} -> 1 | AD5: {=_xlfn.LET(_xlpm.기본_색인번호, 5, _xlpm.추가_색인번호, 6, _xlpm.개별보정치, W5, _xlpm.패턴보정치, VLOOKUP($G5, Factor!$B$5:$I$51, _xlpm.기본_색인번호, 0), _xlpm.소모탄환보정치, VLOOKUP($H5, Factor!$T$5:$AA$51, _xlpm.기본_색인번호, 0), _xlpm.지형보정치, VLOOKUP($I5, Factor!$K$12:$R$13, _xlpm.기본_색인번호, 0), _xlpm.공격속성보정치, VLOOKUP($J5, Factor!$K$5:$R$7, _xlpm.기본_색인번호, 0), _xlpm.피해범위보정치, INDEX(Factor!$AN$5:$AV$51, _xlfn.XMATCH(IF(OR($G5="blast", $G5="curved", $G5= "debuff"), $L5, 0), Factor!$AN$5:$AN$51, -1), _xlpm.추가_색인번호)-IF(AND(OR($G5="blast", $G5="curved", $G5= "debuff"), MOD($L5,1)<>0),INDEX(Factor!$AN$5:$AV$51, _xlfn.XMATCH(IF(OR($G5="blast", $G5="curved", $G5= "debuff"), $L5, 0), Factor!$AN$5:$AN$51, -1), 2)*MOD($L5,1)*10,0), _xlpm.상태이상보정치, VLOOKUP(IF($G5 = "debuff", $M5, "null"), Factor!$AX$5:$BE$51, _xlpm.기본_색인번호, 0), _xlpm.지속시간보정치, INDEX(Factor!$BG$5:$BO$51, _xlfn.XMATCH(IF(OR($G5 ="debuff", $G5 = "shot", $G5 = "pierce"), $O5, 0), Factor!$BG$5:$BG$51, -1), _xlpm.추가_색인번호)-IF(AND(OR($G5 ="debuff", $G5 = "shot", $G5 = "pierce"), MOD($O5, 1)<>0), 10*MOD($O5, 1)*INDEX(Factor!$BG$5:$BO$51, _xlfn.XMATCH(IF(OR($G5 ="debuff", $G5 = "shot", $G5 = "pierce"), $O5, 0), Factor!$BG$5:$BG$51, -1), 2), 0), _xlpm.탄환개수보정치, VLOOKUP(IF(OR($G5 = "curved", $G5 = "shot"), $Q5, 1), Factor!$BQ$5:$BX$51, _xlpm.기본_색인번호, 0), _xlpm.상태이상탄환생성위치보정치, IF($G5 = "debuff", VLOOKUP($R5, Factor!$K$18:$R$19, _xlpm.기본_색인번호, 0),1), _xlpm.상태이상탄환형태보정치, IF($G5 = "debuff", VLOOKUP($S5, Factor!$K$24:$R$25, _xlpm.기본_색인번호, 0),1), _xlpm.가격보정치, INDEX(Factor!$AE$5:$AL$51, _xlfn.XMATCH($F5,Factor!$AE$5:$AE$51, -1), _xlpm.기본_색인번호), _xlpm.구경보정치, VLOOKUP($D5, Factor!$BZ$5:$CJ$56, _xlpm.기본_색인번호, 0), _xlpm.결과, _xlpm.개별보정치*_xlpm.패턴보정치*_xlpm.소모탄환보정치*_xlpm.지형보정치*_xlpm.공격속성보정치*_xlpm.피해범위보정치*_xlpm.상태이상보정치*_xlpm.지속시간보정치*_xlpm.탄환개수보정치*_xlpm.상태이상탄환생성위치보정치*_xlpm.상태이상탄환형태보정치*_xlpm.가격보정치*_xlpm.구경보정치, _xlpm.결과)} -> 1 | AE5: {=_xlfn.LET(_xlpm.기본_색인번호, 6, _xlpm.추가_색인번호, 7, _xlpm.개별보정치, X5, _xlpm.패턴보정치, VLOOKUP($G5, Factor!$B$5:$I$51, _xlpm.기본_색인번호, 0), _xlpm.소모탄환보정치, VLOOKUP($H5, Factor!$T$5:$AA$51, _xlpm.기본_색인번호, 0), _xlpm.지형보정치, VLOOKUP($I5, Factor!$K$12:$R$13, _xlpm.기본_색인번호, 0), _xlpm.공격속성보정치, VLOOKUP($J5, Factor!$K$5:$R$7, _xlpm.기본_색인번호, 0), _xlpm.피해범위보정치, INDEX(Factor!$AN$5:$AV$51, _xlfn.XMATCH(IF(OR($G5="blast", $G5="curved", $G5= "debuff"), $L5, 0), Factor!$AN$5:$AN$51, -1), _xlpm.추가_색인번호)-IF(AND(OR($G5="blast", $G5="curved", $G5= "debuff"), MOD($L5,1)<>0),INDEX(Factor!$AN$5:$AV$51, _xlfn.XMATCH(IF(OR($G5="blast", $G5="curved", $G5= "debuff"), $L5, 0), Factor!$AN$5:$AN$51, -1), 2)*MOD($L5,1)*10,0), _xlpm.상태이상보정치, VLOOKUP(IF($G5 = "debuff", $M5, "null"), Factor!$AX$5:$BE$51, _xlpm.기본_색인번호, 0), _xlpm.지속시간보정치, INDEX(Factor!$BG$5:$BO$51, _xlfn.XMATCH(IF(OR($G5 ="debuff", $G5 = "shot", $G5 = "pierce"), $O5, 0), Factor!$BG$5:$BG$51, -1), _xlpm.추가_색인번호)-IF(AND(OR($G5 ="debuff", $G5 = "shot", $G5 = "pierce"), MOD($O5, 1)<>0), 10*MOD($O5, 1)*INDEX(Factor!$BG$5:$BO$51, _xlfn.XMATCH(IF(OR($G5 ="debuff", $G5 = "shot", $G5 = "pierce"), $O5, 0), Factor!$BG$5:$BG$51, -1), 2), 0), _xlpm.탄환개수보정치, VLOOKUP(IF(OR($G5 = "curved", $G5 = "shot"), $Q5, 1), Factor!$BQ$5:$BX$51, _xlpm.기본_색인번호, 0), _xlpm.상태이상탄환생성위치보정치, IF($G5 = "debuff", VLOOKUP($R5, Factor!$K$18:$R$19, _xlpm.기본_색인번호, 0),1), _xlpm.상태이상탄환형태보정치, IF($G5 = "debuff", VLOOKUP($S5, Factor!$K$24:$R$25, _xlpm.기본_색인번호, 0),1), _xlpm.가격보정치, INDEX(Factor!$AE$5:$AL$51, _xlfn.XMATCH($F5,Factor!$AE$5:$AE$51, -1), _xlpm.기본_색인번호), _xlpm.구경보정치, VLOOKUP($D5, Factor!$BZ$5:$CJ$56, _xlpm.기본_색인번호, 0), _xlpm.결과, _xlpm.개별보정치*_xlpm.패턴보정치*_xlpm.소모탄환보정치*_xlpm.지형보정치*_xlpm.공격속성보정치*_xlpm.피해범위보정치*_xlpm.상태이상보정치*_xlpm.지속시간보정치*_xlpm.탄환개수보정치*_xlpm.상태이상탄환생성위치보정치*_xlpm.상태이상탄환형태보정치*_xlpm.가격보정치*_xlpm.구경보정치, _xlpm.결과)} -> 1 | AF5: {=_xlfn.LET(_xlpm.기본_색인번호, 7, _xlpm.추가_색인번호, 8, _xlpm.개별보정치, Y5, _xlpm.패턴보정치, VLOOKUP($G5, Factor!$B$5:$I$51, _xlpm.기본_색인번호, 0), _xlpm.소모탄환보정치, VLOOKUP($H5, Factor!$T$5:$AA$51, _xlpm.기본_색인번호, 0), _xlpm.지형보정치, VLOOKUP($I5, Factor!$K$12:$R$13, _xlpm.기본_색인번호, 0), _xlpm.공격속성보정치, VLOOKUP($J5, Factor!$K$5:$R$7, _xlpm.기본_색인번호, 0), _xlpm.피해범위보정치, INDEX(Factor!$AN$5:$AV$51, _xlfn.XMATCH(IF(OR($G5="blast", $G5="curved", $G5= "debuff"), $L5, 0), Factor!$AN$5:$AN$51, -1), _xlpm.추가_색인번호)-IF(AND(OR($G5="blast", $G5="curved", $G5= "debuff"), MOD($L5,1)<>0),INDEX(Factor!$AN$5:$AV$51, _xlfn.XMATCH(IF(OR($G5="blast", $G5="curved", $G5= "debuff"), $L5, 0), Factor!$AN$5:$AN$51, -1), 2)*MOD($L5,1)*10,0), _xlpm.상태이상보정치, VLOOKUP(IF($G5 = "debuff", $M5, "null"), Factor!$AX$5:$BE$51, _xlpm.기본_색인번호, 0), _xlpm.지속시간보정치, INDEX(Factor!$BG$5:$BO$51, _xlfn.XMATCH(IF(OR($G5 ="debuff", $G5 = "shot", $G5 = "pierce"), $O5, 0), Factor!$BG$5:$BG$51, -1), _xlpm.추가_색인번호)-IF(AND(OR($G5 ="debuff", $G5 = "shot", $G5 = "pierce"), MOD($O5, 1)<>0), 10*MOD($O5, 1)*INDEX(Factor!$BG$5:$BO$51, _xlfn.XMATCH(IF(OR($G5 ="debuff", $G5 = "shot", $G5 = "pierce"), $O5, 0), Factor!$BG$5:$BG$51, -1), 2), 0), _xlpm.탄환개수보정치, VLOOKUP(IF(OR($G5 = "curved", $G5 = "shot"), $Q5, 1), Factor!$BQ$5:$BX$51, _xlpm.기본_색인번호, 0), _xlpm.상태이상탄환생성위치보정치, IF($G5 = "debuff", VLOOKUP($R5, Factor!$K$18:$R$19, _xlpm.기본_색인번호, 0),1), _xlpm.상태이상탄환형태보정치, IF($G5 = "debuff", VLOOKUP($S5, Factor!$K$24:$R$25, _xlpm.기본_색인번호, 0),1), _xlpm.가격보정치, INDEX(Factor!$AE$5:$AL$51, _xlfn.XMATCH($F5,Factor!$AE$5:$AE$51, -1), _xlpm.기본_색인번호), _xlpm.구경보정치, VLOOKUP($D5, Factor!$BZ$5:$CJ$56, _xlpm.기본_색인번호, 0), _xlpm.결과, _xlpm.개별보정치*_xlpm.패턴보정치*_xlpm.소모탄환보정치*_xlpm.지형보정치*_xlpm.공격속성보정치*_xlpm.피해범위보정치*_xlpm.상태이상보정치*_xlpm.지속시간보정치*_xlpm.탄환개수보정치*_xlpm.상태이상탄환생성위치보정치*_xlpm.상태이상탄환형태보정치*_xlpm.가격보정치*_xlpm.구경보정치, _xlpm.결과)} -> 120 | AG5: {=_xlfn.LET(_xlpm.기본_색인번호, 8, _xlpm.추가_색인번호, 9, _xlpm.개별보정치, Z5, _xlpm.패턴보정치, VLOOKUP($G5, Factor!$B$5:$I$51, _xlpm.기본_색인번호, 0), _xlpm.소모탄환보정치, VLOOKUP($H5, Factor!$T$5:$AA$51, _xlpm.기본_색인번호, 0), _xlpm.지형보정치, VLOOKUP($I5, Factor!$K$12:$R$13, _xlpm.기본_색인번호, 0), _xlpm.공격속성보정치, VLOOKUP($J5, Factor!$K$5:$R$7, _xlpm.기본_색인번호, 0), _xlpm.피해범위보정치, INDEX(Factor!$AN$5:$AV$51, _xlfn.XMATCH(IF(OR($G5="blast", $G5="curved", $G5= "debuff"), $L5, 0), Factor!$AN$5:$AN$51, -1), _xlpm.추가_색인번호)-IF(AND(OR($G5="blast", $G5="curved", $G5= "debuff"), MOD($L5,1)<>0),INDEX(Factor!$AN$5:$AV$51, _xlfn.XMATCH(IF(OR($G5="blast", $G5="curved", $G5= "debuff"), $L5, 0), Factor!$AN$5:$AN$51, -1), 2)*MOD($L5,1)*10,0), _xlpm.상태이상보정치, VLOOKUP(IF($G5 = "debuff", $M5, "null"), Factor!$AX$5:$BE$51, _xlpm.기본_색인번호, 0), _xlpm.지속시간보정치, INDEX(Factor!$BG$5:$BO$51, _xlfn.XMATCH(IF(OR($G5 ="debuff", $G5 = "shot", $G5 = "pierce"), $O5, 0), Factor!$BG$5:$BG$51, -1), _xlpm.추가_색인번호)-IF(AND(OR($G5 ="debuff", $G5 = "shot", $G5 = "pierce"), MOD($O5, 1)<>0), 10*MOD($O5, 1)*INDEX(Factor!$BG$5:$BO$51, _xlfn.XMATCH(IF(OR($G5 ="debuff", $G5 = "shot", $G5 = "pierce"), $O5, 0), Factor!$BG$5:$BG$51, -1), 2), 0), _xlpm.탄환개수보정치, VLOOKUP(IF(OR($G5 = "curved", $G5 = "shot"), $Q5, 1), Factor!$BQ$5:$BX$51, _xlpm.기본_색인번호, 0), _xlpm.상태이상탄환생성위치보정치, IF($G5 = "debuff", VLOOKUP($R5, Factor!$K$18:$R$19, _xlpm.기본_색인번호, 0),1), _xlpm.상태이상탄환형태보정치, IF($G5 = "debuff", VLOOKUP($S5, Factor!$K$24:$R$25, _xlpm.기본_색인번호, 0),1), _xlpm.가격보정치, INDEX(Factor!$AE$5:$AL$51, _xlfn.XMATCH($F5,Factor!$AE$5:$AE$51, -1), _xlpm.기본_색인번호), _xlpm.구경보정치, VLOOKUP($D5, Factor!$BZ$5:$CJ$56, _xlpm.기본_색인번호, 0), _xlpm.결과, _xlpm.개별보정치*_xlpm.패턴보정치*_xlpm.소모탄환보정치*_xlpm.지형보정치*_xlpm.공격속성보정치*_xlpm.피해범위보정치*_xlpm.상태이상보정치*_xlpm.지속시간보정치*_xlpm.탄환개수보정치*_xlpm.상태이상탄환생성위치보정치*_xlpm.상태이상탄환형태보정치*_xlpm.가격보정치*_xlpm.구경보정치, _xlpm.결과)} -> 1
A6: ="weapon_"&G6&"_"&VLOOKUP(H6, Factor!$T$5:$AB$7, 9, 0)&"_"&IF(COUNTIFS($G$4:G5, G6, $H$4:H5, H6)+1>=100, COUNTIFS($G$4:G5, G6, $H$4:H5, H6)+1,IF(COUNTIFS($G$4:G5, G6, $H$4:H5, H6)+1>=10, "0"&COUNTIFS($G$4:G5, G6, $H$4:H5, H6)+1, "00"&COUNTIFS($G$4:G5, G6, $H$4:H5, H6)+1)) -> weapon_single_Am_002 | B6: =C6&" "&IF(D6 = "none","", D6)&E6 -> 녹슨 5.56mm기관포 | C6: 녹슨 | D6: 5.56mm | E6: 기관포 | F6: =VLOOKUP(C6, Factor!$AD$5:$AE$15, 2, 0) -> 0 | G6: =VLOOKUP(E6, Factor!$CL$5:$CV$50, 2, 0) -> single | H6: =VLOOKUP(E6, Factor!$CL$5:$CV$50, 3, 0) -> ammo | I6: =VLOOKUP(E6, Factor!$CL$5:$CV$50, 4, 0) -> L | J6: =VLOOKUP(E6, Factor!$CL$5:$CV$50, 5, 0) -> spread | K6: 1 | L6: =VLOOKUP(E6, Factor!$CL$5:$CV$50, 6, 0)*K6*VLOOKUP(D6, Factor!$BZ$5:$CJ$49, 9, 0) -> 0 | M6: =VLOOKUP(E6, Factor!$CL$5:$CV$50, 7, 0) -> null | N6: 1 | O6: =VLOOKUP(E6, Factor!$CL$5:$CV$50, 8, 0)*N6*VLOOKUP(D6, Factor!$BZ$5:$CJ$49, 10, 0) -> 0 | P6: 1 | Q6: =VLOOKUP(E6, Factor!$CL$5:$CV$50, 9, 0)*P6*VLOOKUP(D6, Factor!$BZ$5:$CJ$49, 11, 0) -> 2 | R6: =VLOOKUP(E6, Factor!$CL$5:$CV$50, 10, 0) -> null | S6: =VLOOKUP(E6, Factor!$CL$5:$CV$50, 11, 0) -> null | T6: 1 | U6: 1 | V6: 1 | W6: 1 | X6: 1 | Y6: 1 | Z6: 1 | AA6: {=_xlfn.LET(_xlpm.기본_색인번호, 2, _xlpm.추가_색인번호, 3, _xlpm.개별보정치, T6, _xlpm.패턴보정치, VLOOKUP($G6, Factor!$B$5:$I$51, _xlpm.기본_색인번호, 0), _xlpm.소모탄환보정치, VLOOKUP($H6, Factor!$T$5:$AA$51, _xlpm.기본_색인번호, 0), _xlpm.지형보정치, VLOOKUP($I6, Factor!$K$12:$R$13, _xlpm.기본_색인번호, 0), _xlpm.공격속성보정치, VLOOKUP($J6, Factor!$K$5:$R$7, _xlpm.기본_색인번호, 0), _xlpm.피해범위보정치, INDEX(Factor!$AN$5:$AV$51, _xlfn.XMATCH(IF(OR($G6="blast", $G6="curved", $G6= "debuff"), $L6, 0), Factor!$AN$5:$AN$51, -1), _xlpm.추가_색인번호)-IF(AND(OR($G6="blast", $G6="curved", $G6= "debuff"), MOD($L6,1)<>0),INDEX(Factor!$AN$5:$AV$51, _xlfn.XMATCH(IF(OR($G6="blast", $G6="curved", $G6= "debuff"), $L6, 0), Factor!$AN$5:$AN$51, -1), 2)*MOD($L6,1)*10,0), _xlpm.상태이상보정치, VLOOKUP(IF($G6 = "debuff", $M6, "null"), Factor!$AX$5:$BE$51, _xlpm.기본_색인번호, 0), _xlpm.지속시간보정치, INDEX(Factor!$BG$5:$BO$51, _xlfn.XMATCH(IF(OR($G6 ="debuff", $G6 = "shot", $G6 = "pierce"), $O6, 0), Factor!$BG$5:$BG$51, -1), _xlpm.추가_색인번호)-IF(AND(OR($G6 ="debuff", $G6 = "shot", $G6 = "pierce"), MOD($O6, 1)<>0), 10*MOD($O6, 1)*INDEX(Factor!$BG$5:$BO$51, _xlfn.XMATCH(IF(OR($G6 ="debuff", $G6 = "shot", $G6 = "pierce"), $O6, 0), Factor!$BG$5:$BG$51, -1), 2), 0), _xlpm.탄환개수보정치, VLOOKUP(IF(OR($G6 = "curved", $G6 = "shot"), $Q6, 1), Factor!$BQ$5:$BX$51, _xlpm.기본_색인번호, 0), _xlpm.상태이상탄환생성위치보정치, IF($G6 = "debuff", VLOOKUP($R6, Factor!$K$18:$R$19, _xlpm.기본_색인번호, 0),1), _xlpm.상태이상탄환형태보정치, IF($G6 = "debuff", VLOOKUP($S6, Factor!$K$24:$R$25, _xlpm.기본_색인번호, 0),1), _xlpm.가격보정치, INDEX(Factor!$AE$5:$AL$51, _xlfn.XMATCH($F6,Factor!$AE$5:$AE$51, -1), _xlpm.기본_색인번호), _xlpm.구경보정치, VLOOKUP($D6, Factor!$BZ$5:$CJ$56, _xlpm.기본_색인번호, 0), _xlpm.결과, _xlpm.개별보정치*_xlpm.패턴보정치*_xlpm.소모탄환보정치*_xlpm.지형보정치*_xlpm.공격속성보정치*_xlpm.피해범위보정치*_xlpm.상태이상보정치*_xlpm.지속시간보정치*_xlpm.탄환개수보정치*_xlpm.상태이상탄환생성위치보정치*_xlpm.상태이상탄환형태보정치*_xlpm.가격보정치*_xlpm.구경보정치, _xlpm.결과)} -> 10 | AB6: {=_xlfn.LET(_xlpm.기본_색인번호, 3, _xlpm.추가_색인번호, 4, _xlpm.개별보정치, U6, _xlpm.패턴보정치, VLOOKUP($G6, Factor!$B$5:$I$51, _xlpm.기본_색인번호, 0), _xlpm.소모탄환보정치, VLOOKUP($H6, Factor!$T$5:$AA$51, _xlpm.기본_색인번호, 0), _xlpm.지형보정치, VLOOKUP($I6, Factor!$K$12:$R$13, _xlpm.기본_색인번호, 0), _xlpm.공격속성보정치, VLOOKUP($J6, Factor!$K$5:$R$7, _xlpm.기본_색인번호, 0), _xlpm.피해범위보정치, INDEX(Factor!$AN$5:$AV$51, _xlfn.XMATCH(IF(OR($G6="blast", $G6="curved", $G6= "debuff"), $L6, 0), Factor!$AN$5:$AN$51, -1), _xlpm.추가_색인번호)-IF(AND(OR($G6="blast", $G6="curved", $G6= "debuff"), MOD($L6,1)<>0),INDEX(Factor!$AN$5:$AV$51, _xlfn.XMATCH(IF(OR($G6="blast", $G6="curved", $G6= "debuff"), $L6, 0), Factor!$AN$5:$AN$51, -1), 2)*MOD($L6,1)*10,0), _xlpm.상태이상보정치, VLOOKUP(IF($G6 = "debuff", $M6, "null"), Factor!$AX$5:$BE$51, _xlpm.기본_색인번호, 0), _xlpm.지속시간보정치, INDEX(Factor!$BG$5:$BO$51, _xlfn.XMATCH(IF(OR($G6 ="debuff", $G6 = "shot", $G6 = "pierce"), $O6, 0), Factor!$BG$5:$BG$51, -1), _xlpm.추가_색인번호)-IF(AND(OR($G6 ="debuff", $G6 = "shot", $G6 = "pierce"), MOD($O6, 1)<>0), 10*MOD($O6, 1)*INDEX(Factor!$BG$5:$BO$51, _xlfn.XMATCH(IF(OR($G6 ="debuff", $G6 = "shot", $G6 = "pierce"), $O6, 0), Factor!$BG$5:$BG$51, -1), 2), 0), _xlpm.탄환개수보정치, VLOOKUP(IF(OR($G6 = "curved", $G6 = "shot"), $Q6, 1), Factor!$BQ$5:$BX$51, _xlpm.기본_색인번호, 0), _xlpm.상태이상탄환생성위치보정치, IF($G6 = "debuff", VLOOKUP($R6, Factor!$K$18:$R$19, _xlpm.기본_색인번호, 0),1), _xlpm.상태이상탄환형태보정치, IF($G6 = "debuff", VLOOKUP($S6, Factor!$K$24:$R$25, _xlpm.기본_색인번호, 0),1), _xlpm.가격보정치, INDEX(Factor!$AE$5:$AL$51, _xlfn.XMATCH($F6,Factor!$AE$5:$AE$51, -1), _xlpm.기본_색인번호), _xlpm.구경보정치, VLOOKUP($D6, Factor!$BZ$5:$CJ$56, _xlpm.기본_색인번호, 0), _xlpm.결과, _xlpm.개별보정치*_xlpm.패턴보정치*_xlpm.소모탄환보정치*_xlpm.지형보정치*_xlpm.공격속성보정치*_xlpm.피해범위보정치*_xlpm.상태이상보정치*_xlpm.지속시간보정치*_xlpm.탄환개수보정치*_xlpm.상태이상탄환생성위치보정치*_xlpm.상태이상탄환형태보정치*_xlpm.가격보정치*_xlpm.구경보정치, _xlpm.결과)} -> 4 | AC6: {=_xlfn.LET(_xlpm.기본_색인번호, 4, _xlpm.추가_색인번호, 5, _xlpm.개별보정치, V6, _xlpm.패턴보정치, VLOOKUP($G6, Factor!$B$5:$I$51, _xlpm.기본_색인번호, 0), _xlpm.소모탄환보정치, VLOOKUP($H6, Factor!$T$5:$AA$51, _xlpm.기본_색인번호, 0), _xlpm.지형보정치, VLOOKUP($I6, Factor!$K$12:$R$13, _xlpm.기본_색인번호, 0), _xlpm.공격속성보정치, VLOOKUP($J6, Factor!$K$5:$R$7, _xlpm.기본_색인번호, 0), _xlpm.피해범위보정치, INDEX(Factor!$AN$5:$AV$51, _xlfn.XMATCH(IF(OR($G6="blast", $G6="curved", $G6= "debuff"), $L6, 0), Factor!$AN$5:$AN$51, -1), _xlpm.추가_색인번호)-IF(AND(OR($G6="blast", $G6="curved", $G6= "debuff"), MOD($L6,1)<>0),INDEX(Factor!$AN$5:$AV$51, _xlfn.XMATCH(IF(OR($G6="blast", $G6="curved", $G6= "debuff"), $L6, 0), Factor!$AN$5:$AN$51, -1), 2)*MOD($L6,1)*10,0), _xlpm.상태이상보정치, VLOOKUP(IF($G6 = "debuff", $M6, "null"), Factor!$AX$5:$BE$51, _xlpm.기본_색인번호, 0), _xlpm.지속시간보정치, INDEX(Factor!$BG$5:$BO$51, _xlfn.XMATCH(IF(OR($G6 ="debuff", $G6 = "shot", $G6 = "pierce"), $O6, 0), Factor!$BG$5:$BG$51, -1), _xlpm.추가_색인번호)-IF(AND(OR($G6 ="debuff", $G6 = "shot", $G6 = "pierce"), MOD($O6, 1)<>0), 10*MOD($O6, 1)*INDEX(Factor!$BG$5:$BO$51, _xlfn.XMATCH(IF(OR($G6 ="debuff", $G6 = "shot", $G6 = "pierce"), $O6, 0), Factor!$BG$5:$BG$51, -1), 2), 0), _xlpm.탄환개수보정치, VLOOKUP(IF(OR($G6 = "curved", $G6 = "shot"), $Q6, 1), Factor!$BQ$5:$BX$51, _xlpm.기본_색인번호, 0), _xlpm.상태이상탄환생성위치보정치, IF($G6 = "debuff", VLOOKUP($R6, Factor!$K$18:$R$19, _xlpm.기본_색인번호, 0),1), _xlpm.상태이상탄환형태보정치, IF($G6 = "debuff", VLOOKUP($S6, Factor!$K$24:$R$25, _xlpm.기본_색인번호, 0),1), _xlpm.가격보정치, INDEX(Factor!$AE$5:$AL$51, _xlfn.XMATCH($F6,Factor!$AE$5:$AE$51, -1), _xlpm.기본_색인번호), _xlpm.구경보정치, VLOOKUP($D6, Factor!$BZ$5:$CJ$56, _xlpm.기본_색인번호, 0), _xlpm.결과, _xlpm.개별보정치*_xlpm.패턴보정치*_xlpm.소모탄환보정치*_xlpm.지형보정치*_xlpm.공격속성보정치*_xlpm.피해범위보정치*_xlpm.상태이상보정치*_xlpm.지속시간보정치*_xlpm.탄환개수보정치*_xlpm.상태이상탄환생성위치보정치*_xlpm.상태이상탄환형태보정치*_xlpm.가격보정치*_xlpm.구경보정치, _xlpm.결과)} -> 1 | AD6: {=_xlfn.LET(_xlpm.기본_색인번호, 5, _xlpm.추가_색인번호, 6, _xlpm.개별보정치, W6, _xlpm.패턴보정치, VLOOKUP($G6, Factor!$B$5:$I$51, _xlpm.기본_색인번호, 0), _xlpm.소모탄환보정치, VLOOKUP($H6, Factor!$T$5:$AA$51, _xlpm.기본_색인번호, 0), _xlpm.지형보정치, VLOOKUP($I6, Factor!$K$12:$R$13, _xlpm.기본_색인번호, 0), _xlpm.공격속성보정치, VLOOKUP($J6, Factor!$K$5:$R$7, _xlpm.기본_색인번호, 0), _xlpm.피해범위보정치, INDEX(Factor!$AN$5:$AV$51, _xlfn.XMATCH(IF(OR($G6="blast", $G6="curved", $G6= "debuff"), $L6, 0), Factor!$AN$5:$AN$51, -1), _xlpm.추가_색인번호)-IF(AND(OR($G6="blast", $G6="curved", $G6= "debuff"), MOD($L6,1)<>0),INDEX(Factor!$AN$5:$AV$51, _xlfn.XMATCH(IF(OR($G6="blast", $G6="curved", $G6= "debuff"), $L6, 0), Factor!$AN$5:$AN$51, -1), 2)*MOD($L6,1)*10,0), _xlpm.상태이상보정치, VLOOKUP(IF($G6 = "debuff", $M6, "null"), Factor!$AX$5:$BE$51, _xlpm.기본_색인번호, 0), _xlpm.지속시간보정치, INDEX(Factor!$BG$5:$BO$51, _xlfn.XMATCH(IF(OR($G6 ="debuff", $G6 = "shot", $G6 = "pierce"), $O6, 0), Factor!$BG$5:$BG$51, -1), _xlpm.추가_색인번호)-IF(AND(OR($G6 ="debuff", $G6 = "shot", $G6 = "pierce"), MOD($O6, 1)<>0), 10*MOD($O6, 1)*INDEX(Factor!$BG$5:$BO$51, _xlfn.XMATCH(IF(OR($G6 ="debuff", $G6 = "shot", $G6 = "pierce"), $O6, 0), Factor!$BG$5:$BG$51, -1), 2), 0), _xlpm.탄환개수보정치, VLOOKUP(IF(OR($G6 = "curved", $G6 = "shot"), $Q6, 1), Factor!$BQ$5:$BX$51, _xlpm.기본_색인번호, 0), _xlpm.상태이상탄환생성위치보정치, IF($G6 = "debuff", VLOOKUP($R6, Factor!$K$18:$R$19, _xlpm.기본_색인번호, 0),1), _xlpm.상태이상탄환형태보정치, IF($G6 = "debuff", VLOOKUP($S6, Factor!$K$24:$R$25, _xlpm.기본_색인번호, 0),1), _xlpm.가격보정치, INDEX(Factor!$AE$5:$AL$51, _xlfn.XMATCH($F6,Factor!$AE$5:$AE$51, -1), _xlpm.기본_색인번호), _xlpm.구경보정치, VLOOKUP($D6, Factor!$BZ$5:$CJ$56, _xlpm.기본_색인번호, 0), _xlpm.결과, _xlpm.개별보정치*_xlpm.패턴보정치*_xlpm.소모탄환보정치*_xlpm.지형보정치*_xlpm.공격속성보정치*_xlpm.피해범위보정치*_xlpm.상태이상보정치*_xlpm.지속시간보정치*_xlpm.탄환개수보정치*_xlpm.상태이상탄환생성위치보정치*_xlpm.상태이상탄환형태보정치*_xlpm.가격보정치*_xlpm.구경보정치, _xlpm.결과)} -> 1 | AE6: {=_xlfn.LET(_xlpm.기본_색인번호, 6, _xlpm.추가_색인번호, 7, _xlpm.개별보정치, X6, _xlpm.패턴보정치, VLOOKUP($G6, Factor!$B$5:$I$51, _xlpm.기본_색인번호, 0), _xlpm.소모탄환보정치, VLOOKUP($H6, Factor!$T$5:$AA$51, _xlpm.기본_색인번호, 0), _xlpm.지형보정치, VLOOKUP($I6, Factor!$K$12:$R$13, _xlpm.기본_색인번호, 0), _xlpm.공격속성보정치, VLOOKUP($J6, Factor!$K$5:$R$7, _xlpm.기본_색인번호, 0), _xlpm.피해범위보정치, INDEX(Factor!$AN$5:$AV$51, _xlfn.XMATCH(IF(OR($G6="blast", $G6="curved", $G6= "debuff"), $L6, 0), Factor!$AN$5:$AN$51, -1), _xlpm.추가_색인번호)-IF(AND(OR($G6="blast", $G6="curved", $G6= "debuff"), MOD($L6,1)<>0),INDEX(Factor!$AN$5:$AV$51, _xlfn.XMATCH(IF(OR($G6="blast", $G6="curved", $G6= "debuff"), $L6, 0), Factor!$AN$5:$AN$51, -1), 2)*MOD($L6,1)*10,0), _xlpm.상태이상보정치, VLOOKUP(IF($G6 = "debuff", $M6, "null"), Factor!$AX$5:$BE$51, _xlpm.기본_색인번호, 0), _xlpm.지속시간보정치, INDEX(Factor!$BG$5:$BO$51, _xlfn.XMATCH(IF(OR($G6 ="debuff", $G6 = "shot", $G6 = "pierce"), $O6, 0), Factor!$BG$5:$BG$51, -1), _xlpm.추가_색인번호)-IF(AND(OR($G6 ="debuff", $G6 = "shot", $G6 = "pierce"), MOD($O6, 1)<>0), 10*MOD($O6, 1)*INDEX(Factor!$BG$5:$BO$51, _xlfn.XMATCH(IF(OR($G6 ="debuff", $G6 = "shot", $G6 = "pierce"), $O6, 0), Factor!$BG$5:$BG$51, -1), 2), 0), _xlpm.탄환개수보정치, VLOOKUP(IF(OR($G6 = "curved", $G6 = "shot"), $Q6, 1), Factor!$BQ$5:$BX$51, _xlpm.기본_색인번호, 0), _xlpm.상태이상탄환생성위치보정치, IF($G6 = "debuff", VLOOKUP($R6, Factor!$K$18:$R$19, _xlpm.기본_색인번호, 0),1), _xlpm.상태이상탄환형태보정치, IF($G6 = "debuff", VLOOKUP($S6, Factor!$K$24:$R$25, _xlpm.기본_색인번호, 0),1), _xlpm.가격보정치, INDEX(Factor!$AE$5:$AL$51, _xlfn.XMATCH($F6,Factor!$AE$5:$AE$51, -1), _xlpm.기본_색인번호), _xlpm.구경보정치, VLOOKUP($D6, Factor!$BZ$5:$CJ$56, _xlpm.기본_색인번호, 0), _xlpm.결과, _xlpm.개별보정치*_xlpm.패턴보정치*_xlpm.소모탄환보정치*_xlpm.지형보정치*_xlpm.공격속성보정치*_xlpm.피해범위보정치*_xlpm.상태이상보정치*_xlpm.지속시간보정치*_xlpm.탄환개수보정치*_xlpm.상태이상탄환생성위치보정치*_xlpm.상태이상탄환형태보정치*_xlpm.가격보정치*_xlpm.구경보정치, _xlpm.결과)} -> 1 | AF6: {=_xlfn.LET(_xlpm.기본_색인번호, 7, _xlpm.추가_색인번호, 8, _xlpm.개별보정치, Y6, _xlpm.패턴보정치, VLOOKUP($G6, Factor!$B$5:$I$51, _xlpm.기본_색인번호, 0), _xlpm.소모탄환보정치, VLOOKUP($H6, Factor!$T$5:$AA$51, _xlpm.기본_색인번호, 0), _xlpm.지형보정치, VLOOKUP($I6, Factor!$K$12:$R$13, _xlpm.기본_색인번호, 0), _xlpm.공격속성보정치, VLOOKUP($J6, Factor!$K$5:$R$7, _xlpm.기본_색인번호, 0), _xlpm.피해범위보정치, INDEX(Factor!$AN$5:$AV$51, _xlfn.XMATCH(IF(OR($G6="blast", $G6="curved", $G6= "debuff"), $L6, 0), Factor!$AN$5:$AN$51, -1), _xlpm.추가_색인번호)-IF(AND(OR($G6="blast", $G6="curved", $G6= "debuff"), MOD($L6,1)<>0),INDEX(Factor!$AN$5:$AV$51, _xlfn.XMATCH(IF(OR($G6="blast", $G6="curved", $G6= "debuff"), $L6, 0), Factor!$AN$5:$AN$51, -1), 2)*MOD($L6,1)*10,0), _xlpm.상태이상보정치, VLOOKUP(IF($G6 = "debuff", $M6, "null"), Factor!$AX$5:$BE$51, _xlpm.기본_색인번호, 0), _xlpm.지속시간보정치, INDEX(Factor!$BG$5:$BO$51, _xlfn.XMATCH(IF(OR($G6 ="debuff", $G6 = "shot", $G6 = "pierce"), $O6, 0), Factor!$BG$5:$BG$51, -1), _xlpm.추가_색인번호)-IF(AND(OR($G6 ="debuff", $G6 = "shot", $G6 = "pierce"), MOD($O6, 1)<>0), 10*MOD($O6, 1)*INDEX(Factor!$BG$5:$BO$51, _xlfn.XMATCH(IF(OR($G6 ="debuff", $G6 = "shot", $G6 = "pierce"), $O6, 0), Factor!$BG$5:$BG$51, -1), 2), 0), _xlpm.탄환개수보정치, VLOOKUP(IF(OR($G6 = "curved", $G6 = "shot"), $Q6, 1), Factor!$BQ$5:$BX$51, _xlpm.기본_색인번호, 0), _xlpm.상태이상탄환생성위치보정치, IF($G6 = "debuff", VLOOKUP($R6, Factor!$K$18:$R$19, _xlpm.기본_색인번호, 0),1), _xlpm.상태이상탄환형태보정치, IF($G6 = "debuff", VLOOKUP($S6, Factor!$K$24:$R$25, _xlpm.기본_색인번호, 0),1), _xlpm.가격보정치, INDEX(Factor!$AE$5:$AL$51, _xlfn.XMATCH($F6,Factor!$AE$5:$AE$51, -1), _xlpm.기본_색인번호), _xlpm.구경보정치, VLOOKUP($D6, Factor!$BZ$5:$CJ$56, _xlpm.기본_색인번호, 0), _xlpm.결과, _xlpm.개별보정치*_xlpm.패턴보정치*_xlpm.소모탄환보정치*_xlpm.지형보정치*_xlpm.공격속성보정치*_xlpm.피해범위보정치*_xlpm.상태이상보정치*_xlpm.지속시간보정치*_xlpm.탄환개수보정치*_xlpm.상태이상탄환생성위치보정치*_xlpm.상태이상탄환형태보정치*_xlpm.가격보정치*_xlpm.구경보정치, _xlpm.결과)} -> 120 | AG6: {=_xlfn.LET(_xlpm.기본_색인번호, 8, _xlpm.추가_색인번호, 9, _xlpm.개별보정치, Z6, _xlpm.패턴보정치, VLOOKUP($G6, Factor!$B$5:$I$51, _xlpm.기본_색인번호, 0), _xlpm.소모탄환보정치, VLOOKUP($H6, Factor!$T$5:$AA$51, _xlpm.기본_색인번호, 0), _xlpm.지형보정치, VLOOKUP($I6, Factor!$K$12:$R$13, _xlpm.기본_색인번호, 0), _xlpm.공격속성보정치, VLOOKUP($J6, Factor!$K$5:$R$7, _xlpm.기본_색인번호, 0), _xlpm.피해범위보정치, INDEX(Factor!$AN$5:$AV$51, _xlfn.XMATCH(IF(OR($G6="blast", $G6="curved", $G6= "debuff"), $L6, 0), Factor!$AN$5:$AN$51, -1), _xlpm.추가_색인번호)-IF(AND(OR($G6="blast", $G6="curved", $G6= "debuff"), MOD($L6,1)<>0),INDEX(Factor!$AN$5:$AV$51, _xlfn.XMATCH(IF(OR($G6="blast", $G6="curved", $G6= "debuff"), $L6, 0), Factor!$AN$5:$AN$51, -1), 2)*MOD($L6,1)*10,0), _xlpm.상태이상보정치, VLOOKUP(IF($G6 = "debuff", $M6, "null"), Factor!$AX$5:$BE$51, _xlpm.기본_색인번호, 0), _xlpm.지속시간보정치, INDEX(Factor!$BG$5:$BO$51, _xlfn.XMATCH(IF(OR($G6 ="debuff", $G6 = "shot", $G6 = "pierce"), $O6, 0), Factor!$BG$5:$BG$51, -1), _xlpm.추가_색인번호)-IF(AND(OR($G6 ="debuff", $G6 = "shot", $G6 = "pierce"), MOD($O6, 1)<>0), 10*MOD($O6, 1)*INDEX(Factor!$BG$5:$BO$51, _xlfn.XMATCH(IF(OR($G6 ="debuff", $G6 = "shot", $G6 = "pierce"), $O6, 0), Factor!$BG$5:$BG$51, -1), 2), 0), _xlpm.탄환개수보정치, VLOOKUP(IF(OR($G6 = "curved", $G6 = "shot"), $Q6, 1), Factor!$BQ$5:$BX$51, _xlpm.기본_색인번호, 0), _xlpm.상태이상탄환생성위치보정치, IF($G6 = "debuff", VLOOKUP($R6, Factor!$K$18:$R$19, _xlpm.기본_색인번호, 0),1), _xlpm.상태이상탄환형태보정치, IF($G6 = "debuff", VLOOKUP($S6, Factor!$K$24:$R$25, _xlpm.기본_색인번호, 0),1), _xlpm.가격보정치, INDEX(Factor!$AE$5:$AL$51, _xlfn.XMATCH($F6,Factor!$AE$5:$AE$51, -1), _xlpm.기본_색인번호), _xlpm.구경보정치, VLOOKUP($D6, Factor!$BZ$5:$CJ$56, _xlpm.기본_색인번호, 0), _xlpm.결과, _xlpm.개별보정치*_xlpm.패턴보정치*_xlpm.소모탄환보정치*_xlpm.지형보정치*_xlpm.공격속성보정치*_xlpm.피해범위보정치*_xlpm.상태이상보정치*_xlpm.지속시간보정치*_xlpm.탄환개수보정치*_xlpm.상태이상탄환생성위치보정치*_xlpm.상태이상탄환형태보정치*_xlpm.가격보정치*_xlpm.구경보정치, _xlpm.결과)} -> 1
A7: ="weapon_"&G7&"_"&VLOOKUP(H7, Factor!$T$5:$AB$7, 9, 0)&"_"&IF(COUNTIFS($G$4:G6, G7, $H$4:H6, H7)+1>=100, COUNTIFS($G$4:G6, G7, $H$4:H6, H7)+1,IF(COUNTIFS($G$4:G6, G7, $H$4:H6, H7)+1>=10, "0"&COUNTIFS($G$4:G6, G7, $H$4:H6, H7)+1, "00"&COUNTIFS($G$4:G6, G7, $H$4:H6, H7)+1)) -> weapon_single_Am_003 | B7: =C7&" "&IF(D7 = "none","", D7)&E7 -> 녹슨 7.62mm기관포 | C7: 녹슨 | D7: 7.62mm | E7: 기관포 | F7: =VLOOKUP(C7, Factor!$AD$5:$AE$15, 2, 0) -> 0 | G7: =VLOOKUP(E7, Factor!$CL$5:$CV$50, 2, 0) -> single | H7: =VLOOKUP(E7, Factor!$CL$5:$CV$50, 3, 0) -> ammo | I7: =VLOOKUP(E7, Factor!$CL$5:$CV$50, 4, 0) -> L | J7: =VLOOKUP(E7, Factor!$CL$5:$CV$50, 5, 0) -> spread | K7: 1 | L7: =VLOOKUP(E7, Factor!$CL$5:$CV$50, 6, 0)*K7*VLOOKUP(D7, Factor!$BZ$5:$CJ$49, 9, 0) -> 0 | M7: =VLOOKUP(E7, Factor!$CL$5:$CV$50, 7, 0) -> null | N7: 1 | O7: =VLOOKUP(E7, Factor!$CL$5:$CV$50, 8, 0)*N7*VLOOKUP(D7, Factor!$BZ$5:$CJ$49, 10, 0) -> 0 | P7: 1 | Q7: =VLOOKUP(E7, Factor!$CL$5:$CV$50, 9, 0)*P7*VLOOKUP(D7, Factor!$BZ$5:$CJ$49, 11, 0) -> 3 | R7: =VLOOKUP(E7, Factor!$CL$5:$CV$50, 10, 0) -> null | S7: =VLOOKUP(E7, Factor!$CL$5:$CV$50, 11, 0) -> null | T7: 1 | U7: 1 | V7: 1 | W7: 1 | X7: 1 | Y7: 1 | Z7: 1 | AA7: {=_xlfn.LET(_xlpm.기본_색인번호, 2, _xlpm.추가_색인번호, 3, _xlpm.개별보정치, T7, _xlpm.패턴보정치, VLOOKUP($G7, Factor!$B$5:$I$51, _xlpm.기본_색인번호, 0), _xlpm.소모탄환보정치, VLOOKUP($H7, Factor!$T$5:$AA$51, _xlpm.기본_색인번호, 0), _xlpm.지형보정치, VLOOKUP($I7, Factor!$K$12:$R$13, _xlpm.기본_색인번호, 0), _xlpm.공격속성보정치, VLOOKUP($J7, Factor!$K$5:$R$7, _xlpm.기본_색인번호, 0), _xlpm.피해범위보정치, INDEX(Factor!$AN$5:$AV$51, _xlfn.XMATCH(IF(OR($G7="blast", $G7="curved", $G7= "debuff"), $L7, 0), Factor!$AN$5:$AN$51, -1), _xlpm.추가_색인번호)-IF(AND(OR($G7="blast", $G7="curved", $G7= "debuff"), MOD($L7,1)<>0),INDEX(Factor!$AN$5:$AV$51, _xlfn.XMATCH(IF(OR($G7="blast", $G7="curved", $G7= "debuff"), $L7, 0), Factor!$AN$5:$AN$51, -1), 2)*MOD($L7,1)*10,0), _xlpm.상태이상보정치, VLOOKUP(IF($G7 = "debuff", $M7, "null"), Factor!$AX$5:$BE$51, _xlpm.기본_색인번호, 0), _xlpm.지속시간보정치, INDEX(Factor!$BG$5:$BO$51, _xlfn.XMATCH(IF(OR($G7 ="debuff", $G7 = "shot", $G7 = "pierce"), $O7, 0), Factor!$BG$5:$BG$51, -1), _xlpm.추가_색인번호)-IF(AND(OR($G7 ="debuff", $G7 = "shot", $G7 = "pierce"), MOD($O7, 1)<>0), 10*MOD($O7, 1)*INDEX(Factor!$BG$5:$BO$51, _xlfn.XMATCH(IF(OR($G7 ="debuff", $G7 = "shot", $G7 = "pierce"), $O7, 0), Factor!$BG$5:$BG$51, -1), 2), 0), _xlpm.탄환개수보정치, VLOOKUP(IF(OR($G7 = "curved", $G7 = "shot"), $Q7, 1), Factor!$BQ$5:$BX$51, _xlpm.기본_색인번호, 0), _xlpm.상태이상탄환생성위치보정치, IF($G7 = "debuff", VLOOKUP($R7, Factor!$K$18:$R$19, _xlpm.기본_색인번호, 0),1), _xlpm.상태이상탄환형태보정치, IF($G7 = "debuff", VLOOKUP($S7, Factor!$K$24:$R$25, _xlpm.기본_색인번호, 0),1), _xlpm.가격보정치, INDEX(Factor!$AE$5:$AL$51, _xlfn.XMATCH($F7,Factor!$AE$5:$AE$51, -1), _xlpm.기본_색인번호), _xlpm.구경보정치, VLOOKUP($D7, Factor!$BZ$5:$CJ$56, _xlpm.기본_색인번호, 0), _xlpm.결과, _xlpm.개별보정치*_xlpm.패턴보정치*_xlpm.소모탄환보정치*_xlpm.지형보정치*_xlpm.공격속성보정치*_xlpm.피해범위보정치*_xlpm.상태이상보정치*_xlpm.지속시간보정치*_xlpm.탄환개수보정치*_xlpm.상태이상탄환생성위치보정치*_xlpm.상태이상탄환형태보정치*_xlpm.가격보정치*_xlpm.구경보정치, _xlpm.결과)} -> 10 | AB7: {=_xlfn.LET(_xlpm.기본_색인번호, 3, _xlpm.추가_색인번호, 4, _xlpm.개별보정치, U7, _xlpm.패턴보정치, VLOOKUP($G7, Factor!$B$5:$I$51, _xlpm.기본_색인번호, 0), _xlpm.소모탄환보정치, VLOOKUP($H7, Factor!$T$5:$AA$51, _xlpm.기본_색인번호, 0), _xlpm.지형보정치, VLOOKUP($I7, Factor!$K$12:$R$13, _xlpm.기본_색인번호, 0), _xlpm.공격속성보정치, VLOOKUP($J7, Factor!$K$5:$R$7, _xlpm.기본_색인번호, 0), _xlpm.피해범위보정치, INDEX(Factor!$AN$5:$AV$51, _xlfn.XMATCH(IF(OR($G7="blast", $G7="curved", $G7= "debuff"), $L7, 0), Factor!$AN$5:$AN$51, -1), _xlpm.추가_색인번호)-IF(AND(OR($G7="blast", $G7="curved", $G7= "debuff"), MOD($L7,1)<>0),INDEX(Factor!$AN$5:$AV$51, _xlfn.XMATCH(IF(OR($G7="blast", $G7="curved", $G7= "debuff"), $L7, 0), Factor!$AN$5:$AN$51, -1), 2)*MOD($L7,1)*10,0), _xlpm.상태이상보정치, VLOOKUP(IF($G7 = "debuff", $M7, "null"), Factor!$AX$5:$BE$51, _xlpm.기본_색인번호, 0), _xlpm.지속시간보정치, INDEX(Factor!$BG$5:$BO$51, _xlfn.XMATCH(IF(OR($G7 ="debuff", $G7 = "shot", $G7 = "pierce"), $O7, 0), Factor!$BG$5:$BG$51, -1), _xlpm.추가_색인번호)-IF(AND(OR($G7 ="debuff", $G7 = "shot", $G7 = "pierce"), MOD($O7, 1)<>0), 10*MOD($O7, 1)*INDEX(Factor!$BG$5:$BO$51, _xlfn.XMATCH(IF(OR($G7 ="debuff", $G7 = "shot", $G7 = "pierce"), $O7, 0), Factor!$BG$5:$BG$51, -1), 2), 0), _xlpm.탄환개수보정치, VLOOKUP(IF(OR($G7 = "curved", $G7 = "shot"), $Q7, 1), Factor!$BQ$5:$BX$51, _xlpm.기본_색인번호, 0), _xlpm.상태이상탄환생성위치보정치, IF($G7 = "debuff", VLOOKUP($R7, Factor!$K$18:$R$19, _xlpm.기본_색인번호, 0),1), _xlpm.상태이상탄환형태보정치, IF($G7 = "debuff", VLOOKUP($S7, Factor!$K$24:$R$25, _xlpm.기본_색인번호, 0),1), _xlpm.가격보정치, INDEX(Factor!$AE$5:$AL$51, _xlfn.XMATCH($F7,Factor!$AE$5:$AE$51, -1), _xlpm.기본_색인번호), _xlpm.구경보정치, VLOOKUP($D7, Factor!$BZ$5:$CJ$56, _xlpm.기본_색인번호, 0), _xlpm.결과, _xlpm.개별보정치*_xlpm.패턴보정치*_xlpm.소모탄환보정치*_xlpm.지형보정치*_xlpm.공격속성보정치*_xlpm.피해범위보정치*_xlpm.상태이상보정치*_xlpm.지속시간보정치*_xlpm.탄환개수보정치*_xlpm.상태이상탄환생성위치보정치*_xlpm.상태이상탄환형태보정치*_xlpm.가격보정치*_xlpm.구경보정치, _xlpm.결과)} -> 4 | AC7: {=_xlfn.LET(_xlpm.기본_색인번호, 4, _xlpm.추가_색인번호, 5, _xlpm.개별보정치, V7, _xlpm.패턴보정치, VLOOKUP($G7, Factor!$B$5:$I$51, _xlpm.기본_색인번호, 0), _xlpm.소모탄환보정치, VLOOKUP($H7, Factor!$T$5:$AA$51, _xlpm.기본_색인번호, 0), _xlpm.지형보정치, VLOOKUP($I7, Factor!$K$12:$R$13, _xlpm.기본_색인번호, 0), _xlpm.공격속성보정치, VLOOKUP($J7, Factor!$K$5:$R$7, _xlpm.기본_색인번호, 0), _xlpm.피해범위보정치, INDEX(Factor!$AN$5:$AV$51, _xlfn.XMATCH(IF(OR($G7="blast", $G7="curved", $G7= "debuff"), $L7, 0), Factor!$AN$5:$AN$51, -1), _xlpm.추가_색인번호)-IF(AND(OR($G7="blast", $G7="curved", $G7= "debuff"), MOD($L7,1)<>0),INDEX(Factor!$AN$5:$AV$51, _xlfn.XMATCH(IF(OR($G7="blast", $G7="curved", $G7= "debuff"), $L7, 0), Factor!$AN$5:$AN$51, -1), 2)*MOD($L7,1)*10,0), _xlpm.상태이상보정치, VLOOKUP(IF($G7 = "debuff", $M7, "null"), Factor!$AX$5:$BE$51, _xlpm.기본_색인번호, 0), _xlpm.지속시간보정치, INDEX(Factor!$BG$5:$BO$51, _xlfn.XMATCH(IF(OR($G7 ="debuff", $G7 = "shot", $G7 = "pierce"), $O7, 0), Factor!$BG$5:$BG$51, -1), _xlpm.추가_색인번호)-IF(AND(OR($G7 ="debuff", $G7 = "shot", $G7 = "pierce"), MOD($O7, 1)<>0), 10*MOD($O7, 1)*INDEX(Factor!$BG$5:$BO$51, _xlfn.XMATCH(IF(OR($G7 ="debuff", $G7 = "shot", $G7 = "pierce"), $O7, 0), Factor!$BG$5:$BG$51, -1), 2), 0), _xlpm.탄환개수보정치, VLOOKUP(IF(OR($G7 = "curved", $G7 = "shot"), $Q7, 1), Factor!$BQ$5:$BX$51, _xlpm.기본_색인번호, 0), _xlpm.상태이상탄환생성위치보정치, IF($G7 = "debuff", VLOOKUP($R7, Factor!$K$18:$R$19, _xlpm.기본_색인번호, 0),1), _xlpm.상태이상탄환형태보정치, IF($G7 = "debuff", VLOOKUP($S7, Factor!$K$24:$R$25, _xlpm.기본_색인번호, 0),1), _xlpm.가격보정치, INDEX(Factor!$AE$5:$AL$51, _xlfn.XMATCH($F7,Factor!$AE$5:$AE$51, -1), _xlpm.기본_색인번호), _xlpm.구경보정치, VLOOKUP($D7, Factor!$BZ$5:$CJ$56, _xlpm.기본_색인번호, 0), _xlpm.결과, _xlpm.개별보정치*_xlpm.패턴보정치*_xlpm.소모탄환보정치*_xlpm.지형보정치*_xlpm.공격속성보정치*_xlpm.피해범위보정치*_xlpm.상태이상보정치*_xlpm.지속시간보정치*_xlpm.탄환개수보정치*_xlpm.상태이상탄환생성위치보정치*_xlpm.상태이상탄환형태보정치*_xlpm.가격보정치*_xlpm.구경보정치, _xlpm.결과)} -> 1 | AD7: {=_xlfn.LET(_xlpm.기본_색인번호, 5, _xlpm.추가_색인번호, 6, _xlpm.개별보정치, W7, _xlpm.패턴보정치, VLOOKUP($G7, Factor!$B$5:$I$51, _xlpm.기본_색인번호, 0), _xlpm.소모탄환보정치, VLOOKUP($H7, Factor!$T$5:$AA$51, _xlpm.기본_색인번호, 0), _xlpm.지형보정치, VLOOKUP($I7, Factor!$K$12:$R$13, _xlpm.기본_색인번호, 0), _xlpm.공격속성보정치, VLOOKUP($J7, Factor!$K$5:$R$7, _xlpm.기본_색인번호, 0), _xlpm.피해범위보정치, INDEX(Factor!$AN$5:$AV$51, _xlfn.XMATCH(IF(OR($G7="blast", $G7="curved", $G7= "debuff"), $L7, 0), Factor!$AN$5:$AN$51, -1), _xlpm.추가_색인번호)-IF(AND(OR($G7="blast", $G7="curved", $G7= "debuff"), MOD($L7,1)<>0),INDEX(Factor!$AN$5:$AV$51, _xlfn.XMATCH(IF(OR($G7="blast", $G7="curved", $G7= "debuff"), $L7, 0), Factor!$AN$5:$AN$51, -1), 2)*MOD($L7,1)*10,0), _xlpm.상태이상보정치, VLOOKUP(IF($G7 = "debuff", $M7, "null"), Factor!$AX$5:$BE$51, _xlpm.기본_색인번호, 0), _xlpm.지속시간보정치, INDEX(Factor!$BG$5:$BO$51, _xlfn.XMATCH(IF(OR($G7 ="debuff", $G7 = "shot", $G7 = "pierce"), $O7, 0), Factor!$BG$5:$BG$51, -1), _xlpm.추가_색인번호)-IF(AND(OR($G7 ="debuff", $G7 = "shot", $G7 = "pierce"), MOD($O7, 1)<>0), 10*MOD($O7, 1)*INDEX(Factor!$BG$5:$BO$51, _xlfn.XMATCH(IF(OR($G7 ="debuff", $G7 = "shot", $G7 = "pierce"), $O7, 0), Factor!$BG$5:$BG$51, -1), 2), 0), _xlpm.탄환개수보정치, VLOOKUP(IF(OR($G7 = "curved", $G7 = "shot"), $Q7, 1), Factor!$BQ$5:$BX$51, _xlpm.기본_색인번호, 0), _xlpm.상태이상탄환생성위치보정치, IF($G7 = "debuff", VLOOKUP($R7, Factor!$K$18:$R$19, _xlpm.기본_색인번호, 0),1), _xlpm.상태이상탄환형태보정치, IF($G7 = "debuff", VLOOKUP($S7, Factor!$K$24:$R$25, _xlpm.기본_색인번호, 0),1), _xlpm.가격보정치, INDEX(Factor!$AE$5:$AL$51, _xlfn.XMATCH($F7,Factor!$AE$5:$AE$51, -1), _xlpm.기본_색인번호), _xlpm.구경보정치, VLOOKUP($D7, Factor!$BZ$5:$CJ$56, _xlpm.기본_색인번호, 0), _xlpm.결과, _xlpm.개별보정치*_xlpm.패턴보정치*_xlpm.소모탄환보정치*_xlpm.지형보정치*_xlpm.공격속성보정치*_xlpm.피해범위보정치*_xlpm.상태이상보정치*_xlpm.지속시간보정치*_xlpm.탄환개수보정치*_xlpm.상태이상탄환생성위치보정치*_xlpm.상태이상탄환형태보정치*_xlpm.가격보정치*_xlpm.구경보정치, _xlpm.결과)} -> 1 | AE7: {=_xlfn.LET(_xlpm.기본_색인번호, 6, _xlpm.추가_색인번호, 7, _xlpm.개별보정치, X7, _xlpm.패턴보정치, VLOOKUP($G7, Factor!$B$5:$I$51, _xlpm.기본_색인번호, 0), _xlpm.소모탄환보정치, VLOOKUP($H7, Factor!$T$5:$AA$51, _xlpm.기본_색인번호, 0), _xlpm.지형보정치, VLOOKUP($I7, Factor!$K$12:$R$13, _xlpm.기본_색인번호, 0), _xlpm.공격속성보정치, VLOOKUP($J7, Factor!$K$5:$R$7, _xlpm.기본_색인번호, 0), _xlpm.피해범위보정치, INDEX(Factor!$AN$5:$AV$51, _xlfn.XMATCH(IF(OR($G7="blast", $G7="curved", $G7= "debuff"), $L7, 0), Factor!$AN$5:$AN$51, -1), _xlpm.추가_색인번호)-IF(AND(OR($G7="blast", $G7="curved", $G7= "debuff"), MOD($L7,1)<>0),INDEX(Factor!$AN$5:$AV$51, _xlfn.XMATCH(IF(OR($G7="blast", $G7="curved", $G7= "debuff"), $L7, 0), Factor!$AN$5:$AN$51, -1), 2)*MOD($L7,1)*10,0), _xlpm.상태이상보정치, VLOOKUP(IF($G7 = "debuff", $M7, "null"), Factor!$AX$5:$BE$51, _xlpm.기본_색인번호, 0), _xlpm.지속시간보정치, INDEX(Factor!$BG$5:$BO$51, _xlfn.XMATCH(IF(OR($G7 ="debuff", $G7 = "shot", $G7 = "pierce"), $O7, 0), Factor!$BG$5:$BG$51, -1), _xlpm.추가_색인번호)-IF(AND(OR($G7 ="debuff", $G7 = "shot", $G7 = "pierce"), MOD($O7, 1)<>0), 10*MOD($O7, 1)*INDEX(Factor!$BG$5:$BO$51, _xlfn.XMATCH(IF(OR($G7 ="debuff", $G7 = "shot", $G7 = "pierce"), $O7, 0), Factor!$BG$5:$BG$51, -1), 2), 0), _xlpm.탄환개수보정치, VLOOKUP(IF(OR($G7 = "curved", $G7 = "shot"), $Q7, 1), Factor!$BQ$5:$BX$51, _xlpm.기본_색인번호, 0), _xlpm.상태이상탄환생성위치보정치, IF($G7 = "debuff", VLOOKUP($R7, Factor!$K$18:$R$19, _xlpm.기본_색인번호, 0),1), _xlpm.상태이상탄환형태보정치, IF($G7 = "debuff", VLOOKUP($S7, Factor!$K$24:$R$25, _xlpm.기본_색인번호, 0),1), _xlpm.가격보정치, INDEX(Factor!$AE$5:$AL$51, _xlfn.XMATCH($F7,Factor!$AE$5:$AE$51, -1), _xlpm.기본_색인번호), _xlpm.구경보정치, VLOOKUP($D7, Factor!$BZ$5:$CJ$56, _xlpm.기본_색인번호, 0), _xlpm.결과, _xlpm.개별보정치*_xlpm.패턴보정치*_xlpm.소모탄환보정치*_xlpm.지형보정치*_xlpm.공격속성보정치*_xlpm.피해범위보정치*_xlpm.상태이상보정치*_xlpm.지속시간보정치*_xlpm.탄환개수보정치*_xlpm.상태이상탄환생성위치보정치*_xlpm.상태이상탄환형태보정치*_xlpm.가격보정치*_xlpm.구경보정치, _xlpm.결과)} -> 1 | AF7: {=_xlfn.LET(_xlpm.기본_색인번호, 7, _xlpm.추가_색인번호, 8, _xlpm.개별보정치, Y7, _xlpm.패턴보정치, VLOOKUP($G7, Factor!$B$5:$I$51, _xlpm.기본_색인번호, 0), _xlpm.소모탄환보정치, VLOOKUP($H7, Factor!$T$5:$AA$51, _xlpm.기본_색인번호, 0), _xlpm.지형보정치, VLOOKUP($I7, Factor!$K$12:$R$13, _xlpm.기본_색인번호, 0), _xlpm.공격속성보정치, VLOOKUP($J7, Factor!$K$5:$R$7, _xlpm.기본_색인번호, 0), _xlpm.피해범위보정치, INDEX(Factor!$AN$5:$AV$51, _xlfn.XMATCH(IF(OR($G7="blast", $G7="curved", $G7= "debuff"), $L7, 0), Factor!$AN$5:$AN$51, -1), _xlpm.추가_색인번호)-IF(AND(OR($G7="blast", $G7="curved", $G7= "debuff"), MOD($L7,1)<>0),INDEX(Factor!$AN$5:$AV$51, _xlfn.XMATCH(IF(OR($G7="blast", $G7="curved", $G7= "debuff"), $L7, 0), Factor!$AN$5:$AN$51, -1), 2)*MOD($L7,1)*10,0), _xlpm.상태이상보정치, VLOOKUP(IF($G7 = "debuff", $M7, "null"), Factor!$AX$5:$BE$51, _xlpm.기본_색인번호, 0), _xlpm.지속시간보정치, INDEX(Factor!$BG$5:$BO$51, _xlfn.XMATCH(IF(OR($G7 ="debuff", $G7 = "shot", $G7 = "pierce"), $O7, 0), Factor!$BG$5:$BG$51, -1), _xlpm.추가_색인번호)-IF(AND(OR($G7 ="debuff", $G7 = "shot", $G7 = "pierce"), MOD($O7, 1)<>0), 10*MOD($O7, 1)*INDEX(Factor!$BG$5:$BO$51, _xlfn.XMATCH(IF(OR($G7 ="debuff", $G7 = "shot", $G7 = "pierce"), $O7, 0), Factor!$BG$5:$BG$51, -1), 2), 0), _xlpm.탄환개수보정치, VLOOKUP(IF(OR($G7 = "curved", $G7 = "shot"), $Q7, 1), Factor!$BQ$5:$BX$51, _xlpm.기본_색인번호, 0), _xlpm.상태이상탄환생성위치보정치, IF($G7 = "debuff", VLOOKUP($R7, Factor!$K$18:$R$19, _xlpm.기본_색인번호, 0),1), _xlpm.상태이상탄환형태보정치, IF($G7 = "debuff", VLOOKUP($S7, Factor!$K$24:$R$25, _xlpm.기본_색인번호, 0),1), _xlpm.가격보정치, INDEX(Factor!$AE$5:$AL$51, _xlfn.XMATCH($F7,Factor!$AE$5:$AE$51, -1), _xlpm.기본_색인번호), _xlpm.구경보정치, VLOOKUP($D7, Factor!$BZ$5:$CJ$56, _xlpm.기본_색인번호, 0), _xlpm.결과, _xlpm.개별보정치*_xlpm.패턴보정치*_xlpm.소모탄환보정치*_xlpm.지형보정치*_xlpm.공격속성보정치*_xlpm.피해범위보정치*_xlpm.상태이상보정치*_xlpm.지속시간보정치*_xlpm.탄환개수보정치*_xlpm.상태이상탄환생성위치보정치*_xlpm.상태이상탄환형태보정치*_xlpm.가격보정치*_xlpm.구경보정치, _xlpm.결과)} -> 120 | AG7: {=_xlfn.LET(_xlpm.기본_색인번호, 8, _xlpm.추가_색인번호, 9, _xlpm.개별보정치, Z7, _xlpm.패턴보정치, VLOOKUP($G7, Factor!$B$5:$I$51, _xlpm.기본_색인번호, 0), _xlpm.소모탄환보정치, VLOOKUP($H7, Factor!$T$5:$AA$51, _xlpm.기본_색인번호, 0), _xlpm.지형보정치, VLOOKUP($I7, Factor!$K$12:$R$13, _xlpm.기본_색인번호, 0), _xlpm.공격속성보정치, VLOOKUP($J7, Factor!$K$5:$R$7, _xlpm.기본_색인번호, 0), _xlpm.피해범위보정치, INDEX(Factor!$AN$5:$AV$51, _xlfn.XMATCH(IF(OR($G7="blast", $G7="curved", $G7= "debuff"), $L7, 0), Factor!$AN$5:$AN$51, -1), _xlpm.추가_색인번호)-IF(AND(OR($G7="blast", $G7="curved", $G7= "debuff"), MOD($L7,1)<>0),INDEX(Factor!$AN$5:$AV$51, _xlfn.XMATCH(IF(OR($G7="blast", $G7="curved", $G7= "debuff"), $L7, 0), Factor!$AN$5:$AN$51, -1), 2)*MOD($L7,1)*10,0), _xlpm.상태이상보정치, VLOOKUP(IF($G7 = "debuff", $M7, "null"), Factor!$AX$5:$BE$51, _xlpm.기본_색인번호, 0), _xlpm.지속시간보정치, INDEX(Factor!$BG$5:$BO$51, _xlfn.XMATCH(IF(OR($G7 ="debuff", $G7 = "shot", $G7 = "pierce"), $O7, 0), Factor!$BG$5:$BG$51, -1), _xlpm.추가_색인번호)-IF(AND(OR($G7 ="debuff", $G7 = "shot", $G7 = "pierce"), MOD($O7, 1)<>0), 10*MOD($O7, 1)*INDEX(Factor!$BG$5:$BO$51, _xlfn.XMATCH(IF(OR($G7 ="debuff", $G7 = "shot", $G7 = "pierce"), $O7, 0), Factor!$BG$5:$BG$51, -1), 2), 0), _xlpm.탄환개수보정치, VLOOKUP(IF(OR($G7 = "curved", $G7 = "shot"), $Q7, 1), Factor!$BQ$5:$BX$51, _xlpm.기본_색인번호, 0), _xlpm.상태이상탄환생성위치보정치, IF($G7 = "debuff", VLOOKUP($R7, Factor!$K$18:$R$19, _xlpm.기본_색인번호, 0),1), _xlpm.상태이상탄환형태보정치, IF($G7 = "debuff", VLOOKUP($S7, Factor!$K$24:$R$25, _xlpm.기본_색인번호, 0),1), _xlpm.가격보정치, INDEX(Factor!$AE$5:$AL$51, _xlfn.XMATCH($F7,Factor!$AE$5:$AE$51, -1), _xlpm.기본_색인번호), _xlpm.구경보정치, VLOOKUP($D7, Factor!$BZ$5:$CJ$56, _xlpm.기본_색인번호, 0), _xlpm.결과, _xlpm.개별보정치*_xlpm.패턴보정치*_xlpm.소모탄환보정치*_xlpm.지형보정치*_xlpm.공격속성보정치*_xlpm.피해범위보정치*_xlpm.상태이상보정치*_xlpm.지속시간보정치*_xlpm.탄환개수보정치*_xlpm.상태이상탄환생성위치보정치*_xlpm.상태이상탄환형태보정치*_xlpm.가격보정치*_xlpm.구경보정치, _xlpm.결과)} -> 1
