Workbook

Sheet 개요
B2: 개요
B3: - 게임 서클트레인의 상점, 커스터마이징, 전투에서 사용되는 트레인 파츠의 능력치와 가격의 데이터를 저장하는 테이블이다.
B4: 내부키 | C4: 외부키
B6: 테이블 내용
B8: Locomotive | C8: (기관차의 스탯 정보를 담는 테이블이다.)
C9: column명 | D9: 한글명칭 | E9: 데이터타입 | F9: 설명
C10: locomotiveId | D10: 기관차 ID | E10: string | F10: 데이터를 식별하기 위한 ID값이다.
C11: locomotiveName | D11: 기관차 이름 | E11: string | F11: 기관차의 이름 데이터이다.
C12: locomotiveMaxspeed | D12: 최대속력 | E12: flaot | F12: 기관차의 최대 속력 수치 값이다. 인게임 트레인의 속력은 해당 수치 이하로만 가능하다.
C13: locomotiveHorsepower | D13: 최대 출력 | E13: float | F13: 기관차의 최대 출력 수치 값이다. 이 수치에 비례해 가속도 및 허용중량이 증가한다.
C14: locomotiveCouch | D14: 최대 연결 칸 | E14: int | F14: 기관차의 최대 연결 칸 수치 데이터를 저장한다. 이 수치만큼 편성 칸을 추가할 수 있다.
C15: locomotiveAccelpower | D15: 기본 가속력 | E15: float | F15: 기관차의 기본 가속력 수치 값이다. 이동시 기차의 초당 몇만큼의 속도가 오를지에 대한 값이다.
C16: locomotiveBreakpower | D16: 제동력 | E16: float | F16: 기관차의 제동력 수치이다. 정지시 초당 몇만큼 속도가 감소할지에 대한 값이다.
C17: locomotiveWeightlimit | D17: 기본 허용 중량 | E17: int | F17: 기관차의 허용중량 수치 값이다.
C18: locomotiveHp | D18: 내구력 | E18: int | F18: 기관차의 최대 체력수치이다. 체력수치가 0 이하가 되면 게임오버이다.
C19: locomotiveDef | D19: 방어력 | E19: int | F19: 기관차의 방어력 수치 값이다. 기관차가 피해를 받을 때 이 수치에 비례해 받는 피해가 감소한다.
C20: locomotiveShield | D20: 자기장 방어막 | E20: int | F20: 기관차의 보호막 수치이다.
... C24: locomotiveText | D24: 기관차 설명 문구 | E24: string | F24: 기관차의 UI상 설명 데이터이다.
B26: Couch | C26: (편성 칸의 스탯 정보를 담는 테이블이다.)
C27: column명 | D27: 한글명칭 | E27: 데이터타입 | F27: 설명
C28: couchId | D28: 편성칸 ID | E28: string | F28: 데이터를 식별하기 위한 ID값이다.
C29: couchName | D29: 편성 칸 이름 | E29: string | F29: 편성 칸의 이름 데이터이다.
C30: couchHp | D30: 내구력 | E30: int | F30: 편성 칸의 체력 수치이다. 수치가 0 이하면 파괴된다.
C31: couchDef | D31: 방어력 | E31: int | F31: 편성 칸의 방어력 수치이다. 피해를 받을 때 이 수치에 비례해 받는 피해가 감소한다.
C32: couchshield | D32: 자기장 방어막 | E32: int | F32: 편성 칸의 보호막 수치이다.
C33: couchSynergyPower | D33: 승무원 시너지 계수 | E33: float | F33: 수치만큼 이 편성 칸의 승무원이 증가시키는 스탯이 증가한다.
C34: couchCost | D34: 편성 칸 가격 | E34: int | F34: 상점에서 해당 편성 칸을 구매할 때 필요한 비용수치이다.
C35: couchWeight | D35: 편성 칸 무게 | E35: float | F35: 편성 칸의 무게 수치이다.
C36: couchText | D36: 편성 칸 설명문구 | E36: string | F36: 편성 칸의 UI상 설명 데이터이다.
B38: Engine | C38: 엔진 파츠의 스탯 정보를 담는 테이블이다.
C39: column명 | D39: 한글명칭 | E39: 데이터타입 | F39: 설명
C40: engineId | D40: 엔진ID | E40: string | F40: 데이터를 식별하기 위한 ID값이다.
C41: engineName | D41: 엔진 이름 | E41: string | F41: 엔진의 이름 데이터이다.
C42: enginePowerUp | D42: 최대출력 증가량 | E42: float | F42: 엔진의 최대 출력 증가량 수치이다.
C43: engineCost | D43: 엔진 가격 | E43: int | F43: 상점에서 해당 파츠를 구매할 때 필요한 비용수치이다.
C44: engineWeight | D44: 엔진 무게 | E44: float | F44: 엔진의 무게 수치이다.
C45: engineText | D45: 엔진 설명 문구 | E45: string | F45: 엔진의 UI상 설명 데이터이다.
B47: Generator
C48: column명 | D48: 한글명칭 | E48: 데이터타입 | F48: 설명
C49: generatorId | D49: 제네레이터ID | E49: string | F49: 데이터를 식별하기 위한 ID값이다.
...

Sheet Factor
B1: ● 이 시트에서는 각 시트의 능력치를 특정 조건에 맞춰 일괄적으로 수정할 수 있다. ● 기본 능력치는 종류를 기준으로 적용된다. ● 가격을 기준으로 보정치 배율이 적용된다. ● 객실파츠의 경우 추가적으로 생산하는 물건에 따른 보정이 적용된다. ● ID의 경우 ID 생성 팩터의 구성요소를 조합해 자동으로 생성을 진행한다.
C2: 기관차 종류별 기본 능력치 | Q2: 객차 종류별 기본능력치 | Y2: 엔진 종류 기본능력치 | AD2: 제네레이터 종류 기본능력치 | AI2: 제동장치 종류 보정 | AN2: 객실파트 종류보정 | AU2: 객실파츠 공업물/생산물 보정 | BB2: 승무원 종류 보정 | BK2: 기관차 ID 생성 팩터 | BQ2: 편성 칸 ID 생성 팩터 | BW2: 엔진 ID 생성 팩터 | CC2: 제네레이터 ID 생성 팩터 | CI2: 제동장치 ID 생성 팩터 | CO2: 객실 파츠 ID 및 구분 자동생성 팩터
C3: 종류 구분 | D3: 최대속력 | E3: 최대 출력 | F3: 최대 연결 칸 | G3: 기본 가속력 | H3: 제동력 | I3: 기본 허용 중량 | J3: 내구력 | K3: 방어력 | L3: 자기장 방어막 | M3: 인벤토리 추가량 | N3: 탑승 칸 추가량 | Q3: 종류구분 | R3: 내구력 | S3: 방어력 | T3: 자기장 방어막 | U3: 승무원 시너지 계수 | V3: 편성 칸 무게 | Y3: 종류구분 | Z3: 최대출력 증가량 | AA3: 엔진 무게 | AD3: 종류구분 | AE3: 자기장 방벽 증가량 | AF3: 제네레이터 무게 | AI3: 종류구분 | AJ3: 제동력 증가량 | AK3: 제동장치 무게 | AN3: 종류구분 | AO3: 객실 파츠 생산력 | AP3: 객실 파츠 공업력 | AQ3: 객실 파츠 인벤토리 증가량 | AR3: 객실 파츠 승객수용 증가량 | AS3: 객실 파츠 무게 | AU3: 종류구분 | AV3: 객실 파츠 생산력 | AW3: 객실 파츠 공업력 | AX3: 객실 파츠 무게 | BB3: 종류구분 | BC3: 대지공격력 | BD3: 대공공격력 | BE3: 방어력 | BF3: 기본 사기 | BG3: 생산력 | BH3: 공업력 | BK3: 종류구분 | BL3: 단어 | BM3: 종류구분 | BN3: 번호 | BQ3: 종류구분 | BR3: 단어 | BS3: 종류구분 | BT3: 번호 | BW3: 종류구분 | BX3: 단어 | BY3: 종류구분 | BZ3: 번호 | CC3: 종류구분 | CD3: 단어 | CE3: 종류구분 | CF3: 번호 | CI3: 종류구분 | CJ3: 단어 | CK3: 종류구분 | CL3: 번호 | CO3: 종류구분 | CP3: 구분 | CQ3: 생산물품 | CR3: ID중간 형식 | CS3: 종류구분 | CT3: 번호
C4: 표준 증기 | D4: 100 | E4: 1000 | F4: 1 | G4: 4 | H4: 10 | I4: 10000 | J4: 1000 | K4: 30 | L4: 1000 | M4: 1 | N4: 1 | Q4: 표준 나무 | R4: 500 | S4: 10 | T4: 500 | U4: 1 | V4: 1000 | Y4: 표준 4기통 | Z4: 10 | AA4: 500 | AD4: 소형 표준 | AE4: 100 | AF4: 500 | AI4: 표준 기계식 | AJ4: 5 | AK4: 300 | AN4: 생산 | AO4: 1 | AP4: 1 | AQ4: 1 | AR4: 1 | AS4: 5000 | AU4: ammo | AV4: 0 | AW4: 10 | AX4: 1 | BB4: 생산형 | BC4: 5 | BD4: 5 | BE4: 5 | BF4: 50 | BG4: 10 | BH4: 10 | BK4: 증기 | BL4: St | BM4: 표준 | BN4: 001 | BQ4: 나무 | BR4: Wo | BS4: 표준 | BT4: 001 | BW4: 표준 | BX4: No | BY4: 4기통 | BZ4: 001 | CC4: 소형 | CD4: Sm | CE4: 표준 | CF4: 001 | CI4: 기계식 | CJ4: Mac | CK4: 표준 | CL4: 001 | CO4: 스마트팜 | CP4: 생산 | CQ4: food | CR4: Prod_Food_ | CS4: 표준 | CT4: 001
C5: 표준 전기 | D5: 200 | E5: 800 | F5: 1 | G5: 8 | H5: 10 | I5: 7000 | J5: 700 | K5: 5 | L5: 700 | M5: 1 | N5: 1 | Q5: 표준 강철 | R5: 700 | S5: 20 | T5: 700 | U5: 1.2 | V5: 1500 | Y5: 표준 6기통 | Z5: 20 | AA5: 1000 | AD5: 소형 고성능 | AE5: 500 | AF5: 900 | AI5: 고성능 기계식 | AJ5: 10 | AK5: 600 | AN5: 인원수송 | AO5: 0 | AP5: 0 | AQ5: 0 | AR5: 4 | AS5: 1000 | AU5: shell | AV5: 0 | AW5: 5 | AX5: 1.2 | BB5: 방어형 | BC5: 5 | BD5: 5 | BE5: 10 | BF5: 50 | BG5: 5 | BH5: 5 | BK5: 전기 | BL5: El | BM5: 쾌속 | BN5: 002 | BQ5: 강철 | BR5: St | BS5: 중갑 | BT5: 002 | BW5: 고성능 | BX5: Hi | BY5: 6기통 | BZ5: 002 | CC5: 표준 | CD5: No | CE5: 고성능 | CF5: 002 | CI5: 유압식 | CJ5: Hyd | CK5: 고성능 | CL5: 002 | CO5: 탄약공장 | CP5: 공업 | CQ5: ammo | CR5: Indu_Ammo_ | CS5: 경량 | CT5: 002
C6: 표준 디젤 | D6: 150 | E6: 1200 | F6: 1 | G6: 6 | H6: 10 | I6: 15000 | J6: 800 | K6: 10 | L6: 800 | M6: 1 | N6: 1 | Q6: 표준 티타늄 | R6: 1000 | S6: 30 | T6: 1000 | U6: 1.4 | V6: 2000 | Y6: 표준 8기통 | Z6: 40 | AA6: 2000 | AD6: 소형 경량 | AE6: 70 | AF6: 200 | AI6: 경량 기계식 | AJ6: 3 | AK6: 100 | AN6: 물자수송 | AO6: 0 | AP6: 0 | AQ6: 2 | AR6: 0 | AS6: 2000 | AU6: missile | AV6: 0 | AW6: 2 | AX6: 1.3 | BB6: 전투형 | BC6: 10 | BD6: 10 | BE6: 5 | BF6: 50 | BG6: 5 | BH6: 5 | BK6: 디젤 | BL6: Dz | BM6: 중갑 | BN6: 003 | BQ6: 티타늄 | BR6: Ti | BS6: 화물 | BT6: 003 | BW6: 경량형 | BX6: Li | BY6: 8기통 | BZ6: 003 | CC6: 대형 | CD6: Bi | CE6: 경량 | CF6: 003 | CI6: 전자식 | CJ6: Elc | CK6: 경량 | CL6: 003 | CO6: 포탄공장 | CP6: 공업 | CQ6: shell | CR6: Indu_Shell_ | CS6: 대형 | CT6: 003
C7: 쾌속 증기 | D7: 110 | E7: 900 | F7: 1 | G7: 6 | H7: 10 | I7: 10000 | J7: 800 | K7: 20 | L7: 800 | M7: 1 | N7: 1 | Q7: 중갑 나무 | R7: 500 | S7: 20 | T7: 500 | U7: 1 | V7: 2000 | Y7: 표준 10기통 | Z7: 50 | AA7: 3000 | AD7: 소형 재생 | AE7: 140 | AF7: 700 | AI7: 화물용 기계식 | AJ7: 12 | AK7: 800 | AN7: 공업 | AO7: 0 | AP7: 1 | AQ7: 0 | AR7: 0 | AS7: 5000 | AU7: siecleium | AV7: 0 | AW7: 10 | AX7: 1 | BM7: 화물 | BN7: 004 | BS7: 군용 | BT7: 004 | BY7: 10기통 | BZ7: 004 | CE7: 재생 | CF7: 004 | CK7: 화물용 | CL7: 004 | CO7: 미사일공장 | CP7: 공업 | CQ7: missile | CR7: Indu_Missile_ | CT7: 004
C8: 쾌속 전기 | D8: 220 | E8: 700 | F8: 1 | G8: 10 | H8: 10 | I8: 7000 | J8: 500 | K8: 3 | L8: 500 | M8: 1 | N8: 1 | Q8: 중갑 강철 | R8: 700 | S8: 35 | T8: 700 | U8: 1.2 | V8: 3000 | Y8: 표준 12기통 | Z8: 70 | AA8: 4000 | AD8: 소형 듀얼코어 | AE8: 800 | AF8: 1500 | AI8: 표준 유압식 | AJ8: 5.5 | AK8: 280 | AU8: food | AV8: 10 | AW8: 0 | AX8: 1 | BM8: 군용 | BN8: 005 | BS8: 여객 | BT8: 005 | BY8: 12기통 | BZ8: 005 | CE8: 듀얼코어 | CF8: 005 | CL8: 005 | CO8: 서클리움 정제소 | CP8: 공업 | CQ8: siecleium | CR8: Indu_Siecleium_ | CT8: 005
C9: 쾌속 디젤 | D9: 165 | E9: 1000 | F9: 1 | G9: 8 | H9: 10 | I9: 15000 | J9: 650 | K9: 5 | L9: 650 | M9: 1 | N9: 1 | Q9: 중갑 티타늄 | R9: 1000 | S9: 55 | T9: 1000 | U9: 1.4 | V9: 4000 | Y9: 표준 군용 | Z9: 90 | AA9: 6000 | AD9: 표준 표준 | AE9: 100 | AF9: 500 | AI9: 고성능 유압식 | AJ9: 10.5 | AK9: 550 | BM9: 여객 | BN9: 006 | BS9: 시운 | BT9: 006 | BY9: 군용 | BZ9: 006 | CF9: 006 | CL9: 006 | CO9: 화물 수송 칸 | CP9: 물자수송 | CQ9: null | CR9: Trans_Inven_ | CT9: 006
C10: 중갑 증기 | D10: 90 | E10: 1200 | F10: 1 | G10: 4 | H10: 10 | I10: 8000 | J10: 1500 | K10: 50 | L10: 1500 | M10: 1 | N10: 1 | Q10: 화물 나무 | R10: 500 | S10: 10 | T10: 500 | U10: 0.9 | V10: 700 | Y10: 고성능 4기통 | Z10: 20 | AA10: 1800 | AD10: 표준 고성능 | AE10: 500 | AF10: 900 | AI10: 경량 유압식 | AJ10: 3.5 | AK10: 90 | BM10: 시운 | BN10: 007 | BS10: 경량 | BT10: 007 | BZ10: 007 | CF10: 007 | CL10: 007 | CO10: 인원 수송 칸 | CP10: 인원수송 | CQ10: null | CR10: Trans_Pass_ | CT10: 007
C11: 중갑 전기 | D11: 170 | E11: 100 | F11: 1 | G11: 8 | H11: 10 | I11: 5000 | J11: 1000 | K11: 15 | L11: 1000 | M11: 1 | N11: 1 | Q11: 화물 강철 | R11: 700 | S11: 20 | T11: 700 | U11: 1.1 | V11: 1000 | Y11: 고성능 6기통 | Z11: 40 | AA11: 3000 | AD11: 표준 경량 | AE11: 70 | AF11: 200 | AI11: 화물용 유압식 | AJ11: 12.5 | AK11: 750 | BM11: 경량 | BN11: 008 | BT11: 008 | BZ11: 008 | CF11: 008 | CL11: 008 | CT11: 008
C12: 중갑 디젤 | D12: 110 | E12: 1500 | F12: 1 | G12: 6 | H12: 10 | I12: 12000 | J12: 1300 | K12: 30 | L12: 1300 | M12: 1 | N12: 1 | Q12: 화물 티타늄 | R12: 1000 | S12: 30 | T12: 1000 | U12: 1.2 | V12: 1200 | Y12: 고성능 8기통 | Z12: 60 | AA12: 4000 | AD12: 표준 재생 | AE12: 140 | AF12: 700 | AI12: 표준 전자식 | AJ12: 4.5 | AK12: 250 | BM12: 견인 | BN12: 009 | BT12: 009 | BZ12: 009 | CF12: 009 | CL12: 009 | CT12: 009
C13: 화물 증기 | D13: 90 | E13: 1000 | F13: 1 | G13: 4 | H13: 10 | I13: 10000 | J13: 1000 | K13: 30 | L13: 1000 | M13: 3 | N13: 1 | Q13: 군용 나무 | R13: 700 | S13: 15 | T13: 700 | U13: 1.1 | V13: 3000 | Y13: 고성능 10기통 | Z13: 50 | AA13: 3000 | AD13: 표준 듀얼코어 | AE13: 800 | AF13: 1500 | AI13: 고성능 전자식 | AJ13: 9.5 | AK13: 500 | BN13: 010 | BT13: 010 | BZ13: 010 | CF13: 010 | CL13: 010 | CT13: 010
C14: 화물 전기 | D14: 180 | E14: 800 | F14: 1 | G14: 8 | H14: 10 | I14: 7000 | J14: 700 | K14: 5 | L14: 700 | M14: 3 | N14: 1 | Q14: 군용 강철 | R14: 900 | S14: 30 | T14: 900 | U14: 1.3 | V14: 4500 | Y14: 고성능 12기통 | Z14: 120 | AA14: 6000 | AD14: 대형 표준 | AE14: 100 | AF14: 500 | AI14: 경량 전자식 | AJ14: 2.5 | AK14: 70
C15: 화물 디젤 | D15: 120 | E15: 1200 | F15: 1 | G15: 6 | H15: 10 | I15: 15000 | J15: 800 | K15: 10 | L15: 800 | M15: 3 | N15: 1 | Q15: 군용 티타늄 | R15: 1400 | S15: 50 | T15: 1400 | U15: 1.5 | V15: 6000 | Y15: 고성능 군용 | Z15: 150 | AA15: 12000 | AD15: 대형 고성능 | AE15: 500 | AF15: 900 | AI15: 화물용 전자식 | AJ15: 11.5 | AK15: 700
C16: 군용 증기 | D16: 90 | E16: 1600 | F16: 1 | G16: 2 | H16: 18 | I16: 10000 | J16: 1000 | K16: 30 | L16: 1000 | M16: 1 | N16: 1 | Q16: 여객 나무 | R16: 400 | S16: 8 | T16: 400 | U16: 1.2 | V16: 1000 | Y16: 경량형 4기통 | Z16: 7 | AA16: 300 | AD16: 대형 경량 | AE16: 70 | AF16: 200
C17: 군용 전기 | D17: 170 | E17: 1000 | F17: 1 | G17: 5 | H17: 18 | I17: 7000 | J17: 700 | K17: 5 | L17: 700 | M17: 1 | N17: 1 | Q17: 여객 강철 | R17: 600 | S17: 20 | T17: 600 | U17: 1.4 | V17: 1500 | Y17: 경량형 6기통 | Z17: 15 | AA17: 700 | AD17: 대형 재생 | AE17: 140 | AF17: 700
C18: 군용 디젤 | D18: 110 | E18: 1600 | F18: 1 | G18: 3 | H18: 18 | I18: 15000 | J18: 800 | K18: 10 | L18: 800 | M18: 1 | N18: 1 | Q18: 여객 티타늄 | R18: 800 | S18: 15 | T18: 8000 | U18: 1.7 | V18: 2000 | Y18: 경량형 8기통 | Z18: 30 | AA18: 1200 | AD18: 대형 듀얼코어 | AE18: 800 | AF18: 1500
C19: 여객 증기 | D19: 100 | E19: 1000 | F19: 1 | G19: 4 | H19: 10 | I19: 10000 | J19: 900 | K19: 25 | L19: 900 | M19: 1 | N19: 3 | Q19: 시운 나무 | R19: 200 | S19: 10 | T19: 800 | U19: 1 | V19: 1000 | Y19: 경량형 10기통 | Z19: 40 | AA19: 1800
C20: 여객 전기 | D20: 200 | E20: 800 | F20: 1 | G20: 8 | H20: 10 | I20: 7000 | J20: 600 | K20: 4 | L20: 600 | M20: 1 | N20: 3 | Q20: 시운 강철 | R20: 300 | S20: 20 | T20: 1100 | U20: 1.2 | V20: 1500 | Y20: 경량형 12기통 | Z20: 60 | AA20: 2500
C21: 여객 디젤 | D21: 150 | E21: 1200 | F21: 1 | G21: 6 | H21: 10 | I21: 15000 | J21: 700 | K21: 7 | L21: 700 | M21: 1 | N21: 3 | Q21: 시운 티타늄 | R21: 500 | S21: 30 | T21: 1500 | U21: 1.4 | V21: 2000 | Y21: 경량형 군용 | Z21: 70 | AA21: 3000
C22: 시운 증기 | D22: 100 | E22: 1000 | F22: 1 | G22: 6 | H22: 10 | I22: 10000 | J22: 500 | K22: 30 | L22: 2000 | M22: 1 | N22: 1 | Q22: 경량 나무 | R22: 300 | S22: 8 | T22: 300 | U22: 1 | V22: 500
C23: 시운 전기 | D23: 200 | E23: 800 | F23: 1 | G23: 10 | H23: 10 | I23: 7000 | J23: 300 | K23: 5 | L23: 1000 | M23: 1 | N23: 1 | Q23: 경량 강철 | R23: 400 | S23: 15 | T23: 400 | U23: 1.2 | V23: 700
C24: 시운 디젤 | D24: 150 | E24: 1200 | F24: 1 | G24: 8 | H24: 10 | I24: 15000 | J24: 400 | K24: 10 | L24: 1500 | M24: 1 | N24: 1 | Q24: 경량 티타늄 | R24: 600 | S24: 20 | T24: 600 | U24: 1.4 | V24: 1000
C25: 경량 증기 | D25: 100 | E25: 900 | F25: 1 | G25: 5 | H25: 10 | I25: 8000 | J25: 1000 | K25: 30 | L25: 1000 | M25: 1 | N25: 1
C26: 경량 전기 | D26: 200 | E26: 700 | F26: 1 | G26: 9 | H26: 10 | I26: 5000 | J26: 700 | K26: 5 | L26: 700 | M26: 1 | N26: 1
C27: 경량 디젤 | D27: 150 | E27: 1100 | F27: 1 | G27: 7 | H27: 10 | I27: 12000 | J27: 800 | K27: 10 | L27: 800 | M27: 1 | N27: 1
C28: 견인 증기 | D28: 90 | E28: 1000 | F28: 1 | G28: 3 | H28: 10 | I28: 15000 | J28: 1000 | K28: 30 | L28: 1000 | M28: 1 | N28: 1
C29: 견인 전기 | D29: 180 | E29: 800 | F29: 1 | G29: 7 | H29: 10 | I29: 12000 | J29: 700 | K29: 5 | L29: 700 | M29: 1 | N29: 1
C30: 견인 디젤 | D30: 120 | E30: 1200 | F30: 1 | G30: 5 | H30: 10 | I30: 20000 | J30: 800 | K30: 10 | L30: 800 | M30: 1 | N30: 1
B39: 등급 색인 | C39: 기관차 가격별 보정치 | P39: 등급 색인 | Q39: 객차 가격 보정 | X39: 등급 색인 | Y39: 엔진 가격 보정 | AC39: 등급 색인 | AD39: 제네레이터 가격 보정 | AH39: 등급 색인 | AI39: 제동장치 가격 보정 | AM39: 등급 색인 | AN39: 객실파트 가격 보정 | AU39: 객실 파츠 성능 보정
B40: 등급 | C40: 종류 구분 | D40: 최대속력 | E40: 최대 출력 | F40: 최대 연결 칸 | G40: 기본 가속력 | H40: 제동력 | I40: 기본 허용 중량 | J40: 내구력 | K40: 방어력 | L40: 자기장 방어막 | M40: 인벤토리 추가량 | N40: 탑승 칸 추가량 | P40: 등급 | Q40: 종류구분 | R40: 내구력 | S40: 방어력 | T40: 자기장 방어막 | U40: 승무원 시너지 계수 | V40: 편성 칸 무게 | X40: 등급 | Y40: 종류구분 | Z40: 최대출력 증가량 | AA40: 엔진 무게 | AC40: 등급 | AD40: 종류구분 | AE40: 자기장 방벽 증가량 | AF40: 제네레이터 무게 | AH40: 등급 | AI40: 종류구분 | AJ40: 제동력 증가량 | AK40: 제동장치 무게 | AM40: 등급 | AN40: 종류구분 | AO40: 객실 파츠 생산력 | AP40: 객실 파츠 공업력 | AQ40: 객실 파츠 인벤토리 증가량 | AR40: 객실 파츠 승객수용 증가량 | AS40: 객실 파츠 무게 | AU40: 종류구분 | AV40: 객실 파츠 생산력 | AW40: 객실 파츠 공업력 | AX40: 객실 파츠 인벤토리 증가량 | AY40: 객실 파츠 승객수용 증가량 | AZ40: 객실 파츠 무게
B41: T1 | C41: 10000 | D41: 1 | E41: 1 | F41: 2 | G41: 1 | H41: 1 | I41: 1 | J41: 1 | K41: 1 | L41: 1 | M41: 1 | N41: 1 | P41: T1 | Q41: 2000 | R41: 1 | S41: 1 | T41: 1 | U41: 1 | V41: 1 | X41: T1 | Y41: 1000 | Z41: 1 | AA41: 1 | AC41: T1 | AD41: 1000 | AE41: 1 | AF41: 1 | AH41: T1 | AI41: 1000 | AJ41: 1 | AK41: 1 | AM41: T1 | AN41: 5000 | AO41: 1 | AP41: 1 | AQ41: 1 | AR41: 1 | AS41: 1 | AU41: 표준 | AV41: 1 | AW41: 1 | AX41: 1 | AY41: 1 | AZ41: 1
B42: T2 | C42: 20000 | D42: 1.2 | E42: 1.2 | F42: 3 | G42: 1.2 | H42: 1.2 | I42: 1.2 | J42: 1.2 | K42: 1.2 | L42: 1.2 | M42: 2 | N42: 2 | P42: T2 | Q42: 4000 | R42: 1.2 | S42: 1.2 | T42: 1.2 | U42: 1.2 | V42: 1.2 | X42: T2 | Y42: 2000 | Z42: 1.2 | AA42: 1.2 | AC42: T2 | AD42: 2000 | AE42: 1.2 | AF42: 1.2 | AH42: T2 | AI42: 2000 | AJ42: 1.2 | AK42: 1.2 | AM42: T2 | AN42: 10000 | AO42: 1.2 | AP42: 1.2 | AQ42: 1.2 | AR42: 1.2 | AS42: 1.2 | AU42: 경량 | AV42: 0.8 | AW42: 0.8 | AX42: 1 | AY42: 1 | AZ42: 0.8
B43: T3 | C43: 30000 | D43: 1.4 | E43: 1.4 | F43: 4 | G43: 1.4 | H43: 1.4 | I43: 1.4 | J43: 1.4 | K43: 1.4 | L43: 1.4 | M43: 3 | N43: 3 | P43: T3 | Q43: 6000 | R43: 1.4 | S43: 1.4 | T43: 1.4 | U43: 1.4 | V43: 1.4 | X43: T3 | Y43: 3000 | Z43: 1.4 | AA43: 1.4 | AC43: T3 | AD43: 3000 | AE43: 1.4 | AF43: 1.4 | AH43: T3 | AI43: 3000 | AJ43: 1.4 | AK43: 1.4 | AM43: T3 | AN43: 15000 | AO43: 1.4 | AP43: 1.4 | AQ43: 1.4 | AR43: 1.4 | AS43: 1.4 | AU43: 대형 | AV43: 1.2 | AW43: 1.2 | AX43: 1 | AY43: 1 | AZ43: 1.2
B44: T4 | C44: 40000 | D44: 1.6 | E44: 1.6 | F44: 5 | G44: 1.6 | H44: 1.6 | I44: 1.6 | J44: 1.6 | K44: 1.6 | L44: 1.6 | M44: 4 | N44: 4 | P44: T4 | Q44: 8000 | R44: 1.6 | S44: 1.6 | T44: 1.6 | U44: 1.6 | V44: 1.6 | X44: T4 | Y44: 4000 | Z44: 1.6 | AA44: 1.6 | AC44: T4 | AD44: 4000 | AE44: 1.6 | AF44: 1.6 | AH44: T4 | AI44: 4000 | AJ44: 1.6 | AK44: 1.6 | AM44: T4 | AN44: 20000 | AO44: 1.6 | AP44: 1.6 | AQ44: 1.6 | AR44: 1.6 | AS44: 1.6
B45: T5 | C45: 50000 | D45: 1.8 | E45: 1.8 | F45: 6 | G45: 1.8 | H45: 1.8 | I45: 1.8 | J45: 1.8 | K45: 1.8 | L45: 1.8 | M45: 5 | N45: 5 | P45: T5 | Q45: 10000 | R45: 1.8 | S45: 1.8 | T45: 1.8 | U45: 1.8 | V45: 1.8 | X45: T5 | Y45: 5000 | Z45: 1.8 | AA45: 1.8 | AC45: T5 | AD45: 5000 | AE45: 1.8 | AF45: 1.8 | AH45: T5 | AI45: 5000 | AJ45: 1.8 | AK45: 1.8 | AM45: T5 | AN45: 25000 | AO45: 1.8 | AP45: 1.8 | AQ45: 1.8 | AR45: 1.8 | AS45: 1.8
B46: T6 | C46: 60000 | D46: 2 | E46: 2 | F46: 7 | G46: 2 | H46: 2 | I46: 2 | J46: 2 | K46: 2 | L46: 2 | M46: 6 | N46: 6 | P46: T6 | Q46: 12000 | R46: 2 | S46: 2 | T46: 2 | U46: 2 | V46: 2 | X46: T6 | Y46: 6000 | Z46: 2 | AA46: 2 | AC46: T6 | AD46: 6000 | AE46: 2 | AF46: 2 | AH46: T6 | AI46: 6000 | AJ46: 2 | AK46: 2 | AM46: T6 | AN46: 30000 | AO46: 2 | AP46: 2 | AQ46: 2 | AR46: 2 | AS46: 2
B47: T7 | C47: 70000 | D47: 2.2 | E47: 2.2 | F47: 8 | G47: 2.2 | H47: 2.2 | I47: 2.2 | J47: 2.2 | K47: 2.2 | L47: 2.2 | M47: 7 | N47: 7 | P47: T7 | Q47: 14000 | R47: 2.2 | S47: 2.2 | T47: 2.2 | U47: 2.2 | V47: 2.2 | X47: T7 | Y47: 7000 | Z47: 2.2 | AA47: 2.2 | AC47: T7 | AD47: 7000 | AE47: 2.2 | AF47: 2.2 | AH47: T7 | AI47: 7000 | AJ47: 2.2 | AK47: 2.2 | AM47: T7 | AN47: 35000 | AO47: 2.2 | AP47: 2.2 | AQ47: 2.2 | AR47: 2.2 | AS47: 2.2
B48: T8 | C48: 80000 | D48: 2.4 | E48: 2.4 | F48: 9 | G48: 2.4 | H48: 2.4 | I48: 2.4 | J48: 2.4 | K48: 2.4 | L48: 2.4 | M48: 8 | N48: 8 | P48: T8 | Q48: 16000 | R48: 2.4 | S48: 2.4 | T48: 2.4 | U48: 2.4 | V48: 2.4 | X48: T8 | Y48: 8000 | Z48: 2.4 | AA48: 2.4 | AC48: T8 | AD48: 8000 | AE48: 2.4 | AF48: 2.4 | AH48: T8 | AI48: 8000 | AJ48: 2.4 | AK48: 2.4 | AM48: T8 | AN48: 40000 | AO48: 2.4 | AP48: 2.4 | AQ48: 2.4 | AR48: 2.4 | AS48: 2.4
...

Sheet Locomotive
A1: ● 3열은 데이터의 자료형이며 자료형이 한글로 되어있는 경우 인게임에서 사용하지 않는 데이터지만 테이블에서 수치조정 또는 색인을 위해 넣은 데이터이다. ● 보정치의 수치를 조정해 각 몬스터 별로 상세 능력치를 조정할 수 있다. ● 보정값의 경우 수치 조정의도가 없는 경우 1을 유지한다. ● ID는 locomotive_기관차종류_등급_번호 순으로 구성된다. ● ID 이름 가격은 3열에 노란색으로 칠해진 내부색인 칼럼에 데이터를 입력하면 자동 생성된다. ● 배정되는 값은 Factor 시트를 참고한다.
A2: 기관차 ID | B2: 기관차 이름 | C2: 기관차 가격 | D2: 기관차 등급 | E2: 기관차 종류(특징구분) | F2: 기관차 종류(동력 구분) | G2: 기관차 종류(합본) | H2: 최대속력 보정치 | I2: 최대 출력 보정치 | J2: 최대 연결 칸 보정치 | K2: 기본 가속력 보정치 | L2: 제동력 보정치 | M2: 기본 허용 중량 보정치 | N2: 내구력 보정치 | O2: 방어력 보정치 | P2: 자기장 방어막 보정치 | Q2: 인벤토리 추가량 보정치 | R2: 탑승 칸 추가량 보정치 | S2: 기관차 종류 | T2: 최대속력 | U2: 최대 출력 | V2: 최대 연결 칸 | W2: 기본 가속력 | X2: 제동력 | Y2: 기본 허용 중량 | Z2: 내구력 | AA2: 방어력 | AB2: 자기장 방어막 | AC2: 인벤토리 추가량 | AD2: 탑승 칸 추가량
A3: string | B3: string | C3: int | D3: 내부 색인 | E3: 내부 색인 | F3: 내부 색인 | G3: 내부 색인 | H3: 보정치 | I3: 보정치 | J3: 보정치 | K3: 보정치 | L3: 보정치 | M3: 보정치 | N3: 보정치 | O3: 보정치 | P3: 보정치 | Q3: 보정치 | R3: 보정치 | S3: flaot | T3: float | U3: int | V3: float | W3: float | X3: int | Y3: int | Z3: int | AA3: int | AB3: int | AC3: int | AD3: string
A4: locomotiveId | B4: locomotiveName | C4: locomotiveCost | D4: locomotiveType | E4: locomotiveType | F4: locomotiveType | G4: locomotiveType | H4: locomotiveMaxspeed | I4: locomotiveHorsepower | J4: locomotiveCouch | K4: locomotiveAccelpower | L4: locomotiveBreakpower | M4: locomotiveWeightlimit | N4: locomotiveHp | O4: locomotiveDef | P4: locomotiveShield | Q4: locomotiveInventoryUp | R4: locomotiveBordingUp | S4: locomotiveMaxspeed | T4: locomotiveHorsepower | U4: locomotiveCouch | V4: locomotiveAccelpower | W4: locomotiveBreakpower | X4: locomotiveWeightlimit | Y4: locomotiveHp | Z4: locomotiveDef | AA4: locomotiveShield | AB4: locomotiveInventoryUp | AC4: locomotiveBordingUp | AD4: locomotiveText
A5: ="locomotive_"& VLOOKUP(F5, Factor!$BK$4:$BL$6, 2, 0) &"_"&Locomotive!D5&"_"&VLOOKUP(E5, Factor!$BM$4:$BN$36, 2, 0) -> locomotive_St_T1_001 | B5: =D5&" "&G5&"기관차" -> T1 표준 증기기관차 | C5: =VLOOKUP(D5, Factor!$B$41:$C$50, 2, 0) -> 10000 | D5: T1 | E5: 표준 | F5: 증기 | G5: =E5&" "&F5 -> 표준 증기 | H5: 1 | I5: 1 | J5: 1 | K5: 1 | L5: 1 | M5: 1 | N5: 1 | O5: 1 | P5: 1 | Q5: 1 | R5: 1 | S5: {=H5*VLOOKUP($G5, Factor!$C$4:$N$36, 2, 0)*INDEX(Factor!$C$41:$N$87, _xlfn.XMATCH($C5, Factor!$C$41:$C$87, -1), 2)} -> 100 | T5: {=I5*VLOOKUP($G5, Factor!$C$4:$N$36, 3, 0)*INDEX(Factor!$C$41:$N$87, _xlfn.XMATCH($C5, Factor!$C$41:$C$87, -1), 3)} -> 1000 | U5: {=J5*VLOOKUP($G5, Factor!$C$4:$N$36, 4, 0)*INDEX(Factor!$C$41:$N$87, _xlfn.XMATCH($C5, Factor!$C$41:$C$87, -1), 4)} -> 2 | V5: {=K5*VLOOKUP($G5, Factor!$C$4:$N$36, 5, 0)*INDEX(Factor!$C$41:$N$87, _xlfn.XMATCH($C5, Factor!$C$41:$C$87, -1), 5)} -> 4 | W5: {=L5*VLOOKUP($G5, Factor!$C$4:$N$36, 6, 0)*INDEX(Factor!$C$41:$N$87, _xlfn.XMATCH($C5, Factor!$C$41:$C$87, -1), 6)} -> 10 | X5: {=M5*VLOOKUP($G5, Factor!$C$4:$N$36, 7, 0)*INDEX(Factor!$C$41:$N$87, _xlfn.XMATCH($C5, Factor!$C$41:$C$87, -1), 7)} -> 10000 | Y5: {=N5*VLOOKUP($G5, Factor!$C$4:$N$36, 8, 0)*INDEX(Factor!$C$41:$N$87, _xlfn.XMATCH($C5, Factor!$C$41:$C$87, -1), 8)} -> 1000 | Z5: {=O5*VLOOKUP($G5, Factor!$C$4:$N$36, 9, 0)*INDEX(Factor!$C$41:$N$87, _xlfn.XMATCH($C5, Factor!$C$41:$C$87, -1), 9)} -> 30 | AA5: {=P5*VLOOKUP($G5, Factor!$C$4:$N$36, 10, 0)*INDEX(Factor!$C$41:$N$87, _xlfn.XMATCH($C5, Factor!$C$41:$C$87, -1), 10)} -> 1000 | AB5: {=Q5*VLOOKUP($G5, Factor!$C$4:$N$36, 11, 0)*INDEX(Factor!$C$41:$N$87, _xlfn.XMATCH($C5, Factor!$C$41:$C$87, -1), 11)} -> 1 | AC5: {=R5*VLOOKUP($G5, Factor!$C$4:$N$36, 12, 0)*INDEX(Factor!$C$41:$N$87, _xlfn.XMATCH($C5, Factor!$C$41:$C$87, -1), 12)} -> 1
A6: ="locomotive_"& VLOOKUP(F6, Factor!$BK$4:$BL$6, 2, 0) &"_"&Locomotive!D6&"_"&VLOOKUP(E6, Factor!$BM$4:$BN$36, 2, 0) -> locomotive_El_T1_001 | B6: =D6&" "&G6&"기관차" -> T1 표준 전기기관차 | C6: =VLOOKUP(D6, Factor!$B$41:$C$50, 2, 0) -> 10000 | D6: T1 | E6: 표준 | F6: 전기 | G6: =E6&" "&F6 -> 표준 전기 | H6: 1 | I6: 1 | J6: 1 | K6: 1 | L6: 1 | M6: 1 | N6: 1 | O6: 1 | P6: 1 | Q6: 1 | R6: 1 | S6: {=H6*VLOOKUP($G6, Factor!$C$4:$N$36, 2, 0)*INDEX(Factor!$C$41:$N$87, _xlfn.XMATCH($C6, Factor!$C$41:$C$87, -1), 2)} -> 200 | T6: {=I6*VLOOKUP($G6, Factor!$C$4:$N$36, 3, 0)*INDEX(Factor!$C$41:$N$87, _xlfn.XMATCH($C6, Factor!$C$41:$C$87, -1), 3)} -> 800 | U6: {=J6*VLOOKUP($G6, Factor!$C$4:$N$36, 4, 0)*INDEX(Factor!$C$41:$N$87, _xlfn.XMATCH($C6, Factor!$C$41:$C$87, -1), 4)} -> 2 | V6: {=K6*VLOOKUP($G6, Factor!$C$4:$N$36, 5, 0)*INDEX(Factor!$C$41:$N$87, _xlfn.XMATCH($C6, Factor!$C$41:$C$87, -1), 5)} -> 8 | W6: {=L6*VLOOKUP($G6, Factor!$C$4:$N$36, 6, 0)*INDEX(Factor!$C$41:$N$87, _xlfn.XMATCH($C6, Factor!$C$41:$C$87, -1), 6)} -> 10 | X6: {=M6*VLOOKUP($G6, Factor!$C$4:$N$36, 7, 0)*INDEX(Factor!$C$41:$N$87, _xlfn.XMATCH($C6, Factor!$C$41:$C$87, -1), 7)} -> 7000 | Y6: {=N6*VLOOKUP($G6, Factor!$C$4:$N$36, 8, 0)*INDEX(Factor!$C$41:$N$87, _xlfn.XMATCH($C6, Factor!$C$41:$C$87, -1), 8)} -> 700 | Z6: {=O6*VLOOKUP($G6, Factor!$C$4:$N$36, 9, 0)*INDEX(Factor!$C$41:$N$87, _xlfn.XMATCH($C6, Factor!$C$41:$C$87, -1), 9)} -> 5 | AA6: {=P6*VLOOKUP($G6, Factor!$C$4:$N$36, 10, 0)*INDEX(Factor!$C$41:$N$87, _xlfn.XMATCH($C6, Factor!$C$41:$C$87, -1), 10)} -> 700 | AB6: {=Q6*VLOOKUP($G6, Factor!$C$4:$N$36, 11, 0)*INDEX(Factor!$C$41:$N$87, _xlfn.XMATCH($C6, Factor!$C$41:$C$87, -1), 11)} -> 1 | AC6: {=R6*VLOOKUP($G6, Factor!$C$4:$N$36, 12, 0)*INDEX(Factor!$C$41:$N$87, _xlfn.XMATCH($C6, Factor!$C$41:$C$87, -1), 12)} -> 1
A7: ="locomotive_"& VLOOKUP(F7, Factor!$BK$4:$BL$6, 2, 0) &"_"&Locomotive!D7&"_"&VLOOKUP(E7, Factor!$BM$4:$BN$36, 2, 0) -> locomotive_Dz_T1_001 | B7: =D7&" "&G7&"기관차" -> T1 표준 디젤기관차 | C7: =VLOOKUP(D7, Factor!$B$41:$C$50, 2, 0) -> 10000 | D7: T1 | E7: 표준 | F7: 디젤 | G7: =E7&" "&F7 -> 표준 디젤 | H7: 1 | I7: 1 | J7: 1 | K7: 1 | L7: 1 | M7: 1 | N7: 1 | O7: 1 | P7: 1 | Q7: 1 | R7: 1 | S7: {=H7*VLOOKUP($G7, Factor!$C$4:$N$36, 2, 0)*INDEX(Factor!$C$41:$N$87, _xlfn.XMATCH($C7, Factor!$C$41:$C$87, -1), 2)} -> 150 | T7: {=I7*VLOOKUP($G7, Factor!$C$4:$N$36, 3, 0)*INDEX(Factor!$C$41:$N$87, _xlfn.XMATCH($C7, Factor!$C$41:$C$87, -1), 3)} -> 1200 | U7: {=J7*VLOOKUP($G7, Factor!$C$4:$N$36, 4, 0)*INDEX(Factor!$C$41:$N$87, _xlfn.XMATCH($C7, Factor!$C$41:$C$87, -1), 4)} -> 2 | V7: {=K7*VLOOKUP($G7, Factor!$C$4:$N$36, 5, 0)*INDEX(Factor!$C$41:$N$87, _xlfn.XMATCH($C7, Factor!$C$41:$C$87, -1), 5)} -> 6 | W7: {=L7*VLOOKUP($G7, Factor!$C$4:$N$36, 6, 0)*INDEX(Factor!$C$41:$N$87, _xlfn.XMATCH($C7, Factor!$C$41:$C$87, -1), 6)} -> 10 | X7: {=M7*VLOOKUP($G7, Factor!$C$4:$N$36, 7, 0)*INDEX(Factor!$C$41:$N$87, _xlfn.XMATCH($C7, Factor!$C$41:$C$87, -1), 7)} -> 15000 | Y7: {=N7*VLOOKUP($G7, Factor!$C$4:$N$36, 8, 0)*INDEX(Factor!$C$41:$N$87, _xlfn.XMATCH($C7, Factor!$C$41:$C$87, -1), 8)} -> 800 | Z7: {=O7*VLOOKUP($G7, Factor!$C$4:$N$36, 9, 0)*INDEX(Factor!$C$41:$N$87, _xlfn.XMATCH($C7, Factor!$C$41:$C$87, -1), 9)} -> 10 | AA7: {=P7*VLOOKUP($G7, Factor!$C$4:$N$36, 10, 0)*INDEX(Factor!$C$41:$N$87, _xlfn.XMATCH($C7, Factor!$C$41:$C$87, -1), 10)} -> 800 | AB7: {=Q7*VLOOKUP($G7, Factor!$C$4:$N$36, 11, 0)*INDEX(Factor!$C$41:$N$87, _xlfn.XMATCH($C7, Factor!$C$41:$C$87, -1), 11)} -> 1 | AC7: {=R7*VLOOKUP($G7, Factor!$C$4:$N$36, 12, 0)*INDEX(Factor!$C$41:$N$87, _xlfn.XMATCH($C7, Factor!$C$41:$C$87, -1), 12)} -> 1
A8: ="locomotive_"& VLOOKUP(F8, Factor!$BK$4:$BL$6, 2, 0) &"_"&Locomotive!D8&"_"&VLOOKUP(E8, Factor!$BM$4:$BN$36, 2, 0) -> locomotive_St_T1_002 | B8: =D8&" "&G8&"기관차" -> T1 쾌속 증기기관차 | C8: =VLOOKUP(D8, Factor!$B$41:$C$50, 2, 0) -> 10000 | D8: T1 | E8: 쾌속 | F8: 증기 | G8: =E8&" "&F8 -> 쾌속 증기 | H8: 1 | I8: 1 | J8: 1 | K8: 1 | L8: 1 | M8: 1 | N8: 1 | O8: 1 | P8: 1 | Q8: 1 | R8: 1 | S8: {=H8*VLOOKUP($G8, Factor!$C$4:$N$36, 2, 0)*INDEX(Factor!$C$41:$N$87, _xlfn.XMATCH($C8, Factor!$C$41:$C$87, -1), 2)} -> 110 | T8: {=I8*VLOOKUP($G8, Factor!$C$4:$N$36, 3, 0)*INDEX(Factor!$C$41:$N$87, _xlfn.XMATCH($C8, Factor!$C$41:$C$87, -1), 3)} -> 900 | U8: {=J8*VLOOKUP($G8, Factor!$C$4:$N$36, 4, 0)*INDEX(Factor!$C$41:$N$87, _xlfn.XMATCH($C8, Factor!$C$41:$C$87, -1), 4)} -> 2 | V8: {=K8*VLOOKUP($G8, Factor!$C$4:$N$36, 5, 0)*INDEX(Factor!$C$41:$N$87, _xlfn.XMATCH($C8, Factor!$C$41:$C$87, -1), 5)} -> 6 | W8: {=L8*VLOOKUP($G8, Factor!$C$4:$N$36, 6, 0)*INDEX(Factor!$C$41:$N$87, _xlfn.XMATCH($C8, Factor!$C$41:$C$87, -1), 6)} -> 10 | X8: {=M8*VLOOKUP($G8, Factor!$C$4:$N$36, 7, 0)*INDEX(Factor!$C$41:$N$87, _xlfn.XMATCH($C8, Factor!$C$41:$C$87, -1), 7)} -> 10000 | Y8: {=N8*VLOOKUP($G8, Factor!$C$4:$N$36, 8, 0)*INDEX(Factor!$C$41:$N$87, _xlfn.XMATCH($C8, Factor!$C$41:$C$87, -1), 8)} -> 800 | Z8: {=O8*VLOOKUP($G8, Factor!$C$4:$N$36, 9, 0)*INDEX(Factor!$C$41:$N$87, _xlfn.XMATCH($C8, Factor!$C$41:$C$87, -1), 9)} -> 20 | AA8: {=P8*VLOOKUP($G8, Factor!$C$4:$N$36, 10, 0)*INDEX(Factor!$C$41:$N$87, _xlfn.XMATCH($C8, Factor!$C$41:$C$87, -1), 10)} -> 800 | AB8: {=Q8*VLOOKUP($G8, Factor!$C$4:$N$36, 11, 0)*INDEX(Factor!$C$41:$N$87, _xlfn.XMATCH($C8, Factor!$C$41:$C$87, -1), 11)} -> 1 | AC8: {=R8*VLOOKUP($G8, Factor!$C$4:$N$36, 12, 0)*INDEX(Factor!$C$41:$N$87, _xlfn.XMATCH($C8, Factor!$C$41:$C$87, -1), 12)} -> 1
A9: ="locomotive_"& VLOOKUP(F9, Factor!$BK$4:$BL$6, 2, 0) &"_"&Locomotive!D9&"_"&VLOOKUP(E9, Factor!$BM$4:$BN$36, 2, 0) -> locomotive_El_T1_002 | B9: =D9&" "&G9&"기관차" -> T1 쾌속 전기기관차 | C9: =VLOOKUP(D9, Factor!$B$41:$C$50, 2, 0) -> 10000 | D9: T1 | E9: 쾌속 | F9: 전기 | G9: =E9&" "&F9 -> 쾌속 전기 | H9: 1 | I9: 1 | J9: 1 | K9: 1 | L9: 1 | M9: 1 | N9: 1 | O9: 1 | P9: 1 | Q9: 1 | R9: 1 | S9: {=H9*VLOOKUP($G9, Factor!$C$4:$N$36, 2, 0)*INDEX(Factor!$C$41:$N$87, _xlfn.XMATCH($C9, Factor!$C$41:$C$87, -1), 2)} -> 220 | T9: {=I9*VLOOKUP($G9, Factor!$C$4:$N$36, 3, 0)*INDEX(Factor!$C$41:$N$87, _xlfn.XMATCH($C9, Factor!$C$41:$C$87, -1), 3)} -> 700 | U9: {=J9*VLOOKUP($G9, Factor!$C$4:$N$36, 4, 0)*INDEX(Factor!$C$41:$N$87, _xlfn.XMATCH($C9, Factor!$C$41:$C$87, -1), 4)} -> 2 | V9: {=K9*VLOOKUP($G9, Factor!$C$4:$N$36, 5, 0)*INDEX(Factor!$C$41:$N$87, _xlfn.XMATCH($C9, Factor!$C$41:$C$87, -1), 5)} -> 10 | W9: {=L9*VLOOKUP($G9, Factor!$C$4:$N$36, 6, 0)*INDEX(Factor!$C$41:$N$87, _xlfn.XMATCH($C9, Factor!$C$41:$C$87, -1), 6)} -> 10 | X9: {=M9*VLOOKUP($G9, Factor!$C$4:$N$36, 7, 0)*INDEX(Factor!$C$41:$N$87, _xlfn.XMATCH($C9, Factor!$C$41:$C$87, -1), 7)} -> 7000 | Y9: {=N9*VLOOKUP($G9, Factor!$C$4:$N$36, 8, 0)*INDEX(Factor!$C$41:$N$87, _xlfn.XMATCH($C9, Factor!$C$41:$C$87, -1), 8)} -> 500 | Z9: {=O9*VLOOKUP($G9, Factor!$C$4:$N$36, 9, 0)*INDEX(Factor!$C$41:$N$87, _xlfn.XMATCH($C9, Factor!$C$41:$C$87, -1), 9)} -> 3 | AA9: {=P9*VLOOKUP($G9, Factor!$C$4:$N$36, 10, 0)*INDEX(Factor!$C$41:$N$87, _xlfn.XMATCH($C9, Factor!$C$41:$C$87, -1), 10)} -> 500 | AB9: {=Q9*VLOOKUP($G9, Factor!$C$4:$N$36, 11, 0)*INDEX(Factor!$C$41:$N$87, _xlfn.XMATCH($C9, Factor!$C$41:$C$87, -1), 11)} -> 1 | AC9: {=R9*VLOOKUP($G9, Factor!$C$4:$N$36, 12, 0)*INDEX(Factor!$C$41:$N$87, _xlfn.XMATCH($C9, Factor!$C$41:$C$87, -1), 12)} -> 1
A10: ="locomotive_"& VLOOKUP(F10, Factor!$BK$4:$BL$6, 2, 0) &"_"&Locomotive!D10&"_"&VLOOKUP(E10, Factor!$BM$4:$BN$36, 2, 0) -> locomotive_Dz_T1_002 | B10: =D10&" "&G10&"기관차" -> T1 쾌속 디젤기관차 | C10: =VLOOKUP(D10, Factor!$B$41:$C$50, 2, 0) -> 10000 | D10: T1 | E10: 쾌속 | F10: 디젤 | G10: =E10&" "&F10 -> 쾌속 디젤 | H10: 1 | I10: 1 | J10: 1 | K10: 1 | L10: 1 | M10: 1 | N10: 1 | O10: 1 | P10: 1 | Q10: 1 | R10: 1 | S10: {=H10*VLOOKUP($G10, Factor!$C$4:$N$36, 2, 0)*INDEX(Factor!$C$41:$N$87, _xlfn.XMATCH($C10, Factor!$C$41:$C$87, -1), 2)} -> 165 | T10: {=I10*VLOOKUP($G10, Factor!$C$4:$N$36, 3, 0)*INDEX(Factor!$C$41:$N$87, _xlfn.XMATCH($C10, Factor!$C$41:$C$87, -1), 3)} -> 1000 | U10: {=J10*VLOOKUP($G10, Factor!$C$4:$N$36, 4, 0)*INDEX(Factor!$C$41:$N$87, _xlfn.XMATCH($C10, Factor!$C$41:$C$87, -1), 4)} -> 2 | V10: {=K10*VLOOKUP($G10, Factor!$C$4:$N$36, 5, 0)*INDEX(Factor!$C$41:$N$87, _xlfn.XMATCH($C10, Factor!$C$41:$C$87, -1), 5)} -> 8 | W10: {=L10*VLOOKUP($G10, Factor!$C$4:$N$36, 6, 0)*INDEX(Factor!$C$41:$N$87, _xlfn.XMATCH($C10, Factor!$C$41:$C$87, -1), 6)} -> 10 | X10: {=M10*VLOOKUP($G10, Factor!$C$4:$N$36, 7, 0)*INDEX(Factor!$C$41:$N$87, _xlfn.XMATCH($C10, Factor!$C$41:$C$87, -1), 7)} -> 15000 | Y10: {=N10*VLOOKUP($G10, Factor!$C$4:$N$36, 8, 0)*INDEX(Factor!$C$41:$N$87, _xlfn.XMATCH($C10, Factor!$C$41:$C$87, -1), 8)} -> 650 | Z10: {=O10*VLOOKUP($G10, Factor!$C$4:$N$36, 9, 0)*INDEX(Factor!$C$41:$N$87, _xlfn.XMATCH($C10, Factor!$C$41:$C$87, -1), 9)} -> 5 | AA10: {=P10*VLOOKUP($G10, Factor!$C$4:$N$36, 10, 0)*INDEX(Factor!$C$41:$N$87, _xlfn.XMATCH($C10, Factor!$C$41:$C$87, -1), 10)} -> 650 | AB10: {=Q10*VLOOKUP($G10, Factor!$C$4:$N$36, 11, 0)*INDEX(Factor!$C$41:$N$87, _xlfn.XMATCH($C10, Factor!$C$41:$C$87, -1), 11)} -> 1 | AC10: {=R10*VLOOKUP($G10, Factor!$C$4:$N$36, 12, 0)*INDEX(Factor!$C$41:$N$87, _xlfn.XMATCH($C10, Factor!$C$41:$C$87, -1), 12)} -> 1
A11: ="locomotive_"& VLOOKUP(F11, Factor!$BK$4:$BL$6, 2, 0) &"_"&Locomotive!D11&"_"&VLOOKUP(E11, Factor!$BM$4:$BN$36, 2, 0) -> locomotive_St_T1_003 | B11: =D11&" "&G11&"기관차" -> T1 중갑 증기기관차 | C11: =VLOOKUP(D11, Factor!$B$41:$C$50, 2, 0) -> 10000 | D11: T1 | E11: 중갑 | F11: 증기 | G11: =E11&" "&F11 -> 중갑 증기 | H11: 1 | I11: 1 | J11: 1 | K11: 1 | L11: 1 | M11: 1 | N11: 1 | O11: 1 | P11: 1 | Q11: 1 | R11: 1 | S11: {=H11*VLOOKUP($G11, Factor!$C$4:$N$36, 2, 0)*INDEX(Factor!$C$41:$N$87, _xlfn.XMATCH($C11, Factor!$C$41:$C$87, -1), 2)} -> 90 | T11: {=I11*VLOOKUP($G11, Factor!$C$4:$N$36, 3, 0)*INDEX(Factor!$C$41:$N$87, _xlfn.XMATCH($C11, Factor!$C$41:$C$87, -1), 3)} -> 1200 | U11: {=J11*VLOOKUP($G11, Factor!$C$4:$N$36, 4, 0)*INDEX(Factor!$C$41:$N$87, _xlfn.XMATCH($C11, Factor!$C$41:$C$87, -1), 4)} -> 2 | V11: {=K11*VLOOKUP($G11, Factor!$C$4:$N$36, 5, 0)*INDEX(Factor!$C$41:$N$87, _xlfn.XMATCH($C11, Factor!$C$41:$C$87, -1), 5)} -> 4 | W11: {=L11*VLOOKUP($G11, Factor!$C$4:$N$36, 6, 0)*INDEX(Factor!$C$41:$N$87, _xlfn.XMATCH($C11, Factor!$C$41:$C$87, -1), 6)} -> 10 | X11: {=M11*VLOOKUP($G11, Factor!$C$4:$N$36, 7, 0)*INDEX(Factor!$C$41:$N$87, _xlfn.XMATCH($C11, Factor!$C$41:$C$87, -1), 7)} -> 8000 | Y11: {=N11*VLOOKUP($G11, Factor!$C$4:$N$36, 8, 0)*INDEX(Factor!$C$41:$N$87, _xlfn.XMATCH($C11, Factor!$C$41:$C$87, -1), 8)} -> 1500 | Z11: {=O11*VLOOKUP($G11, Factor!$C$4:$N$36, 9, 0)*INDEX(Factor!$C$41:$N$87, _xlfn.XMATCH($C11, Factor!$C$41:$C$87, -1), 9)} -> 50 | AA11: {=P11*VLOOKUP($G11, Factor!$C$4:$N$36, 10, 0)*INDEX(Factor!$C$41:$N$87, _xlfn.XMATCH($C11, Factor!$C$41:$C$87, -1), 10)} -> 1500 | AB11: {=Q11*VLOOKUP($G11, Factor!$C$4:$N$36, 11, 0)*INDEX(Factor!$C$41:$N$87, _xlfn.XMATCH($C11, Factor!$C$41:$C$87, -1), 11)} -> 1 | AC11: {=R11*VLOOKUP($G11, Factor!$C$4:$N$36, 12, 0)*INDEX(Factor!$C$41:$N$87, _xlfn.XMATCH($C11, Factor!$C$41:$C$87, -1), 12)} -> 1
A12: ="locomotive_"& VLOOKUP(F12, Factor!$BK$4:$BL$6, 2, 0) &"_"&Locomotive!D12&"_"&VLOOKUP(E12, Factor!$BM$4:$BN$36, 2, 0) -> locomotive_El_T1_003 | B12: =D12&" "&G12&"기관차" -> T1 중갑 전기기관차 | C12: =VLOOKUP(D12, Factor!$B$41:$C$50, 2, 0) -> 10000 | D12: T1 | E12: 중갑 | F12: 전기 | G12: =E12&" "&F12 -> 중갑 전기 | H12: 1 | I12: 1 | J12: 1 | K12: 1 | L12: 1 | M12: 1 | N12: 1 | O12: 1 | P12: 1 | Q12: 1 | R12: 1 | S12: {=H12*VLOOKUP($G12, Factor!$C$4:$N$36, 2, 0)*INDEX(Factor!$C$41:$N$87, _xlfn.XMATCH($C12, Factor!$C$41:$C$87, -1), 2)} -> 170 | T12: {=I12*VLOOKUP($G12, Factor!$C$4:$N$36, 3, 0)*INDEX(Factor!$C$41:$N$87, _xlfn.XMATCH($C12, Factor!$C$41:$C$87, -1), 3)} -> 100 | U12: {=J12*VLOOKUP($G12, Factor!$C$4:$N$36, 4, 0)*INDEX(Factor!$C$41:$N$87, _xlfn.XMATCH($C12, Factor!$C$41:$C$87, -1), 4)} -> 2 | V12: {=K12*VLOOKUP($G12, Factor!$C$4:$N$36, 5, 0)*INDEX(Factor!$C$41:$N$87, _xlfn.XMATCH($C12, Factor!$C$41:$C$87, -1), 5)} -> 8 | W12: {=L12*VLOOKUP($G12, Factor!$C$4:$N$36, 6, 0)*INDEX(Factor!$C$41:$N$87, _xlfn.XMATCH($C12, Factor!$C$41:$C$87, -1), 6)} -> 10 | X12: {=M12*VLOOKUP($G12, Factor!$C$4:$N$36, 7, 0)*INDEX(Factor!$C$41:$N$87, _xlfn.XMATCH($C12, Factor!$C$41:$C$87, -1), 7)} -> 5000 | Y12: {=N12*VLOOKUP($G12, Factor!$C$4:$N$36, 8, 0)*INDEX(Factor!$C$41:$N$87, _xlfn.XMATCH($C12, Factor!$C$41:$C$87, -1), 8)} -> 1000 | Z12: {=O12*VLOOKUP($G12, Factor!$C$4:$N$36, 9, 0)*INDEX(Factor!$C$41:$N$87, _xlfn.XMATCH($C12, Factor!$C$41:$C$87, -1), 9)} -> 15 | AA12: {=P12*VLOOKUP($G12, Factor!$C$4:$N$36, 10, 0)*INDEX(Factor!$C$41:$N$87, _xlfn.XMATCH($C12, Factor!$C$41:$C$87, -1), 10)} -> 1000 | AB12: {=Q12*VLOOKUP($G12, Factor!$C$4:$N$36, 11, 0)*INDEX(Factor!$C$41:$N$87, _xlfn.XMATCH($C12, Factor!$C$41:$C$87, -1), 11)} -> 1 | AC12: {=R12*VLOOKUP($G12, Factor!$C$4:$N$36, 12, 0)*INDEX(Factor!$C$41:$N$87, _xlfn.XMATCH($C12, Factor!$C$41:$C$87, -1), 12)} -> 1
A13: ="locomotive_"& VLOOKUP(F13, Factor!$BK$4:$BL$6, 2, 0) &"_"&Locomotive!D13&"_"&VLOOKUP(E13, Factor!$BM$4:$BN$36, 2, 0) -> locomotive_Dz_T1_003 | B13: =D13&" "&G13&"기관차" -> T1 중갑 디젤기관차 | C13: =VLOOKUP(D13, Factor!$B$41:$C$50, 2, 0) -> 10000 | D13: T1 | E13: 중갑 | F13: 디젤 | G13: =E13&" "&F13 -> 중갑 디젤 | H13: 1 | I13: 1 | J13: 1 | K13: 1 | L13: 1 | M13: 1 | N13: 1 | O13: 1 | P13: 1 | Q13: 1 | R13: 1 | S13: {=H13*VLOOKUP($G13, Factor!$C$4:$N$36, 2, 0)*INDEX(Factor!$C$41:$N$87, _xlfn.XMATCH($C13, Factor!$C$41:$C$87, -1), 2)} -> 110 | T13: {=I13*VLOOKUP($G13, Factor!$C$4:$N$36, 3, 0)*INDEX(Factor!$C$41:$N$87, _xlfn.XMATCH($C13, Factor!$C$41:$C$87, -1), 3)} -> 1500 | U13: {=J13*VLOOKUP($G13, Factor!$C$4:$N$36, 4, 0)*INDEX(Factor!$C$41:$N$87, _xlfn.XMATCH($C13, Factor!$C$41:$C$87, -1), 4)} -> 2 | V13: {=K13*VLOOKUP($G13, Factor!$C$4:$N$36, 5, 0)*INDEX(Factor!$C$41:$N$87, _xlfn.XMATCH($C13, Factor!$C$41:$C$87, -1), 5)} -> 6 | W13: {=L13*VLOOKUP($G13, Factor!$C$4:$N$36, 6, 0)*INDEX(Factor!$C$41:$N$87, _xlfn.XMATCH($C13, Factor!$C$41:$C$87, -1), 6)} -> 10 | X13: {=M13*VLOOKUP($G13, Factor!$C$4:$N$36, 7, 0)*INDEX(Factor!$C$41:$N$87, _xlfn.XMATCH($C13, Factor!$C$41:$C$87, -1), 7)} -> 12000 | Y13: {=N13*VLOOKUP($G13, Factor!$C$4:$N$36, 8, 0)*INDEX(Factor!$C$41:$N$87, _xlfn.XMATCH($C13, Factor!$C$41:$C$87, -1), 8)} -> 1300 | Z13: {=O13*VLOOKUP($G13, Factor!$C$4:$N$36, 9, 0)*INDEX(Factor!$C$41:$N$87, _xlfn.XMATCH($C13, Factor!$C$41:$C$87, -1), 9)} -> 30 | AA13: {=P13*VLOOKUP($G13, Factor!$C$4:$N$36, 10, 0)*INDEX(Factor!$C$41:$N$87, _xlfn.XMATCH($C13, Factor!$C$41:$C$87, -1), 10)} -> 1300 | AB13: {=Q13*VLOOKUP($G13, Factor!$C$4:$N$36, 11, 0)*INDEX(Factor!$C$41:$N$87, _xlfn.XMATCH($C13, Factor!$C$41:$C$87, -1), 11)} -> 1 | AC13: {=R13*VLOOKUP($G13, Factor!$C$4:$N$36, 12, 0)*INDEX(Factor!$C$41:$N$87, _xlfn.XMATCH($C13, Factor!$C$41:$C$87, -1), 12)} -> 1
A14: ="locomotive_"& VLOOKUP(F14, Factor!$BK$4:$BL$6, 2, 0) &"_"&Locomotive!D14&"_"&VLOOKUP(E14, Factor!$BM$4:$BN$36, 2, 0) -> locomotive_St_T1_004 | B14: =D14&" "&G14&"기관차" -> T1 화물 증기기관차 | C14: =VLOOKUP(D14, Factor!$B$41:$C$50, 2, 0) -> 10000 | D14: T1 | E14: 화물 | F14: 증기 | G14: =E14&" "&F14 -> 화물 증기 | H14: 1 | I14: 1 | J14: 1 | K14: 1 | L14: 1 | M14: 1 | N14: 1 | O14: 1 | P14: 1 | Q14: 1 | R14: 1 | S14: {=H14*VLOOKUP($G14, Factor!$C$4:$N$36, 2, 0)*INDEX(Factor!$C$41:$N$87, _xlfn.XMATCH($C14, Factor!$C$41:$C$87, -1), 2)} -> 90 | T14: {=I14*VLOOKUP($G14, Factor!$C$4:$N$36, 3, 0)*INDEX(Factor!$C$41:$N$87, _xlfn.XMATCH($C14, Factor!$C$41:$C$87, -1), 3)} -> 1000 | U14: {=J14*VLOOKUP($G14, Factor!$C$4:$N$36, 4, 0)*INDEX(Factor!$C$41:$N$87, _xlfn.XMATCH($C14, Factor!$C$41:$C$87, -1), 4)} -> 2 | V14: {=K14*VLOOKUP($G14, Factor!$C$4:$N$36, 5, 0)*INDEX(Factor!$C$41:$N$87, _xlfn.XMATCH($C14, Factor!$C$41:$C$87, -1), 5)} -> 4 | W14: {=L14*VLOOKUP($G14, Factor!$C$4:$N$36, 6, 0)*INDEX(Factor!$C$41:$N$87, _xlfn.XMATCH($C14, Factor!$C$41:$C$87, -1), 6)} -> 10 | X14: {=M14*VLOOKUP($G14, Factor!$C$4:$N$36, 7, 0)*INDEX(Factor!$C$41:$N$87, _xlfn.XMATCH($C14, Factor!$C$41:$C$87, -1), 7)} -> 10000 | Y14: {=N14*VLOOKUP($G14, Factor!$C$4:$N$36, 8, 0)*INDEX(Factor!$C$41:$N$87, _xlfn.XMATCH($C14, Factor!$C$41:$C$87, -1), 8)} -> 1000 | Z14: {=O14*VLOOKUP($G14, Factor!$C$4:$N$36, 9, 0)*INDEX(Factor!$C$41:$N$87, _xlfn.XMATCH($C14, Factor!$C$41:$C$87, -1), 9)} -> 30 | AA14: {=P14*VLOOKUP($G14, Factor!$C$4:$N$36, 10, 0)*INDEX(Factor!$C$41:$N$87, _xlfn.XMATCH($C14, Factor!$C$41:$C$87, -1), 10)} -> 1000 | AB14: {=Q14*VLOOKUP($G14, Factor!$C$4:$N$36, 11, 0)*INDEX(Factor!$C$41:$N$87, _xlfn.XMATCH($C14, Factor!$C$41:$C$87, -1), 11)} -> 3 | AC14: {=R14*VLOOKUP($G14, Factor!$C$4:$N$36, 12, 0)*INDEX(Factor!$C$41:$N$87, _xlfn.XMATCH($C14, Factor!$C$41:$C$87, -1), 12)} -> 1
A15: ="locomotive_"& VLOOKUP(F15, Factor!$BK$4:$BL$6, 2, 0) &"_"&Locomotive!D15&"_"&VLOOKUP(E15, Factor!$BM$4:$BN$36, 2, 0) -> locomotive_El_T1_004 | B15: =D15&" "&G15&"기관차" -> T1 화물 전기기관차 | C15: =VLOOKUP(D15, Factor!$B$41:$C$50, 2, 0) -> 10000 | D15: T1 | E15: 화물 | F15: 전기 | G15: =E15&" "&F15 -> 화물 전기 | H15: 1 | I15: 1 | J15: 1 | K15: 1 | L15: 1 | M15: 1 | N15: 1 | O15: 1 | P15: 1 | Q15: 1 | R15: 1 | S15: {=H15*VLOOKUP($G15, Factor!$C$4:$N$36, 2, 0)*INDEX(Factor!$C$41:$N$87, _xlfn.XMATCH($C15, Factor!$C$41:$C$87, -1), 2)} -> 180 | T15: {=I15*VLOOKUP($G15, Factor!$C$4:$N$36, 3, 0)*INDEX(Factor!$C$41:$N$87, _xlfn.XMATCH($C15, Factor!$C$41:$C$87, -1), 3)} -> 800 | U15: {=J15*VLOOKUP($G15, Factor!$C$4:$N$36, 4, 0)*INDEX(Factor!$C$41:$N$87, _xlfn.XMATCH($C15, Factor!$C$41:$C$87, -1), 4)} -> 2 | V15: {=K15*VLOOKUP($G15, Factor!$C$4:$N$36, 5, 0)*INDEX(Factor!$C$41:$N$87, _xlfn.XMATCH($C15, Factor!$C$41:$C$87, -1), 5)} -> 8 | W15: {=L15*VLOOKUP($G15, Factor!$C$4:$N$36, 6, 0)*INDEX(Factor!$C$41:$N$87, _xlfn.XMATCH($C15, Factor!$C$41:$C$87, -1), 6)} -> 10 | X15: {=M15*VLOOKUP($G15, Factor!$C$4:$N$36, 7, 0)*INDEX(Factor!$C$41:$N$87, _xlfn.XMATCH($C15, Factor!$C$41:$C$87, -1), 7)} -> 7000 | Y15: {=N15*VLOOKUP($G15, Factor!$C$4:$N$36, 8, 0)*INDEX(Factor!$C$41:$N$87, _xlfn.XMATCH($C15, Factor!$C$41:$C$87, -1), 8)} -> 700 | Z15: {=O15*VLOOKUP($G15, Factor!$C$4:$N$36, 9, 0)*INDEX(Factor!$C$41:$N$87, _xlfn.XMATCH($C15, Factor!$C$41:$C$87, -1), 9)} -> 5 | AA15: {=P15*VLOOKUP($G15, Factor!$C$4:$N$36, 10, 0)*INDEX(Factor!$C$41:$N$87, _xlfn.XMATCH($C15, Factor!$C$41:$C$87, -1), 10)} -> 700 | AB15: {=Q15*VLOOKUP($G15, Factor!$C$4:$N$36, 11, 0)*INDEX(Factor!$C$41:$N$87, _xlfn.XMATCH($C15, Factor!$C$41:$C$87, -1), 11)} -> 3 | AC15: {=R15*VLOOKUP($G15, Factor!$C$4:$N$36, 12, 0)*INDEX(Factor!$C$41:$N$87, _xlfn.XMATCH($C15, Factor!$C$41:$C$87, -1), 12)} -> 1
A16: ="locomotive_"& VLOOKUP(F16, Factor!$BK$4:$BL$6, 2, 0) &"_"&Locomotive!D16&"_"&VLOOKUP(E16, Factor!$BM$4:$BN$36, 2, 0) -> locomotive_Dz_T1_004 | B16: =D16&" "&G16&"기관차" -> T1 화물 디젤기관차 | C16: =VLOOKUP(D16, Factor!$B$41:$C$50, 2, 0) -> 10000 | D16: T1 | E16: 화물 | F16: 디젤 | G16: =E16&" "&F16 -> 화물 디젤 | H16: 1 | I16: 1 | J16: 1 | K16: 1 | L16: 1 | M16: 1 | N16: 1 | O16: 1 | P16: 1 | Q16: 1 | R16: 1 | S16: {=H16*VLOOKUP($G16, Factor!$C$4:$N$36, 2, 0)*INDEX(Factor!$C$41:$N$87, _xlfn.XMATCH($C16, Factor!$C$41:$C$87, -1), 2)} -> 120 | T16: {=I16*VLOOKUP($G16, Factor!$C$4:$N$36, 3, 0)*INDEX(Factor!$C$41:$N$87, _xlfn.XMATCH($C16, Factor!$C$41:$C$87, -1), 3)} -> 1200 | U16: {=J16*VLOOKUP($G16, Factor!$C$4:$N$36, 4, 0)*INDEX(Factor!$C$41:$N$87, _xlfn.XMATCH($C16, Factor!$C$41:$C$87, -1), 4)} -> 2 | V16: {=K16*VLOOKUP($G16, Factor!$C$4:$N$36, 5, 0)*INDEX(Factor!$C$41:$N$87, _xlfn.XMATCH($C16, Factor!$C$41:$C$87, -1), 5)} -> 6 | W16: {=L16*VLOOKUP($G16, Factor!$C$4:$N$36, 6, 0)*INDEX(Factor!$C$41:$N$87, _xlfn.XMATCH($C16, Factor!$C$41:$C$87, -1), 6)} -> 10 | X16: {=M16*VLOOKUP($G16, Factor!$C$4:$N$36, 7, 0)*INDEX(Factor!$C$41:$N$87, _xlfn.XMATCH($C16, Factor!$C$41:$C$87, -1), 7)} -> 15000 | Y16: {=N16*VLOOKUP($G16, Factor!$C$4:$N$36, 8, 0)*INDEX(Factor!$C$41:$N$87, _xlfn.XMATCH($C16, Factor!$C$41:$C$87, -1), 8)} -> 800 | Z16: {=O16*VLOOKUP($G16, Factor!$C$4:$N$36, 9, 0)*INDEX(Factor!$C$41:$N$87, _xlfn.XMATCH($C16, Factor!$C$41:$C$87, -1), 9)} -> 10 | AA16: {=P16*VLOOKUP($G16, Factor!$C$4:$N$36, 10, 0)*INDEX(Factor!$C$41:$N$87, _xlfn.XMATCH($C16, Factor!$C$41:$C$87, -1), 10)} -> 800 | AB16: {=Q16*VLOOKUP($G16, Factor!$C$4:$N$36, 11, 0)*INDEX(Factor!$C$41:$N$87, _xlfn.XMATCH($C16, Factor!$C$41:$C$87, -1), 11)} -> 3 | AC16: {=R16*VLOOKUP($G16, Factor!$C$4:$N$36, 12, 0)*INDEX(Factor!$C$41:$N$87, _xlfn.XMATCH($C16, Factor!$C$41:$C$87, -1), 12)} -> 1
... A274: ="locomotive_"& VLOOKUP(F274, Factor!$BK$4:$BL$6, 2, 0) &"_"&Locomotive!D274&"_"&VLOOKUP(E274, Factor!$BM$4:$BN$36, 2, 0) -> locomotive_Dz_T10_009 | B274: =D274&" "&G274&"기관차" -> T10 견인 디젤기관차 | C274: =VLOOKUP(D274, Factor!$B$41:$C$50, 2, 0) -> 100000 | D274: T10 | E274: 견인 | F274: 디젤 | G274: =E274&" "&F274 -> 견인 디젤 | H274: 1 | I274: 1 | J274: 1 | K274: 1 | L274: 1 | M274: 1 | N274: 1 | O274: 1 | P274: 1 | Q274: 1 | R274: 1 | S274: {=H274*VLOOKUP($G274, Factor!$C$4:$N$36, 2, 0)*INDEX(Factor!$C$41:$N$87, _xlfn.XMATCH($C274, Factor!$C$41:$C$87, -1), 2)} -> 336 | T274: {=I274*VLOOKUP($G274, Factor!$C$4:$N$36, 3, 0)*INDEX(Factor!$C$41:$N$87, _xlfn.XMATCH($C274, Factor!$C$41:$C$87, -1), 3)} -> 3360 | U274: {=J274*VLOOKUP($G274, Factor!$C$4:$N$36, 4, 0)*INDEX(Factor!$C$41:$N$87, _xlfn.XMATCH($C274, Factor!$C$41:$C$87, -1), 4)} -> 11 | V274: {=K274*VLOOKUP($G274, Factor!$C$4:$N$36, 5, 0)*INDEX(Factor!$C$41:$N$87, _xlfn.XMATCH($C274, Factor!$C$41:$C$87, -1), 5)} -> 14 | W274: {=L274*VLOOKUP($G274, Factor!$C$4:$N$36, 6, 0)*INDEX(Factor!$C$41:$N$87, _xlfn.XMATCH($C274, Factor!$C$41:$C$87, -1), 6)} -> 28 | X274: {=M274*VLOOKUP($G274, Factor!$C$4:$N$36, 7, 0)*INDEX(Factor!$C$41:$N$87, _xlfn.XMATCH($C274, Factor!$C$41:$C$87, -1), 7)} -> 56000 | Y274: {=N274*VLOOKUP($G274, Factor!$C$4:$N$36, 8, 0)*INDEX(Factor!$C$41:$N$87, _xlfn.XMATCH($C274, Factor!$C$41:$C$87, -1), 8)} -> 2240 | Z274: {=O274*VLOOKUP($G274, Factor!$C$4:$N$36, 9, 0)*INDEX(Factor!$C$41:$N$87, _xlfn.XMATCH($C274, Factor!$C$41:$C$87, -1), 9)} -> 28 | AA274: {=P274*VLOOKUP($G274, Factor!$C$4:$N$36, 10, 0)*INDEX(Factor!$C$41:$N$87, _xlfn.XMATCH($C274, Factor!$C$41:$C$87, -1), 10)} -> 2240 | AB274: {=Q274*VLOOKUP($G274, Factor!$C$4:$N$36, 11, 0)*INDEX(Factor!$C$41:$N$87, _xlfn.XMATCH($C274, Factor!$C$41:$C$87, -1), 11)} -> 10 | AC274: {=R274*VLOOKUP($G274, Factor!$C$4:$N$36, 12, 0)*INDEX(Factor!$C$41:$N$87, _xlfn.XMATCH($C274, Factor!$C$41:$C$87, -1), 12)} -> 10

Sheet Couch
A1: ● 3열은 데이터의 자료형이며 자료형이 한글로 되어있는 경우 인게임에서 사용하지 않는 데이터지만 테이블에서 수치조정 또는 색인을 위해 넣은 데이터이다. ● 보정치의 수치를 조정해 각 몬스터 별로 상세 능력치를 조정할 수 있다. ● 보정값의 경우 수치 조정의도가 없는 경우 1을 유지한다. ● ID는 couch_객실종류_등급_번호 순으로 구성된다. ● ID 이름 가격은 3열에 노란색으로 칠해진 내부색인 칼럼에 데이터를 입력하면 자동 생성된다. ● 배정되는 값은 Factor 시트를 참고한다.
A2: 편성칸 ID | B2: 편성 칸 이름 | C2: 편성 칸 가격 | D2: 등급 | E2: 편성 칸 종류(특징구분) | F2: 편성칸 종류(자재 구분) | G2: 편성 칸 종류 | H2: 내구력 보정치 | I2: 방어력 보정치 | J2: 자기장 방어막 보정치 | K2: 승무원 시너지 계수 보정치 | L2: 편성 칸 무게 보정치 | M2: 내구력 | N2: 방어력 | O2: 자기장 방어막 | P2: 승무원 시너지 계수 | Q2: 편성 칸 무게 | R2: 편성 칸 설명문구
A3: string | B3: string | C3: int | D3: 내부색인 | E3: 내부색인 | F3: 내부색인 | G3: 내부색인 | H3: 보정치 | I3: 보정치 | J3: 보정치 | K3: 보정치 | L3: 보정치 | M3: int | N3: int | O3: int | P3: float | Q3: int | R3: string
A4: couchId | B4: couchName | C4: couchCost | D4: couchType | E4: couchType | F4: couchType | G4: couchType | H4: couchHp | I4: couchDef | J4: couchShield | K4: couchSynergyPower | L4: couchWeight | M4: couchHp | N4: couchDef | O4: couchShield | P4: couchSynergyPower | Q4: couchWeight | R4: couchText
A5: ="couch_"&VLOOKUP(F5, Factor!$BQ$4:$BR$6, 2, 0)&"_"&Couch!D5&"_"&VLOOKUP(Couch!E5, Factor!$BS$4:$BT$13, 2, 0) -> couch_Wo_T1_001 | B5: =D5&" "&G5&"객차" -> T1 표준 나무객차 | C5: =VLOOKUP(D5, Factor!$P$41:$Q$50, 2, 0) -> 2000 | D5: T1 | E5: 표준 | F5: 나무 | G5: =E5&" " &F5 -> 표준 나무 | H5: 1 | I5: 1 | J5: 1 | K5: 1 | L5: 1 | M5: {=H5*VLOOKUP($G5, Factor!$Q$4:$V$36, 2, 0)*INDEX(Factor!$Q$41:$V$87, _xlfn.XMATCH($C5, Factor!$Q$41:$Q$87, -1), 2)} -> 500 | N5: {=I5*VLOOKUP($G5, Factor!$Q$4:$V$36, 3, 0)*INDEX(Factor!$Q$41:$V$87, _xlfn.XMATCH($C5, Factor!$Q$41:$Q$87, -1), 3)} -> 10 | O5: {=J5*VLOOKUP($G5, Factor!$Q$4:$V$36, 4, 0)*INDEX(Factor!$Q$41:$V$87, _xlfn.XMATCH($C5, Factor!$Q$41:$Q$87, -1), 4)} -> 500 | P5: {=K5*VLOOKUP($G5, Factor!$Q$4:$V$36, 5, 0)*INDEX(Factor!$Q$41:$V$87, _xlfn.XMATCH($C5, Factor!$Q$41:$Q$87, -1), 5)} -> 1 | Q5: {=L5*VLOOKUP($G5, Factor!$Q$4:$V$36, 6, 0)*INDEX(Factor!$Q$41:$V$87, _xlfn.XMATCH($C5, Factor!$Q$41:$Q$87, -1), 6)} -> 1000
A6: ="couch_"&VLOOKUP(F6, Factor!$BQ$4:$BR$6, 2, 0)&"_"&Couch!D6&"_"&VLOOKUP(Couch!E6, Factor!$BS$4:$BT$13, 2, 0) -> couch_Wo_T1_002 | B6: =D6&" "&G6&"객차" -> T1 중갑 나무객차 | C6: =VLOOKUP(D6, Factor!$P$41:$Q$50, 2, 0) -> 2000 | D6: T1 | E6: 중갑 | F6: 나무 | G6: =E6&" " &F6 -> 중갑 나무 | H6: 1 | I6: 1 | J6: 1 | K6: 1 | L6: 1 | M6: {=H6*VLOOKUP($G6, Factor!$Q$4:$V$36, 2, 0)*INDEX(Factor!$Q$41:$V$87, _xlfn.XMATCH($C6, Factor!$Q$41:$Q$87, -1), 2)} -> 500 | N6: {=I6*VLOOKUP($G6, Factor!$Q$4:$V$36, 3, 0)*INDEX(Factor!$Q$41:$V$87, _xlfn.XMATCH($C6, Factor!$Q$41:$Q$87, -1), 3)} -> 20 | O6: {=J6*VLOOKUP($G6, Factor!$Q$4:$V$36, 4, 0)*INDEX(Factor!$Q$41:$V$87, _xlfn.XMATCH($C6, Factor!$Q$41:$Q$87, -1), 4)} -> 500 | P6: {=K6*VLOOKUP($G6, Factor!$Q$4:$V$36, 5, 0)*INDEX(Factor!$Q$41:$V$87, _xlfn.XMATCH($C6, Factor!$Q$41:$Q$87, -1), 5)} -> 1 | Q6: {=L6*VLOOKUP($G6, Factor!$Q$4:$V$36, 6, 0)*INDEX(Factor!$Q$41:$V$87, _xlfn.XMATCH($C6, Factor!$Q$41:$Q$87, -1), 6)} -> 2000
A7: ="couch_"&VLOOKUP(F7, Factor!$BQ$4:$BR$6, 2, 0)&"_"&Couch!D7&"_"&VLOOKUP(Couch!E7, Factor!$BS$4:$BT$13, 2, 0) -> couch_Wo_T1_003 | B7: =D7&" "&G7&"객차" -> T1 화물 나무객차 | C7: =VLOOKUP(D7, Factor!$P$41:$Q$50, 2, 0) -> 2000 | D7: T1 | E7: 화물 | F7: 나무 | G7: =E7&" " &F7 -> 화물 나무 | H7: 1 | I7: 1 | J7: 1 | K7: 1 | L7: 1 | M7: {=H7*VLOOKUP($G7, Factor!$Q$4:$V$36, 2, 0)*INDEX(Factor!$Q$41:$V$87, _xlfn.XMATCH($C7, Factor!$Q$41:$Q$87, -1), 2)} -> 500 | N7: {=I7*VLOOKUP($G7, Factor!$Q$4:$V$36, 3, 0)*INDEX(Factor!$Q$41:$V$87, _xlfn.XMATCH($C7, Factor!$Q$41:$Q$87, -1), 3)} -> 10 | O7: {=J7*VLOOKUP($G7, Factor!$Q$4:$V$36, 4, 0)*INDEX(Factor!$Q$41:$V$87, _xlfn.XMATCH($C7, Factor!$Q$41:$Q$87, -1), 4)} -> 500 | P7: {=K7*VLOOKUP($G7, Factor!$Q$4:$V$36, 5, 0)*INDEX(Factor!$Q$41:$V$87, _xlfn.XMATCH($C7, Factor!$Q$41:$Q$87, -1), 5)} -> 0.9 | Q7: {=L7*VLOOKUP($G7, Factor!$Q$4:$V$36, 6, 0)*INDEX(Factor!$Q$41:$V$87, _xlfn.XMATCH($C7, Factor!$Q$41:$Q$87, -1), 6)} -> 700
A8: ="couch_"&VLOOKUP(F8, Factor!$BQ$4:$BR$6, 2, 0)&"_"&Couch!D8&"_"&VLOOKUP(Couch!E8, Factor!$BS$4:$BT$13, 2, 0) -> couch_Wo_T1_004 | B8: =D8&" "&G8&"객차" -> T1 군용 나무객차 | C8: =VLOOKUP(D8, Factor!$P$41:$Q$50, 2, 0) -> 2000 | D8: T1 | E8: 군용 | F8: 나무 | G8: =E8&" " &F8 -> 군용 나무 | H8: 1 | I8: 1 | J8: 1 | K8: 1 | L8: 1 | M8: {=H8*VLOOKUP($G8, Factor!$Q$4:$V$36, 2, 0)*INDEX(Factor!$Q$41:$V$87, _xlfn.XMATCH($C8, Factor!$Q$41:$Q$87, -1), 2)} -> 700 | N8: {=I8*VLOOKUP($G8, Factor!$Q$4:$V$36, 3, 0)*INDEX(Factor!$Q$41:$V$87, _xlfn.XMATCH($C8, Factor!$Q$41:$Q$87, -1), 3)} -> 15 | O8: {=J8*VLOOKUP($G8, Factor!$Q$4:$V$36, 4, 0)*INDEX(Factor!$Q$41:$V$87, _xlfn.XMATCH($C8, Factor!$Q$41:$Q$87, -1), 4)} -> 700 | P8: {=K8*VLOOKUP($G8, Factor!$Q$4:$V$36, 5, 0)*INDEX(Factor!$Q$41:$V$87, _xlfn.XMATCH($C8, Factor!$Q$41:$Q$87, -1), 5)} -> 1.1 | Q8: {=L8*VLOOKUP($G8, Factor!$Q$4:$V$36, 6, 0)*INDEX(Factor!$Q$41:$V$87, _xlfn.XMATCH($C8, Factor!$Q$41:$Q$87, -1), 6)} -> 3000
A9: ="couch_"&VLOOKUP(F9, Factor!$BQ$4:$BR$6, 2, 0)&"_"&Couch!D9&"_"&VLOOKUP(Couch!E9, Factor!$BS$4:$BT$13, 2, 0) -> couch_Wo_T1_005 | B9: =D9&" "&G9&"객차" -> T1 여객 나무객차 | C9: =VLOOKUP(D9, Factor!$P$41:$Q$50, 2, 0) -> 2000 | D9: T1 | E9: 여객 | F9: 나무 | G9: =E9&" " &F9 -> 여객 나무 | H9: 1 | I9: 1 | J9: 1 | K9: 1 | L9: 1 | M9: {=H9*VLOOKUP($G9, Factor!$Q$4:$V$36, 2, 0)*INDEX(Factor!$Q$41:$V$87, _xlfn.XMATCH($C9, Factor!$Q$41:$Q$87, -1), 2)} -> 400 | N9: {=I9*VLOOKUP($G9, Factor!$Q$4:$V$36, 3, 0)*INDEX(Factor!$Q$41:$V$87, _xlfn.XMATCH($C9, Factor!$Q$41:$Q$87, -1), 3)} -> 8 | O9: {=J9*VLOOKUP($G9, Factor!$Q$4:$V$36, 4, 0)*INDEX(Factor!$Q$41:$V$87, _xlfn.XMATCH($C9, Factor!$Q$41:$Q$87, -1), 4)} -> 400 | P9: {=K9*VLOOKUP($G9, Factor!$Q$4:$V$36, 5, 0)*INDEX(Factor!$Q$41:$V$87, _xlfn.XMATCH($C9, Factor!$Q$41:$Q$87, -1), 5)} -> 1.2 | Q9: {=L9*VLOOKUP($G9, Factor!$Q$4:$V$36, 6, 0)*INDEX(Factor!$Q$41:$V$87, _xlfn.XMATCH($C9, Factor!$Q$41:$Q$87, -1), 6)} -> 1000
A10: ="couch_"&VLOOKUP(F10, Factor!$BQ$4:$BR$6, 2, 0)&"_"&Couch!D10&"_"&VLOOKUP(Couch!E10, Factor!$BS$4:$BT$13, 2, 0) -> couch_Wo_T1_006 | B10: =D10&" "&G10&"객차" -> T1 시운 나무객차 | C10: =VLOOKUP(D10, Factor!$P$41:$Q$50, 2, 0) -> 2000 | D10: T1 | E10: 시운 | F10: 나무 | G10: =E10&" " &F10 -> 시운 나무 | H10: 1 | I10: 1 | J10: 1 | K10: 1 | L10: 1 | M10: {=H10*VLOOKUP($G10, Factor!$Q$4:$V$36, 2, 0)*INDEX(Factor!$Q$41:$V$87, _xlfn.XMATCH($C10, Factor!$Q$41:$Q$87, -1), 2)} -> 200 | N10: {=I10*VLOOKUP($G10, Factor!$Q$4:$V$36, 3, 0)*INDEX(Factor!$Q$41:$V$87, _xlfn.XMATCH($C10, Factor!$Q$41:$Q$87, -1), 3)} -> 10 | O10: {=J10*VLOOKUP($G10, Factor!$Q$4:$V$36, 4, 0)*INDEX(Factor!$Q$41:$V$87, _xlfn.XMATCH($C10, Factor!$Q$41:$Q$87, -1), 4)} -> 800 | P10: {=K10*VLOOKUP($G10, Factor!$Q$4:$V$36, 5, 0)*INDEX(Factor!$Q$41:$V$87, _xlfn.XMATCH($C10, Factor!$Q$41:$Q$87, -1), 5)} -> 1 | Q10: {=L10*VLOOKUP($G10, Factor!$Q$4:$V$36, 6, 0)*INDEX(Factor!$Q$41:$V$87, _xlfn.XMATCH($C10, Factor!$Q$41:$Q$87, -1), 6)} -> 1000
A11: ="couch_"&VLOOKUP(F11, Factor!$BQ$4:$BR$6, 2, 0)&"_"&Couch!D11&"_"&VLOOKUP(Couch!E11, Factor!$BS$4:$BT$13, 2, 0) -> couch_Wo_T1_007 | B11: =D11&" "&G11&"객차" -> T1 경량 나무객차 | C11: =VLOOKUP(D11, Factor!$P$41:$Q$50, 2, 0) -> 2000 | D11: T1 | E11: 경량 | F11: 나무 | G11: =E11&" " &F11 -> 경량 나무 | H11: 1 | I11: 1 | J11: 1 | K11: 1 | L11: 1 | M11: {=H11*VLOOKUP($G11, Factor!$Q$4:$V$36, 2, 0)*INDEX(Factor!$Q$41:$V$87, _xlfn.XMATCH($C11, Factor!$Q$41:$Q$87, -1), 2)} -> 300 | N11: {=I11*VLOOKUP($G11, Factor!$Q$4:$V$36, 3, 0)*INDEX(Factor!$Q$41:$V$87, _xlfn.XMATCH($C11, Factor!$Q$41:$Q$87, -1), 3)} -> 8 | O11: {=J11*VLOOKUP($G11, Factor!$Q$4:$V$36, 4, 0)*INDEX(Factor!$Q$41:$V$87, _xlfn.XMATCH($C11, Factor!$Q$41:$Q$87, -1), 4)} -> 300 | P11: {=K11*VLOOKUP($G11, Factor!$Q$4:$V$36, 5, 0)*INDEX(Factor!$Q$41:$V$87, _xlfn.XMATCH($C11, Factor!$Q$41:$Q$87, -1), 5)} -> 1 | Q11: {=L11*VLOOKUP($G11, Factor!$Q$4:$V$36, 6, 0)*INDEX(Factor!$Q$41:$V$87, _xlfn.XMATCH($C11, Factor!$Q$41:$Q$87, -1), 6)} -> 500
A12: ="couch_"&VLOOKUP(F12, Factor!$BQ$4:$BR$6, 2, 0)&"_"&Couch!D12&"_"&VLOOKUP(Couch!E12, Factor!$BS$4:$BT$13, 2, 0) -> couch_St_T1_001 | B12: =D12&" "&G12&"객차" -> T1 표준 강철객차 | C12: =VLOOKUP(D12, Factor!$P$41:$Q$50, 2, 0) -> 2000 | D12: T1 | E12: 표준 | F12: 강철 | G12: =E12&" " &F12 -> 표준 강철 | H12: 1 | I12: 1 | J12: 1 | K12: 1 | L12: 1 | M12: {=H12*VLOOKUP($G12, Factor!$Q$4:$V$36, 2, 0)*INDEX(Factor!$Q$41:$V$87, _xlfn.XMATCH($C12, Factor!$Q$41:$Q$87, -1), 2)} -> 700 | N12: {=I12*VLOOKUP($G12, Factor!$Q$4:$V$36, 3, 0)*INDEX(Factor!$Q$41:$V$87, _xlfn.XMATCH($C12, Factor!$Q$41:$Q$87, -1), 3)} -> 20 | O12: {=J12*VLOOKUP($G12, Factor!$Q$4:$V$36, 4, 0)*INDEX(Factor!$Q$41:$V$87, _xlfn.XMATCH($C12, Factor!$Q$41:$Q$87, -1), 4)} -> 700 | P12: {=K12*VLOOKUP($G12, Factor!$Q$4:$V$36, 5, 0)*INDEX(Factor!$Q$41:$V$87, _xlfn.XMATCH($C12, Factor!$Q$41:$Q$87, -1), 5)} -> 1.2 | Q12: {=L12*VLOOKUP($G12, Factor!$Q$4:$V$36, 6, 0)*INDEX(Factor!$Q$41:$V$87, _xlfn.XMATCH($C12, Factor!$Q$41:$Q$87, -1), 6)} -> 1500
A13: ="couch_"&VLOOKUP(F13, Factor!$BQ$4:$BR$6, 2, 0)&"_"&Couch!D13&"_"&VLOOKUP(Couch!E13, Factor!$BS$4:$BT$13, 2, 0) -> couch_St_T1_002 | B13: =D13&" "&G13&"객차" -> T1 중갑 강철객차 | C13: =VLOOKUP(D13, Factor!$P$41:$Q$50, 2, 0) -> 2000 | D13: T1 | E13: 중갑 | F13: 강철 | G13: =E13&" " &F13 -> 중갑 강철 | H13: 1 | I13: 1 | J13: 1 | K13: 1 | L13: 1 | M13: {=H13*VLOOKUP($G13, Factor!$Q$4:$V$36, 2, 0)*INDEX(Factor!$Q$41:$V$87, _xlfn.XMATCH($C13, Factor!$Q$41:$Q$87, -1), 2)} -> 700 | N13: {=I13*VLOOKUP($G13, Factor!$Q$4:$V$36, 3, 0)*INDEX(Factor!$Q$41:$V$87, _xlfn.XMATCH($C13, Factor!$Q$41:$Q$87, -1), 3)} -> 35 | O13: {=J13*VLOOKUP($G13, Factor!$Q$4:$V$36, 4, 0)*INDEX(Factor!$Q$41:$V$87, _xlfn.XMATCH($C13, Factor!$Q$41:$Q$87, -1), 4)} -> 700 | P13: {=K13*VLOOKUP($G13, Factor!$Q$4:$V$36, 5, 0)*INDEX(Factor!$Q$41:$V$87, _xlfn.XMATCH($C13, Factor!$Q$41:$Q$87, -1), 5)} -> 1.2 | Q13: {=L13*VLOOKUP($G13, Factor!$Q$4:$V$36, 6, 0)*INDEX(Factor!$Q$41:$V$87, _xlfn.XMATCH($C13, Factor!$Q$41:$Q$87, -1), 6)} -> 3000
A14: ="couch_"&VLOOKUP(F14, Factor!$BQ$4:$BR$6, 2, 0)&"_"&Couch!D14&"_"&VLOOKUP(Couch!E14, Factor!$BS$4:$BT$13, 2, 0) -> couch_St_T1_003 | B14: =D14&" "&G14&"객차" -> T1 화물 강철객차 | C14: =VLOOKUP(D14, Factor!$P$41:$Q$50, 2, 0) -> 2000 | D14: T1 | E14: 화물 | F14: 강철 | G14: =E14&" " &F14 -> 화물 강철 | H14: 1 | I14: 1 | J14: 1 | K14: 1 | L14: 1 | M14: {=H14*VLOOKUP($G14, Factor!$Q$4:$V$36, 2, 0)*INDEX(Factor!$Q$41:$V$87, _xlfn.XMATCH($C14, Factor!$Q$41:$Q$87, -1), 2)} -> 700 | N14: {=I14*VLOOKUP($G14, Factor!$Q$4:$V$36, 3, 0)*INDEX(Factor!$Q$41:$V$87, _xlfn.XMATCH($C14, Factor!$Q$41:$Q$87, -1), 3)} -> 20 | O14: {=J14*VLOOKUP($G14, Factor!$Q$4:$V$36, 4, 0)*INDEX(Factor!$Q$41:$V$87, _xlfn.XMATCH($C14, Factor!$Q$41:$Q$87, -1), 4)} -> 700 | P14: {=K14*VLOOKUP($G14, Factor!$Q$4:$V$36, 5, 0)*INDEX(Factor!$Q$41:$V$87, _xlfn.XMATCH($C14, Factor!$Q$41:$Q$87, -1), 5)} -> 1.1 | Q14: {=L14*VLOOKUP($G14, Factor!$Q$4:$V$36, 6, 0)*INDEX(Factor!$Q$41:$V$87, _xlfn.XMATCH($C14, Factor!$Q$41:$Q$87, -1), 6)} -> 1000
A15: ="couch_"&VLOOKUP(F15, Factor!$BQ$4:$BR$6, 2, 0)&"_"&Couch!D15&"_"&VLOOKUP(Couch!E15, Factor!$BS$4:$BT$13, 2, 0) -> couch_St_T1_004 | B15: =D15&" "&G15&"객차" -> T1 군용 강철객차 | C15: =VLOOKUP(D15, Factor!$P$41:$Q$50, 2, 0) -> 2000 | D15: T1 | E15: 군용 | F15: 강철 | G15: =E15&" " &F15 -> 군용 강철 | H15: 1 | I15: 1 | J15: 1 | K15: 1 | L15: 1 | M15: {=H15*VLOOKUP($G15, Factor!$Q$4:$V$36, 2, 0)*INDEX(Factor!$Q$41:$V$87, _xlfn.XMATCH($C15, Factor!$Q$41:$Q$87, -1), 2)} -> 900 | N15: {=I15*VLOOKUP($G15, Factor!$Q$4:$V$36, 3, 0)*INDEX(Factor!$Q$41:$V$87, _xlfn.XMATCH($C15, Factor!$Q$41:$Q$87, -1), 3)} -> 30 | O15: {=J15*VLOOKUP($G15, Factor!$Q$4:$V$36, 4, 0)*INDEX(Factor!$Q$41:$V$87, _xlfn.XMATCH($C15, Factor!$Q$41:$Q$87, -1), 4)} -> 900 | P15: {=K15*VLOOKUP($G15, Factor!$Q$4:$V$36, 5, 0)*INDEX(Factor!$Q$41:$V$87, _xlfn.XMATCH($C15, Factor!$Q$41:$Q$87, -1), 5)} -> 1.3 | Q15: {=L15*VLOOKUP($G15, Factor!$Q$4:$V$36, 6, 0)*INDEX(Factor!$Q$41:$V$87, _xlfn.XMATCH($C15, Factor!$Q$41:$Q$87, -1), 6)} -> 4500
A16: ="couch_"&VLOOKUP(F16, Factor!$BQ$4:$BR$6, 2, 0)&"_"&Couch!D16&"_"&VLOOKUP(Couch!E16, Factor!$BS$4:$BT$13, 2, 0) -> couch_St_T1_005 | B16: =D16&" "&G16&"객차" -> T1 여객 강철객차 | C16: =VLOOKUP(D16, Factor!$P$41:$Q$50, 2, 0) -> 2000 | D16: T1 | E16: 여객 | F16: 강철 | G16: =E16&" " &F16 -> 여객 강철 | H16: 1 | I16: 1 | J16: 1 | K16: 1 | L16: 1 | M16: {=H16*VLOOKUP($G16, Factor!$Q$4:$V$36, 2, 0)*INDEX(Factor!$Q$41:$V$87, _xlfn.XMATCH($C16, Factor!$Q$41:$Q$87, -1), 2)} -> 600 | N16: {=I16*VLOOKUP($G16, Factor!$Q$4:$V$36, 3, 0)*INDEX(Factor!$Q$41:$V$87, _xlfn.XMATCH($C16, Factor!$Q$41:$Q$87, -1), 3)} -> 20 | O16: {=J16*VLOOKUP($G16, Factor!$Q$4:$V$36, 4, 0)*INDEX(Factor!$Q$41:$V$87, _xlfn.XMATCH($C16, Factor!$Q$41:$Q$87, -1), 4)} -> 600 | P16: {=K16*VLOOKUP($G16, Factor!$Q$4:$V$36, 5, 0)*INDEX(Factor!$Q$41:$V$87, _xlfn.XMATCH($C16, Factor!$Q$41:$Q$87, -1), 5)} -> 1.4 | Q16: {=L16*VLOOKUP($G16, Factor!$Q$4:$V$36, 6, 0)*INDEX(Factor!$Q$41:$V$87, _xlfn.XMATCH($C16, Factor!$Q$41:$Q$87, -1), 6)} -> 1500
... A214: ="couch_"&VLOOKUP(F214, Factor!$BQ$4:$BR$6, 2, 0)&"_"&Couch!D214&"_"&VLOOKUP(Couch!E214, Factor!$BS$4:$BT$13, 2, 0) -> couch_Ti_T10_007 | B214: =D214&" "&G214&"객차" -> T10 경량 티타늄객차 | C214: =VLOOKUP(D214, Factor!$P$41:$Q$50, 2, 0) -> 20000 | D214: T10 | E214: 경량 | F214: 티타늄 | G214: =E214&" " &F214 -> 경량 티타늄 | H214: 1 | I214: 1 | J214: 1 | K214: 1 | L214: 1 | M214: {=H214*VLOOKUP($G214, Factor!$Q$4:$V$36, 2, 0)*INDEX(Factor!$Q$41:$V$87, _xlfn.XMATCH($C214, Factor!$Q$41:$Q$87, -1), 2)} -> 1680 | N214: {=I214*VLOOKUP($G214, Factor!$Q$4:$V$36, 3, 0)*INDEX(Factor!$Q$41:$V$87, _xlfn.XMATCH($C214, Factor!$Q$41:$Q$87, -1), 3)} -> 56 | O214: {=J214*VLOOKUP($G214, Factor!$Q$4:$V$36, 4, 0)*INDEX(Factor!$Q$41:$V$87, _xlfn.XMATCH($C214, Factor!$Q$41:$Q$87, -1), 4)} -> 1680 | P214: {=K214*VLOOKUP($G214, Factor!$Q$4:$V$36, 5, 0)*INDEX(Factor!$Q$41:$V$87, _xlfn.XMATCH($C214, Factor!$Q$41:$Q$87, -1), 5)} -> 3.92 | Q214: {=L214*VLOOKUP($G214, Factor!$Q$4:$V$36, 6, 0)*INDEX(Factor!$Q$41:$V$87, _xlfn.XMATCH($C214, Factor!$Q$41:$Q$87, -1), 6)} -> 2800

Sheet Engine
A1: ● 3열은 데이터의 자료형이며 자료형이 한글로 되어있는 경우 인게임에서 사용하지 않는 데이터지만 테이블에서 수치조정 또는 색인을 위해 넣은 데이터이다. ● 보정치의 수치를 조정해 각 몬스터 별로 상세 능력치를 조정할 수 있다. ● 보정값의 경우 수치 조정의도가 없는 경우 1을 유지한다. ● ID는 engine_엔진종류_등급_번호 순으로 구성된다. ● ID 이름 가격은 3열에 노란색으로 칠해진 내부색인 칼럼에 데이터를 입력하면 자동 생성된다. ● 배정되는 값은 Factor 시트를 참고한다.
A2: 엔진ID | B2: 엔진 이름 | C2: 엔진 가격 | D2: 등급 | E2: 엔진종류(형식구분) | F2: 엔진종류(성능구분) | G2: 엔진 종류(합본) | H2: 최대출력 증가량 보정치 | I2: 엔진 무게 보정치 | J2: 최대출력 증가량 | K2: 엔진 무게 | L2: 엔진 설명 문구
A3: string | B3: string | C3: int | D3: 내부색인 | E3: 내부색인 | F3: 내부색인 | G3: 내부색인 | H3: 보정치 | I3: 보정치 | J3: float | K3: int | L3: string
A4: engineId | B4: engineName | C4: engineCost | D4: engineType | E4: engineType | F4: engineType | G4: engineType | H4: enginePowerUp | I4: engineWeight | J4: enginePowerUp | K4: engineWeight | L4: engineText
A5: ="engine_"&VLOOKUP(F5, Factor!$BW$4:$BX$6, 2, 0)&"_"&D5&"_"&VLOOKUP(E5, Factor!$BY$4:$BZ$13, 2, 0) -> engine_No_T1_001 | B5: =D5&" "&G5&"엔진팩" -> T1 표준 4기통엔진팩 | C5: =VLOOKUP(D5, Factor!$X$41:$Y$50, 2, 0) -> 1000 | D5: T1 | E5: 4기통 | F5: 표준 | G5: =F5&" "&E5 -> 표준 4기통 | H5: 1 | I5: 1 | J5: {=H5*VLOOKUP($G5, Factor!$Y$4:$AA$36, 2, 0)*INDEX(Factor!$Y$41:$AA$87, _xlfn.XMATCH($C5, Factor!$Y$41:$Y$87, -1), 2)} -> 10 | K5: {=I5*VLOOKUP($G5, Factor!$Y$4:$AA$36, 3, 0)*INDEX(Factor!$Y$41:$AA$87, _xlfn.XMATCH($C5, Factor!$Y$41:$Y$87, -1), 3)} -> 500
A6: ="engine_"&VLOOKUP(F6, Factor!$BW$4:$BX$6, 2, 0)&"_"&D6&"_"&VLOOKUP(E6, Factor!$BY$4:$BZ$13, 2, 0) -> engine_No_T1_002 | B6: =D6&" "&G6&"엔진팩" -> T1 표준 6기통엔진팩 | C6: =VLOOKUP(D6, Factor!$X$41:$Y$50, 2, 0) -> 1000 | D6: T1 | E6: 6기통 | F6: 표준 | G6: =F6&" "&E6 -> 표준 6기통 | H6: 1 | I6: 1 | J6: {=H6*VLOOKUP($G6, Factor!$Y$4:$AA$36, 2, 0)*INDEX(Factor!$Y$41:$AA$87, _xlfn.XMATCH($C6, Factor!$Y$41:$Y$87, -1), 2)} -> 20 | K6: {=I6*VLOOKUP($G6, Factor!$Y$4:$AA$36, 3, 0)*INDEX(Factor!$Y$41:$AA$87, _xlfn.XMATCH($C6, Factor!$Y$41:$Y$87, -1), 3)} -> 1000
A7: ="engine_"&VLOOKUP(F7, Factor!$BW$4:$BX$6, 2, 0)&"_"&D7&"_"&VLOOKUP(E7, Factor!$BY$4:$BZ$13, 2, 0) -> engine_No_T1_003 | B7: =D7&" "&G7&"엔진팩" -> T1 표준 8기통엔진팩 | C7: =VLOOKUP(D7, Factor!$X$41:$Y$50, 2, 0) -> 1000 | D7: T1 | E7: 8기통 | F7: 표준 | G7: =F7&" "&E7 -> 표준 8기통 | H7: 1 | I7: 1 | J7: {=H7*VLOOKUP($G7, Factor!$Y$4:$AA$36, 2, 0)*INDEX(Factor!$Y$41:$AA$87, _xlfn.XMATCH($C7, Factor!$Y$41:$Y$87, -1), 2)} -> 40 | K7: {=I7*VLOOKUP($G7, Factor!$Y$4:$AA$36, 3, 0)*INDEX(Factor!$Y$41:$AA$87, _xlfn.XMATCH($C7, Factor!$Y$41:$Y$87, -1), 3)} -> 2000
